[2023-06-05T18:00:24.538+0000] {processor.py:154} INFO - Started process (PID=6067) to work on /opt/airflow/dags/process_weather_people_data_postgres/process_weather_people_data_postgres.py
[2023-06-05T18:00:24.539+0000] {processor.py:756} INFO - Processing file /opt/airflow/dags/process_weather_people_data_postgres/process_weather_people_data_postgres.py for tasks to queue
[2023-06-05T18:00:24.540+0000] {logging_mixin.py:120} INFO - [2023-06-05T18:00:24.540+0000] {dagbag.py:537} INFO - Filling up the DagBag from /opt/airflow/dags/process_weather_people_data_postgres/process_weather_people_data_postgres.py
[2023-06-05T18:00:24.549+0000] {logging_mixin.py:120} INFO - [2023-06-05T18:00:24.546+0000] {dagbag.py:342} ERROR - Failed to import: /opt/airflow/dags/process_weather_people_data_postgres/process_weather_people_data_postgres.py
Traceback (most recent call last):
  File "/home/airflow/.local/lib/python3.7/site-packages/airflow/models/dagbag.py", line 338, in parse
    loader.exec_module(new_module)
  File "<frozen importlib._bootstrap_external>", line 728, in exec_module
  File "<frozen importlib._bootstrap>", line 219, in _call_with_frames_removed
  File "/opt/airflow/dags/process_weather_people_data_postgres/process_weather_people_data_postgres.py", line 17, in <module>
    from utils.common import get_config
ModuleNotFoundError: No module named 'utils'
[2023-06-05T18:00:24.550+0000] {processor.py:768} WARNING - No viable dags retrieved from /opt/airflow/dags/process_weather_people_data_postgres/process_weather_people_data_postgres.py
[2023-06-05T18:00:24.577+0000] {processor.py:176} INFO - Processing /opt/airflow/dags/process_weather_people_data_postgres/process_weather_people_data_postgres.py took 0.043 seconds
[2023-06-05T18:00:54.726+0000] {processor.py:154} INFO - Started process (PID=6087) to work on /opt/airflow/dags/process_weather_people_data_postgres/process_weather_people_data_postgres.py
[2023-06-05T18:00:54.727+0000] {processor.py:756} INFO - Processing file /opt/airflow/dags/process_weather_people_data_postgres/process_weather_people_data_postgres.py for tasks to queue
[2023-06-05T18:00:54.728+0000] {logging_mixin.py:120} INFO - [2023-06-05T18:00:54.728+0000] {dagbag.py:537} INFO - Filling up the DagBag from /opt/airflow/dags/process_weather_people_data_postgres/process_weather_people_data_postgres.py
[2023-06-05T18:00:54.731+0000] {logging_mixin.py:120} INFO - [2023-06-05T18:00:54.730+0000] {dagbag.py:342} ERROR - Failed to import: /opt/airflow/dags/process_weather_people_data_postgres/process_weather_people_data_postgres.py
Traceback (most recent call last):
  File "/home/airflow/.local/lib/python3.7/site-packages/airflow/models/dagbag.py", line 338, in parse
    loader.exec_module(new_module)
  File "<frozen importlib._bootstrap_external>", line 728, in exec_module
  File "<frozen importlib._bootstrap>", line 219, in _call_with_frames_removed
  File "/opt/airflow/dags/process_weather_people_data_postgres/process_weather_people_data_postgres.py", line 17, in <module>
    from utils.common import get_config
ModuleNotFoundError: No module named 'utils'
[2023-06-05T18:00:54.731+0000] {processor.py:768} WARNING - No viable dags retrieved from /opt/airflow/dags/process_weather_people_data_postgres/process_weather_people_data_postgres.py
[2023-06-05T18:00:54.752+0000] {processor.py:176} INFO - Processing /opt/airflow/dags/process_weather_people_data_postgres/process_weather_people_data_postgres.py took 0.028 seconds
[2023-06-05T18:01:24.905+0000] {processor.py:154} INFO - Started process (PID=6116) to work on /opt/airflow/dags/process_weather_people_data_postgres/process_weather_people_data_postgres.py
[2023-06-05T18:01:24.907+0000] {processor.py:756} INFO - Processing file /opt/airflow/dags/process_weather_people_data_postgres/process_weather_people_data_postgres.py for tasks to queue
[2023-06-05T18:01:24.908+0000] {logging_mixin.py:120} INFO - [2023-06-05T18:01:24.908+0000] {dagbag.py:537} INFO - Filling up the DagBag from /opt/airflow/dags/process_weather_people_data_postgres/process_weather_people_data_postgres.py
[2023-06-05T18:01:24.913+0000] {logging_mixin.py:120} INFO - [2023-06-05T18:01:24.911+0000] {dagbag.py:342} ERROR - Failed to import: /opt/airflow/dags/process_weather_people_data_postgres/process_weather_people_data_postgres.py
Traceback (most recent call last):
  File "/home/airflow/.local/lib/python3.7/site-packages/airflow/models/dagbag.py", line 338, in parse
    loader.exec_module(new_module)
  File "<frozen importlib._bootstrap_external>", line 728, in exec_module
  File "<frozen importlib._bootstrap>", line 219, in _call_with_frames_removed
  File "/opt/airflow/dags/process_weather_people_data_postgres/process_weather_people_data_postgres.py", line 17, in <module>
    from utils.common import get_config
ModuleNotFoundError: No module named 'utils'
[2023-06-05T18:01:24.914+0000] {processor.py:768} WARNING - No viable dags retrieved from /opt/airflow/dags/process_weather_people_data_postgres/process_weather_people_data_postgres.py
[2023-06-05T18:01:24.935+0000] {processor.py:176} INFO - Processing /opt/airflow/dags/process_weather_people_data_postgres/process_weather_people_data_postgres.py took 0.034 seconds
[2023-06-05T18:01:55.151+0000] {processor.py:154} INFO - Started process (PID=6145) to work on /opt/airflow/dags/process_weather_people_data_postgres/process_weather_people_data_postgres.py
[2023-06-05T18:01:55.152+0000] {processor.py:756} INFO - Processing file /opt/airflow/dags/process_weather_people_data_postgres/process_weather_people_data_postgres.py for tasks to queue
[2023-06-05T18:01:55.153+0000] {logging_mixin.py:120} INFO - [2023-06-05T18:01:55.152+0000] {dagbag.py:537} INFO - Filling up the DagBag from /opt/airflow/dags/process_weather_people_data_postgres/process_weather_people_data_postgres.py
[2023-06-05T18:01:55.156+0000] {logging_mixin.py:120} INFO - [2023-06-05T18:01:55.155+0000] {dagbag.py:342} ERROR - Failed to import: /opt/airflow/dags/process_weather_people_data_postgres/process_weather_people_data_postgres.py
Traceback (most recent call last):
  File "/home/airflow/.local/lib/python3.7/site-packages/airflow/models/dagbag.py", line 338, in parse
    loader.exec_module(new_module)
  File "<frozen importlib._bootstrap_external>", line 728, in exec_module
  File "<frozen importlib._bootstrap>", line 219, in _call_with_frames_removed
  File "/opt/airflow/dags/process_weather_people_data_postgres/process_weather_people_data_postgres.py", line 17, in <module>
    from utils.common import get_config
ModuleNotFoundError: No module named 'utils'
[2023-06-05T18:01:55.157+0000] {processor.py:768} WARNING - No viable dags retrieved from /opt/airflow/dags/process_weather_people_data_postgres/process_weather_people_data_postgres.py
[2023-06-05T18:01:55.177+0000] {processor.py:176} INFO - Processing /opt/airflow/dags/process_weather_people_data_postgres/process_weather_people_data_postgres.py took 0.029 seconds
[2023-06-05T18:02:25.321+0000] {processor.py:154} INFO - Started process (PID=6165) to work on /opt/airflow/dags/process_weather_people_data_postgres/process_weather_people_data_postgres.py
[2023-06-05T18:02:25.323+0000] {processor.py:756} INFO - Processing file /opt/airflow/dags/process_weather_people_data_postgres/process_weather_people_data_postgres.py for tasks to queue
[2023-06-05T18:02:25.324+0000] {logging_mixin.py:120} INFO - [2023-06-05T18:02:25.323+0000] {dagbag.py:537} INFO - Filling up the DagBag from /opt/airflow/dags/process_weather_people_data_postgres/process_weather_people_data_postgres.py
[2023-06-05T18:02:25.327+0000] {logging_mixin.py:120} INFO - [2023-06-05T18:02:25.326+0000] {dagbag.py:342} ERROR - Failed to import: /opt/airflow/dags/process_weather_people_data_postgres/process_weather_people_data_postgres.py
Traceback (most recent call last):
  File "/home/airflow/.local/lib/python3.7/site-packages/airflow/models/dagbag.py", line 338, in parse
    loader.exec_module(new_module)
  File "<frozen importlib._bootstrap_external>", line 728, in exec_module
  File "<frozen importlib._bootstrap>", line 219, in _call_with_frames_removed
  File "/opt/airflow/dags/process_weather_people_data_postgres/process_weather_people_data_postgres.py", line 17, in <module>
    from utils.common import get_config
ModuleNotFoundError: No module named 'utils'
[2023-06-05T18:02:25.328+0000] {processor.py:768} WARNING - No viable dags retrieved from /opt/airflow/dags/process_weather_people_data_postgres/process_weather_people_data_postgres.py
[2023-06-05T18:02:25.350+0000] {processor.py:176} INFO - Processing /opt/airflow/dags/process_weather_people_data_postgres/process_weather_people_data_postgres.py took 0.032 seconds
[2023-06-05T18:02:55.501+0000] {processor.py:154} INFO - Started process (PID=6194) to work on /opt/airflow/dags/process_weather_people_data_postgres/process_weather_people_data_postgres.py
[2023-06-05T18:02:55.502+0000] {processor.py:756} INFO - Processing file /opt/airflow/dags/process_weather_people_data_postgres/process_weather_people_data_postgres.py for tasks to queue
[2023-06-05T18:02:55.503+0000] {logging_mixin.py:120} INFO - [2023-06-05T18:02:55.503+0000] {dagbag.py:537} INFO - Filling up the DagBag from /opt/airflow/dags/process_weather_people_data_postgres/process_weather_people_data_postgres.py
[2023-06-05T18:02:55.508+0000] {logging_mixin.py:120} INFO - [2023-06-05T18:02:55.507+0000] {dagbag.py:342} ERROR - Failed to import: /opt/airflow/dags/process_weather_people_data_postgres/process_weather_people_data_postgres.py
Traceback (most recent call last):
  File "/home/airflow/.local/lib/python3.7/site-packages/airflow/models/dagbag.py", line 338, in parse
    loader.exec_module(new_module)
  File "<frozen importlib._bootstrap_external>", line 728, in exec_module
  File "<frozen importlib._bootstrap>", line 219, in _call_with_frames_removed
  File "/opt/airflow/dags/process_weather_people_data_postgres/process_weather_people_data_postgres.py", line 17, in <module>
    from utils.common import get_config
ModuleNotFoundError: No module named 'utils'
[2023-06-05T18:02:55.509+0000] {processor.py:768} WARNING - No viable dags retrieved from /opt/airflow/dags/process_weather_people_data_postgres/process_weather_people_data_postgres.py
[2023-06-05T18:02:55.528+0000] {processor.py:176} INFO - Processing /opt/airflow/dags/process_weather_people_data_postgres/process_weather_people_data_postgres.py took 0.029 seconds
[2023-06-05T18:03:25.701+0000] {processor.py:154} INFO - Started process (PID=6223) to work on /opt/airflow/dags/process_weather_people_data_postgres/process_weather_people_data_postgres.py
[2023-06-05T18:03:25.702+0000] {processor.py:756} INFO - Processing file /opt/airflow/dags/process_weather_people_data_postgres/process_weather_people_data_postgres.py for tasks to queue
[2023-06-05T18:03:25.703+0000] {logging_mixin.py:120} INFO - [2023-06-05T18:03:25.703+0000] {dagbag.py:537} INFO - Filling up the DagBag from /opt/airflow/dags/process_weather_people_data_postgres/process_weather_people_data_postgres.py
[2023-06-05T18:03:25.707+0000] {logging_mixin.py:120} INFO - [2023-06-05T18:03:25.706+0000] {dagbag.py:342} ERROR - Failed to import: /opt/airflow/dags/process_weather_people_data_postgres/process_weather_people_data_postgres.py
Traceback (most recent call last):
  File "/home/airflow/.local/lib/python3.7/site-packages/airflow/models/dagbag.py", line 338, in parse
    loader.exec_module(new_module)
  File "<frozen importlib._bootstrap_external>", line 728, in exec_module
  File "<frozen importlib._bootstrap>", line 219, in _call_with_frames_removed
  File "/opt/airflow/dags/process_weather_people_data_postgres/process_weather_people_data_postgres.py", line 17, in <module>
    from utils.common import get_config
ModuleNotFoundError: No module named 'utils'
[2023-06-05T18:03:25.708+0000] {processor.py:768} WARNING - No viable dags retrieved from /opt/airflow/dags/process_weather_people_data_postgres/process_weather_people_data_postgres.py
[2023-06-05T18:03:25.728+0000] {processor.py:176} INFO - Processing /opt/airflow/dags/process_weather_people_data_postgres/process_weather_people_data_postgres.py took 0.030 seconds
[2023-06-05T18:03:55.875+0000] {processor.py:154} INFO - Started process (PID=6243) to work on /opt/airflow/dags/process_weather_people_data_postgres/process_weather_people_data_postgres.py
[2023-06-05T18:03:55.876+0000] {processor.py:756} INFO - Processing file /opt/airflow/dags/process_weather_people_data_postgres/process_weather_people_data_postgres.py for tasks to queue
[2023-06-05T18:03:55.876+0000] {logging_mixin.py:120} INFO - [2023-06-05T18:03:55.876+0000] {dagbag.py:537} INFO - Filling up the DagBag from /opt/airflow/dags/process_weather_people_data_postgres/process_weather_people_data_postgres.py
[2023-06-05T18:03:55.880+0000] {logging_mixin.py:120} INFO - [2023-06-05T18:03:55.879+0000] {dagbag.py:342} ERROR - Failed to import: /opt/airflow/dags/process_weather_people_data_postgres/process_weather_people_data_postgres.py
Traceback (most recent call last):
  File "/home/airflow/.local/lib/python3.7/site-packages/airflow/models/dagbag.py", line 338, in parse
    loader.exec_module(new_module)
  File "<frozen importlib._bootstrap_external>", line 728, in exec_module
  File "<frozen importlib._bootstrap>", line 219, in _call_with_frames_removed
  File "/opt/airflow/dags/process_weather_people_data_postgres/process_weather_people_data_postgres.py", line 17, in <module>
    from utils.common import get_config
ModuleNotFoundError: No module named 'utils'
[2023-06-05T18:03:55.880+0000] {processor.py:768} WARNING - No viable dags retrieved from /opt/airflow/dags/process_weather_people_data_postgres/process_weather_people_data_postgres.py
[2023-06-05T18:03:55.899+0000] {processor.py:176} INFO - Processing /opt/airflow/dags/process_weather_people_data_postgres/process_weather_people_data_postgres.py took 0.028 seconds
[2023-06-05T18:04:26.047+0000] {processor.py:154} INFO - Started process (PID=6272) to work on /opt/airflow/dags/process_weather_people_data_postgres/process_weather_people_data_postgres.py
[2023-06-05T18:04:26.048+0000] {processor.py:756} INFO - Processing file /opt/airflow/dags/process_weather_people_data_postgres/process_weather_people_data_postgres.py for tasks to queue
[2023-06-05T18:04:26.048+0000] {logging_mixin.py:120} INFO - [2023-06-05T18:04:26.048+0000] {dagbag.py:537} INFO - Filling up the DagBag from /opt/airflow/dags/process_weather_people_data_postgres/process_weather_people_data_postgres.py
[2023-06-05T18:04:26.052+0000] {logging_mixin.py:120} INFO - [2023-06-05T18:04:26.051+0000] {dagbag.py:342} ERROR - Failed to import: /opt/airflow/dags/process_weather_people_data_postgres/process_weather_people_data_postgres.py
Traceback (most recent call last):
  File "/home/airflow/.local/lib/python3.7/site-packages/airflow/models/dagbag.py", line 338, in parse
    loader.exec_module(new_module)
  File "<frozen importlib._bootstrap_external>", line 728, in exec_module
  File "<frozen importlib._bootstrap>", line 219, in _call_with_frames_removed
  File "/opt/airflow/dags/process_weather_people_data_postgres/process_weather_people_data_postgres.py", line 17, in <module>
    from utils.common import get_config
ModuleNotFoundError: No module named 'utils'
[2023-06-05T18:04:26.053+0000] {processor.py:768} WARNING - No viable dags retrieved from /opt/airflow/dags/process_weather_people_data_postgres/process_weather_people_data_postgres.py
[2023-06-05T18:04:26.074+0000] {processor.py:176} INFO - Processing /opt/airflow/dags/process_weather_people_data_postgres/process_weather_people_data_postgres.py took 0.029 seconds
[2023-06-05T18:04:56.236+0000] {processor.py:154} INFO - Started process (PID=6301) to work on /opt/airflow/dags/process_weather_people_data_postgres/process_weather_people_data_postgres.py
[2023-06-05T18:04:56.237+0000] {processor.py:756} INFO - Processing file /opt/airflow/dags/process_weather_people_data_postgres/process_weather_people_data_postgres.py for tasks to queue
[2023-06-05T18:04:56.237+0000] {logging_mixin.py:120} INFO - [2023-06-05T18:04:56.237+0000] {dagbag.py:537} INFO - Filling up the DagBag from /opt/airflow/dags/process_weather_people_data_postgres/process_weather_people_data_postgres.py
[2023-06-05T18:04:56.241+0000] {logging_mixin.py:120} INFO - [2023-06-05T18:04:56.240+0000] {dagbag.py:342} ERROR - Failed to import: /opt/airflow/dags/process_weather_people_data_postgres/process_weather_people_data_postgres.py
Traceback (most recent call last):
  File "/home/airflow/.local/lib/python3.7/site-packages/airflow/models/dagbag.py", line 338, in parse
    loader.exec_module(new_module)
  File "<frozen importlib._bootstrap_external>", line 728, in exec_module
  File "<frozen importlib._bootstrap>", line 219, in _call_with_frames_removed
  File "/opt/airflow/dags/process_weather_people_data_postgres/process_weather_people_data_postgres.py", line 17, in <module>
    from utils.common import get_config
ModuleNotFoundError: No module named 'utils'
[2023-06-05T18:04:56.242+0000] {processor.py:768} WARNING - No viable dags retrieved from /opt/airflow/dags/process_weather_people_data_postgres/process_weather_people_data_postgres.py
[2023-06-05T18:04:56.261+0000] {processor.py:176} INFO - Processing /opt/airflow/dags/process_weather_people_data_postgres/process_weather_people_data_postgres.py took 0.028 seconds
[2023-06-05T18:05:26.409+0000] {processor.py:154} INFO - Started process (PID=6321) to work on /opt/airflow/dags/process_weather_people_data_postgres/process_weather_people_data_postgres.py
[2023-06-05T18:05:26.411+0000] {processor.py:756} INFO - Processing file /opt/airflow/dags/process_weather_people_data_postgres/process_weather_people_data_postgres.py for tasks to queue
[2023-06-05T18:05:26.412+0000] {logging_mixin.py:120} INFO - [2023-06-05T18:05:26.411+0000] {dagbag.py:537} INFO - Filling up the DagBag from /opt/airflow/dags/process_weather_people_data_postgres/process_weather_people_data_postgres.py
[2023-06-05T18:05:26.415+0000] {logging_mixin.py:120} INFO - [2023-06-05T18:05:26.415+0000] {dagbag.py:342} ERROR - Failed to import: /opt/airflow/dags/process_weather_people_data_postgres/process_weather_people_data_postgres.py
Traceback (most recent call last):
  File "/home/airflow/.local/lib/python3.7/site-packages/airflow/models/dagbag.py", line 338, in parse
    loader.exec_module(new_module)
  File "<frozen importlib._bootstrap_external>", line 728, in exec_module
  File "<frozen importlib._bootstrap>", line 219, in _call_with_frames_removed
  File "/opt/airflow/dags/process_weather_people_data_postgres/process_weather_people_data_postgres.py", line 17, in <module>
    from utils.common import get_config
ModuleNotFoundError: No module named 'utils'
[2023-06-05T18:05:26.416+0000] {processor.py:768} WARNING - No viable dags retrieved from /opt/airflow/dags/process_weather_people_data_postgres/process_weather_people_data_postgres.py
[2023-06-05T18:05:26.437+0000] {processor.py:176} INFO - Processing /opt/airflow/dags/process_weather_people_data_postgres/process_weather_people_data_postgres.py took 0.031 seconds
[2023-06-05T18:05:56.585+0000] {processor.py:154} INFO - Started process (PID=6350) to work on /opt/airflow/dags/process_weather_people_data_postgres/process_weather_people_data_postgres.py
[2023-06-05T18:05:56.586+0000] {processor.py:756} INFO - Processing file /opt/airflow/dags/process_weather_people_data_postgres/process_weather_people_data_postgres.py for tasks to queue
[2023-06-05T18:05:56.587+0000] {logging_mixin.py:120} INFO - [2023-06-05T18:05:56.587+0000] {dagbag.py:537} INFO - Filling up the DagBag from /opt/airflow/dags/process_weather_people_data_postgres/process_weather_people_data_postgres.py
[2023-06-05T18:05:56.593+0000] {logging_mixin.py:120} INFO - [2023-06-05T18:05:56.592+0000] {dagbag.py:342} ERROR - Failed to import: /opt/airflow/dags/process_weather_people_data_postgres/process_weather_people_data_postgres.py
Traceback (most recent call last):
  File "/home/airflow/.local/lib/python3.7/site-packages/airflow/models/dagbag.py", line 338, in parse
    loader.exec_module(new_module)
  File "<frozen importlib._bootstrap_external>", line 728, in exec_module
  File "<frozen importlib._bootstrap>", line 219, in _call_with_frames_removed
  File "/opt/airflow/dags/process_weather_people_data_postgres/process_weather_people_data_postgres.py", line 17, in <module>
    from utils.common import get_config
ModuleNotFoundError: No module named 'utils'
[2023-06-05T18:05:56.593+0000] {processor.py:768} WARNING - No viable dags retrieved from /opt/airflow/dags/process_weather_people_data_postgres/process_weather_people_data_postgres.py
[2023-06-05T18:05:56.613+0000] {processor.py:176} INFO - Processing /opt/airflow/dags/process_weather_people_data_postgres/process_weather_people_data_postgres.py took 0.031 seconds
[2023-06-05T18:06:26.782+0000] {processor.py:154} INFO - Started process (PID=6379) to work on /opt/airflow/dags/process_weather_people_data_postgres/process_weather_people_data_postgres.py
[2023-06-05T18:06:26.784+0000] {processor.py:756} INFO - Processing file /opt/airflow/dags/process_weather_people_data_postgres/process_weather_people_data_postgres.py for tasks to queue
[2023-06-05T18:06:26.786+0000] {logging_mixin.py:120} INFO - [2023-06-05T18:06:26.785+0000] {dagbag.py:537} INFO - Filling up the DagBag from /opt/airflow/dags/process_weather_people_data_postgres/process_weather_people_data_postgres.py
[2023-06-05T18:06:26.790+0000] {logging_mixin.py:120} INFO - [2023-06-05T18:06:26.789+0000] {dagbag.py:342} ERROR - Failed to import: /opt/airflow/dags/process_weather_people_data_postgres/process_weather_people_data_postgres.py
Traceback (most recent call last):
  File "/home/airflow/.local/lib/python3.7/site-packages/airflow/models/dagbag.py", line 338, in parse
    loader.exec_module(new_module)
  File "<frozen importlib._bootstrap_external>", line 728, in exec_module
  File "<frozen importlib._bootstrap>", line 219, in _call_with_frames_removed
  File "/opt/airflow/dags/process_weather_people_data_postgres/process_weather_people_data_postgres.py", line 17, in <module>
    from utils.common import get_config
ModuleNotFoundError: No module named 'utils'
[2023-06-05T18:06:26.790+0000] {processor.py:768} WARNING - No viable dags retrieved from /opt/airflow/dags/process_weather_people_data_postgres/process_weather_people_data_postgres.py
[2023-06-05T18:06:26.809+0000] {processor.py:176} INFO - Processing /opt/airflow/dags/process_weather_people_data_postgres/process_weather_people_data_postgres.py took 0.029 seconds
[2023-06-05T18:06:56.968+0000] {processor.py:154} INFO - Started process (PID=6399) to work on /opt/airflow/dags/process_weather_people_data_postgres/process_weather_people_data_postgres.py
[2023-06-05T18:06:56.968+0000] {processor.py:756} INFO - Processing file /opt/airflow/dags/process_weather_people_data_postgres/process_weather_people_data_postgres.py for tasks to queue
[2023-06-05T18:06:56.969+0000] {logging_mixin.py:120} INFO - [2023-06-05T18:06:56.969+0000] {dagbag.py:537} INFO - Filling up the DagBag from /opt/airflow/dags/process_weather_people_data_postgres/process_weather_people_data_postgres.py
[2023-06-05T18:06:56.972+0000] {logging_mixin.py:120} INFO - [2023-06-05T18:06:56.971+0000] {dagbag.py:342} ERROR - Failed to import: /opt/airflow/dags/process_weather_people_data_postgres/process_weather_people_data_postgres.py
Traceback (most recent call last):
  File "/home/airflow/.local/lib/python3.7/site-packages/airflow/models/dagbag.py", line 338, in parse
    loader.exec_module(new_module)
  File "<frozen importlib._bootstrap_external>", line 728, in exec_module
  File "<frozen importlib._bootstrap>", line 219, in _call_with_frames_removed
  File "/opt/airflow/dags/process_weather_people_data_postgres/process_weather_people_data_postgres.py", line 17, in <module>
    from utils.common import get_config
ModuleNotFoundError: No module named 'utils'
[2023-06-05T18:06:56.973+0000] {processor.py:768} WARNING - No viable dags retrieved from /opt/airflow/dags/process_weather_people_data_postgres/process_weather_people_data_postgres.py
[2023-06-05T18:06:56.991+0000] {processor.py:176} INFO - Processing /opt/airflow/dags/process_weather_people_data_postgres/process_weather_people_data_postgres.py took 0.026 seconds
[2023-06-05T18:07:27.139+0000] {processor.py:154} INFO - Started process (PID=6428) to work on /opt/airflow/dags/process_weather_people_data_postgres/process_weather_people_data_postgres.py
[2023-06-05T18:07:27.141+0000] {processor.py:756} INFO - Processing file /opt/airflow/dags/process_weather_people_data_postgres/process_weather_people_data_postgres.py for tasks to queue
[2023-06-05T18:07:27.142+0000] {logging_mixin.py:120} INFO - [2023-06-05T18:07:27.141+0000] {dagbag.py:537} INFO - Filling up the DagBag from /opt/airflow/dags/process_weather_people_data_postgres/process_weather_people_data_postgres.py
[2023-06-05T18:07:27.146+0000] {logging_mixin.py:120} INFO - [2023-06-05T18:07:27.144+0000] {dagbag.py:342} ERROR - Failed to import: /opt/airflow/dags/process_weather_people_data_postgres/process_weather_people_data_postgres.py
Traceback (most recent call last):
  File "/home/airflow/.local/lib/python3.7/site-packages/airflow/models/dagbag.py", line 338, in parse
    loader.exec_module(new_module)
  File "<frozen importlib._bootstrap_external>", line 728, in exec_module
  File "<frozen importlib._bootstrap>", line 219, in _call_with_frames_removed
  File "/opt/airflow/dags/process_weather_people_data_postgres/process_weather_people_data_postgres.py", line 17, in <module>
    from utils.common import get_config
ModuleNotFoundError: No module named 'utils'
[2023-06-05T18:07:27.146+0000] {processor.py:768} WARNING - No viable dags retrieved from /opt/airflow/dags/process_weather_people_data_postgres/process_weather_people_data_postgres.py
[2023-06-05T18:07:27.166+0000] {processor.py:176} INFO - Processing /opt/airflow/dags/process_weather_people_data_postgres/process_weather_people_data_postgres.py took 0.029 seconds
[2023-06-05T18:07:57.330+0000] {processor.py:154} INFO - Started process (PID=6458) to work on /opt/airflow/dags/process_weather_people_data_postgres/process_weather_people_data_postgres.py
[2023-06-05T18:07:57.331+0000] {processor.py:756} INFO - Processing file /opt/airflow/dags/process_weather_people_data_postgres/process_weather_people_data_postgres.py for tasks to queue
[2023-06-05T18:07:57.332+0000] {logging_mixin.py:120} INFO - [2023-06-05T18:07:57.332+0000] {dagbag.py:537} INFO - Filling up the DagBag from /opt/airflow/dags/process_weather_people_data_postgres/process_weather_people_data_postgres.py
[2023-06-05T18:07:57.337+0000] {logging_mixin.py:120} INFO - [2023-06-05T18:07:57.336+0000] {dagbag.py:342} ERROR - Failed to import: /opt/airflow/dags/process_weather_people_data_postgres/process_weather_people_data_postgres.py
Traceback (most recent call last):
  File "/home/airflow/.local/lib/python3.7/site-packages/airflow/models/dagbag.py", line 338, in parse
    loader.exec_module(new_module)
  File "<frozen importlib._bootstrap_external>", line 728, in exec_module
  File "<frozen importlib._bootstrap>", line 219, in _call_with_frames_removed
  File "/opt/airflow/dags/process_weather_people_data_postgres/process_weather_people_data_postgres.py", line 17, in <module>
    from utils.common import get_config
ModuleNotFoundError: No module named 'utils'
[2023-06-05T18:07:57.338+0000] {processor.py:768} WARNING - No viable dags retrieved from /opt/airflow/dags/process_weather_people_data_postgres/process_weather_people_data_postgres.py
[2023-06-05T18:07:57.358+0000] {processor.py:176} INFO - Processing /opt/airflow/dags/process_weather_people_data_postgres/process_weather_people_data_postgres.py took 0.031 seconds
[2023-06-05T18:08:27.504+0000] {processor.py:154} INFO - Started process (PID=6478) to work on /opt/airflow/dags/process_weather_people_data_postgres/process_weather_people_data_postgres.py
[2023-06-05T18:08:27.505+0000] {processor.py:756} INFO - Processing file /opt/airflow/dags/process_weather_people_data_postgres/process_weather_people_data_postgres.py for tasks to queue
[2023-06-05T18:08:27.506+0000] {logging_mixin.py:120} INFO - [2023-06-05T18:08:27.506+0000] {dagbag.py:537} INFO - Filling up the DagBag from /opt/airflow/dags/process_weather_people_data_postgres/process_weather_people_data_postgres.py
[2023-06-05T18:08:27.510+0000] {logging_mixin.py:120} INFO - [2023-06-05T18:08:27.509+0000] {dagbag.py:342} ERROR - Failed to import: /opt/airflow/dags/process_weather_people_data_postgres/process_weather_people_data_postgres.py
Traceback (most recent call last):
  File "/home/airflow/.local/lib/python3.7/site-packages/airflow/models/dagbag.py", line 338, in parse
    loader.exec_module(new_module)
  File "<frozen importlib._bootstrap_external>", line 728, in exec_module
  File "<frozen importlib._bootstrap>", line 219, in _call_with_frames_removed
  File "/opt/airflow/dags/process_weather_people_data_postgres/process_weather_people_data_postgres.py", line 17, in <module>
    from utils.common import get_config
ModuleNotFoundError: No module named 'utils'
[2023-06-05T18:08:27.511+0000] {processor.py:768} WARNING - No viable dags retrieved from /opt/airflow/dags/process_weather_people_data_postgres/process_weather_people_data_postgres.py
[2023-06-05T18:08:27.529+0000] {processor.py:176} INFO - Processing /opt/airflow/dags/process_weather_people_data_postgres/process_weather_people_data_postgres.py took 0.028 seconds
[2023-06-05T18:08:57.678+0000] {processor.py:154} INFO - Started process (PID=6507) to work on /opt/airflow/dags/process_weather_people_data_postgres/process_weather_people_data_postgres.py
[2023-06-05T18:08:57.679+0000] {processor.py:756} INFO - Processing file /opt/airflow/dags/process_weather_people_data_postgres/process_weather_people_data_postgres.py for tasks to queue
[2023-06-05T18:08:57.679+0000] {logging_mixin.py:120} INFO - [2023-06-05T18:08:57.679+0000] {dagbag.py:537} INFO - Filling up the DagBag from /opt/airflow/dags/process_weather_people_data_postgres/process_weather_people_data_postgres.py
[2023-06-05T18:08:57.683+0000] {logging_mixin.py:120} INFO - [2023-06-05T18:08:57.682+0000] {dagbag.py:342} ERROR - Failed to import: /opt/airflow/dags/process_weather_people_data_postgres/process_weather_people_data_postgres.py
Traceback (most recent call last):
  File "/home/airflow/.local/lib/python3.7/site-packages/airflow/models/dagbag.py", line 338, in parse
    loader.exec_module(new_module)
  File "<frozen importlib._bootstrap_external>", line 728, in exec_module
  File "<frozen importlib._bootstrap>", line 219, in _call_with_frames_removed
  File "/opt/airflow/dags/process_weather_people_data_postgres/process_weather_people_data_postgres.py", line 17, in <module>
    from utils.common import get_config
ModuleNotFoundError: No module named 'utils'
[2023-06-05T18:08:57.684+0000] {processor.py:768} WARNING - No viable dags retrieved from /opt/airflow/dags/process_weather_people_data_postgres/process_weather_people_data_postgres.py
[2023-06-05T18:08:57.702+0000] {processor.py:176} INFO - Processing /opt/airflow/dags/process_weather_people_data_postgres/process_weather_people_data_postgres.py took 0.026 seconds
[2023-06-05T18:09:27.873+0000] {processor.py:154} INFO - Started process (PID=6538) to work on /opt/airflow/dags/process_weather_people_data_postgres/process_weather_people_data_postgres.py
[2023-06-05T18:09:27.874+0000] {processor.py:756} INFO - Processing file /opt/airflow/dags/process_weather_people_data_postgres/process_weather_people_data_postgres.py for tasks to queue
[2023-06-05T18:09:27.876+0000] {logging_mixin.py:120} INFO - [2023-06-05T18:09:27.875+0000] {dagbag.py:537} INFO - Filling up the DagBag from /opt/airflow/dags/process_weather_people_data_postgres/process_weather_people_data_postgres.py
[2023-06-05T18:09:27.880+0000] {logging_mixin.py:120} INFO - [2023-06-05T18:09:27.879+0000] {dagbag.py:342} ERROR - Failed to import: /opt/airflow/dags/process_weather_people_data_postgres/process_weather_people_data_postgres.py
Traceback (most recent call last):
  File "/home/airflow/.local/lib/python3.7/site-packages/airflow/models/dagbag.py", line 338, in parse
    loader.exec_module(new_module)
  File "<frozen importlib._bootstrap_external>", line 728, in exec_module
  File "<frozen importlib._bootstrap>", line 219, in _call_with_frames_removed
  File "/opt/airflow/dags/process_weather_people_data_postgres/process_weather_people_data_postgres.py", line 17, in <module>
    from utils.common import get_config
ModuleNotFoundError: No module named 'utils'
[2023-06-05T18:09:27.880+0000] {processor.py:768} WARNING - No viable dags retrieved from /opt/airflow/dags/process_weather_people_data_postgres/process_weather_people_data_postgres.py
[2023-06-05T18:09:27.901+0000] {processor.py:176} INFO - Processing /opt/airflow/dags/process_weather_people_data_postgres/process_weather_people_data_postgres.py took 0.031 seconds
[2023-06-05T18:09:58.048+0000] {processor.py:154} INFO - Started process (PID=6558) to work on /opt/airflow/dags/process_weather_people_data_postgres/process_weather_people_data_postgres.py
[2023-06-05T18:09:58.049+0000] {processor.py:756} INFO - Processing file /opt/airflow/dags/process_weather_people_data_postgres/process_weather_people_data_postgres.py for tasks to queue
[2023-06-05T18:09:58.050+0000] {logging_mixin.py:120} INFO - [2023-06-05T18:09:58.050+0000] {dagbag.py:537} INFO - Filling up the DagBag from /opt/airflow/dags/process_weather_people_data_postgres/process_weather_people_data_postgres.py
[2023-06-05T18:09:58.053+0000] {logging_mixin.py:120} INFO - [2023-06-05T18:09:58.052+0000] {dagbag.py:342} ERROR - Failed to import: /opt/airflow/dags/process_weather_people_data_postgres/process_weather_people_data_postgres.py
Traceback (most recent call last):
  File "/home/airflow/.local/lib/python3.7/site-packages/airflow/models/dagbag.py", line 338, in parse
    loader.exec_module(new_module)
  File "<frozen importlib._bootstrap_external>", line 728, in exec_module
  File "<frozen importlib._bootstrap>", line 219, in _call_with_frames_removed
  File "/opt/airflow/dags/process_weather_people_data_postgres/process_weather_people_data_postgres.py", line 17, in <module>
    from utils.common import get_config
ModuleNotFoundError: No module named 'utils'
[2023-06-05T18:09:58.053+0000] {processor.py:768} WARNING - No viable dags retrieved from /opt/airflow/dags/process_weather_people_data_postgres/process_weather_people_data_postgres.py
[2023-06-05T18:09:58.072+0000] {processor.py:176} INFO - Processing /opt/airflow/dags/process_weather_people_data_postgres/process_weather_people_data_postgres.py took 0.027 seconds
[2023-06-05T18:10:28.266+0000] {processor.py:154} INFO - Started process (PID=6587) to work on /opt/airflow/dags/process_weather_people_data_postgres/process_weather_people_data_postgres.py
[2023-06-05T18:10:28.270+0000] {processor.py:756} INFO - Processing file /opt/airflow/dags/process_weather_people_data_postgres/process_weather_people_data_postgres.py for tasks to queue
[2023-06-05T18:10:28.272+0000] {logging_mixin.py:120} INFO - [2023-06-05T18:10:28.271+0000] {dagbag.py:537} INFO - Filling up the DagBag from /opt/airflow/dags/process_weather_people_data_postgres/process_weather_people_data_postgres.py
[2023-06-05T18:10:28.276+0000] {logging_mixin.py:120} INFO - [2023-06-05T18:10:28.275+0000] {dagbag.py:342} ERROR - Failed to import: /opt/airflow/dags/process_weather_people_data_postgres/process_weather_people_data_postgres.py
Traceback (most recent call last):
  File "/home/airflow/.local/lib/python3.7/site-packages/airflow/models/dagbag.py", line 338, in parse
    loader.exec_module(new_module)
  File "<frozen importlib._bootstrap_external>", line 728, in exec_module
  File "<frozen importlib._bootstrap>", line 219, in _call_with_frames_removed
  File "/opt/airflow/dags/process_weather_people_data_postgres/process_weather_people_data_postgres.py", line 17, in <module>
    from utils.common import get_config
ModuleNotFoundError: No module named 'utils'
[2023-06-05T18:10:28.277+0000] {processor.py:768} WARNING - No viable dags retrieved from /opt/airflow/dags/process_weather_people_data_postgres/process_weather_people_data_postgres.py
[2023-06-05T18:10:28.302+0000] {processor.py:176} INFO - Processing /opt/airflow/dags/process_weather_people_data_postgres/process_weather_people_data_postgres.py took 0.046 seconds
[2023-06-05T18:10:58.479+0000] {processor.py:154} INFO - Started process (PID=6616) to work on /opt/airflow/dags/process_weather_people_data_postgres/process_weather_people_data_postgres.py
[2023-06-05T18:10:58.480+0000] {processor.py:756} INFO - Processing file /opt/airflow/dags/process_weather_people_data_postgres/process_weather_people_data_postgres.py for tasks to queue
[2023-06-05T18:10:58.481+0000] {logging_mixin.py:120} INFO - [2023-06-05T18:10:58.480+0000] {dagbag.py:537} INFO - Filling up the DagBag from /opt/airflow/dags/process_weather_people_data_postgres/process_weather_people_data_postgres.py
[2023-06-05T18:10:58.484+0000] {logging_mixin.py:120} INFO - [2023-06-05T18:10:58.483+0000] {dagbag.py:342} ERROR - Failed to import: /opt/airflow/dags/process_weather_people_data_postgres/process_weather_people_data_postgres.py
Traceback (most recent call last):
  File "/home/airflow/.local/lib/python3.7/site-packages/airflow/models/dagbag.py", line 338, in parse
    loader.exec_module(new_module)
  File "<frozen importlib._bootstrap_external>", line 728, in exec_module
  File "<frozen importlib._bootstrap>", line 219, in _call_with_frames_removed
  File "/opt/airflow/dags/process_weather_people_data_postgres/process_weather_people_data_postgres.py", line 17, in <module>
    from utils.common import get_config
ModuleNotFoundError: No module named 'utils'
[2023-06-05T18:10:58.485+0000] {processor.py:768} WARNING - No viable dags retrieved from /opt/airflow/dags/process_weather_people_data_postgres/process_weather_people_data_postgres.py
[2023-06-05T18:10:58.507+0000] {processor.py:176} INFO - Processing /opt/airflow/dags/process_weather_people_data_postgres/process_weather_people_data_postgres.py took 0.031 seconds
[2023-06-05T18:11:28.675+0000] {processor.py:154} INFO - Started process (PID=6636) to work on /opt/airflow/dags/process_weather_people_data_postgres/process_weather_people_data_postgres.py
[2023-06-05T18:11:28.676+0000] {processor.py:756} INFO - Processing file /opt/airflow/dags/process_weather_people_data_postgres/process_weather_people_data_postgres.py for tasks to queue
[2023-06-05T18:11:28.677+0000] {logging_mixin.py:120} INFO - [2023-06-05T18:11:28.677+0000] {dagbag.py:537} INFO - Filling up the DagBag from /opt/airflow/dags/process_weather_people_data_postgres/process_weather_people_data_postgres.py
[2023-06-05T18:11:28.681+0000] {logging_mixin.py:120} INFO - [2023-06-05T18:11:28.681+0000] {dagbag.py:342} ERROR - Failed to import: /opt/airflow/dags/process_weather_people_data_postgres/process_weather_people_data_postgres.py
Traceback (most recent call last):
  File "/home/airflow/.local/lib/python3.7/site-packages/airflow/models/dagbag.py", line 338, in parse
    loader.exec_module(new_module)
  File "<frozen importlib._bootstrap_external>", line 728, in exec_module
  File "<frozen importlib._bootstrap>", line 219, in _call_with_frames_removed
  File "/opt/airflow/dags/process_weather_people_data_postgres/process_weather_people_data_postgres.py", line 17, in <module>
    from utils.common import get_config
ModuleNotFoundError: No module named 'utils'
[2023-06-05T18:11:28.682+0000] {processor.py:768} WARNING - No viable dags retrieved from /opt/airflow/dags/process_weather_people_data_postgres/process_weather_people_data_postgres.py
[2023-06-05T18:11:28.702+0000] {processor.py:176} INFO - Processing /opt/airflow/dags/process_weather_people_data_postgres/process_weather_people_data_postgres.py took 0.030 seconds
[2023-06-05T18:11:58.833+0000] {processor.py:154} INFO - Started process (PID=6664) to work on /opt/airflow/dags/process_weather_people_data_postgres/process_weather_people_data_postgres.py
[2023-06-05T18:11:58.834+0000] {processor.py:756} INFO - Processing file /opt/airflow/dags/process_weather_people_data_postgres/process_weather_people_data_postgres.py for tasks to queue
[2023-06-05T18:11:58.834+0000] {logging_mixin.py:120} INFO - [2023-06-05T18:11:58.834+0000] {dagbag.py:537} INFO - Filling up the DagBag from /opt/airflow/dags/process_weather_people_data_postgres/process_weather_people_data_postgres.py
[2023-06-05T18:11:58.839+0000] {logging_mixin.py:120} INFO - [2023-06-05T18:11:58.838+0000] {dagbag.py:342} ERROR - Failed to import: /opt/airflow/dags/process_weather_people_data_postgres/process_weather_people_data_postgres.py
Traceback (most recent call last):
  File "/home/airflow/.local/lib/python3.7/site-packages/airflow/models/dagbag.py", line 338, in parse
    loader.exec_module(new_module)
  File "<frozen importlib._bootstrap_external>", line 728, in exec_module
  File "<frozen importlib._bootstrap>", line 219, in _call_with_frames_removed
  File "/opt/airflow/dags/process_weather_people_data_postgres/process_weather_people_data_postgres.py", line 17, in <module>
    from utils.common import get_config
ModuleNotFoundError: No module named 'utils'
[2023-06-05T18:11:58.839+0000] {processor.py:768} WARNING - No viable dags retrieved from /opt/airflow/dags/process_weather_people_data_postgres/process_weather_people_data_postgres.py
[2023-06-05T18:11:58.859+0000] {processor.py:176} INFO - Processing /opt/airflow/dags/process_weather_people_data_postgres/process_weather_people_data_postgres.py took 0.029 seconds
[2023-06-05T18:12:29.016+0000] {processor.py:154} INFO - Started process (PID=6683) to work on /opt/airflow/dags/process_weather_people_data_postgres/process_weather_people_data_postgres.py
[2023-06-05T18:12:29.018+0000] {processor.py:756} INFO - Processing file /opt/airflow/dags/process_weather_people_data_postgres/process_weather_people_data_postgres.py for tasks to queue
[2023-06-05T18:12:29.019+0000] {logging_mixin.py:120} INFO - [2023-06-05T18:12:29.019+0000] {dagbag.py:537} INFO - Filling up the DagBag from /opt/airflow/dags/process_weather_people_data_postgres/process_weather_people_data_postgres.py
[2023-06-05T18:12:29.024+0000] {logging_mixin.py:120} INFO - [2023-06-05T18:12:29.023+0000] {dagbag.py:342} ERROR - Failed to import: /opt/airflow/dags/process_weather_people_data_postgres/process_weather_people_data_postgres.py
Traceback (most recent call last):
  File "/home/airflow/.local/lib/python3.7/site-packages/airflow/models/dagbag.py", line 338, in parse
    loader.exec_module(new_module)
  File "<frozen importlib._bootstrap_external>", line 728, in exec_module
  File "<frozen importlib._bootstrap>", line 219, in _call_with_frames_removed
  File "/opt/airflow/dags/process_weather_people_data_postgres/process_weather_people_data_postgres.py", line 17, in <module>
    from utils.common import get_config
ModuleNotFoundError: No module named 'utils'
[2023-06-05T18:12:29.025+0000] {processor.py:768} WARNING - No viable dags retrieved from /opt/airflow/dags/process_weather_people_data_postgres/process_weather_people_data_postgres.py
[2023-06-05T18:12:29.045+0000] {processor.py:176} INFO - Processing /opt/airflow/dags/process_weather_people_data_postgres/process_weather_people_data_postgres.py took 0.033 seconds
[2023-06-05T18:12:59.167+0000] {processor.py:154} INFO - Started process (PID=6711) to work on /opt/airflow/dags/process_weather_people_data_postgres/process_weather_people_data_postgres.py
[2023-06-05T18:12:59.168+0000] {processor.py:756} INFO - Processing file /opt/airflow/dags/process_weather_people_data_postgres/process_weather_people_data_postgres.py for tasks to queue
[2023-06-05T18:12:59.169+0000] {logging_mixin.py:120} INFO - [2023-06-05T18:12:59.169+0000] {dagbag.py:537} INFO - Filling up the DagBag from /opt/airflow/dags/process_weather_people_data_postgres/process_weather_people_data_postgres.py
[2023-06-05T18:12:59.259+0000] {logging_mixin.py:120} INFO - [2023-06-05T18:12:59.258+0000] {dagbag.py:342} ERROR - Failed to import: /opt/airflow/dags/process_weather_people_data_postgres/process_weather_people_data_postgres.py
Traceback (most recent call last):
  File "/home/airflow/.local/lib/python3.7/site-packages/airflow/models/dagbag.py", line 338, in parse
    loader.exec_module(new_module)
  File "<frozen importlib._bootstrap_external>", line 728, in exec_module
  File "<frozen importlib._bootstrap>", line 219, in _call_with_frames_removed
  File "/opt/airflow/dags/process_weather_people_data_postgres/process_weather_people_data_postgres.py", line 51, in <module>
    start_date=datetime.strptime(dag_config['dag_args'][env]["start_date"], '%Y-%m-%d'),
  File "/usr/local/lib/python3.7/_strptime.py", line 577, in _strptime_datetime
    tt, fraction, gmtoff_fraction = _strptime(data_string, format)
  File "/usr/local/lib/python3.7/_strptime.py", line 359, in _strptime
    (data_string, format))
ValueError: time data 'yyyy-mm-dd' does not match format '%Y-%m-%d'
[2023-06-05T18:12:59.259+0000] {processor.py:768} WARNING - No viable dags retrieved from /opt/airflow/dags/process_weather_people_data_postgres/process_weather_people_data_postgres.py
[2023-06-05T18:12:59.283+0000] {processor.py:176} INFO - Processing /opt/airflow/dags/process_weather_people_data_postgres/process_weather_people_data_postgres.py took 0.119 seconds
[2023-06-05T18:13:28.425+0000] {processor.py:154} INFO - Started process (PID=6739) to work on /opt/airflow/dags/process_weather_people_data_postgres/process_weather_people_data_postgres.py
[2023-06-05T18:13:28.427+0000] {processor.py:756} INFO - Processing file /opt/airflow/dags/process_weather_people_data_postgres/process_weather_people_data_postgres.py for tasks to queue
[2023-06-05T18:13:28.428+0000] {logging_mixin.py:120} INFO - [2023-06-05T18:13:28.427+0000] {dagbag.py:537} INFO - Filling up the DagBag from /opt/airflow/dags/process_weather_people_data_postgres/process_weather_people_data_postgres.py
[2023-06-05T18:13:28.431+0000] {logging_mixin.py:120} INFO - [2023-06-05T18:13:28.429+0000] {dagbag.py:342} ERROR - Failed to import: /opt/airflow/dags/process_weather_people_data_postgres/process_weather_people_data_postgres.py
Traceback (most recent call last):
  File "/home/airflow/.local/lib/python3.7/site-packages/airflow/models/dagbag.py", line 338, in parse
    loader.exec_module(new_module)
  File "<frozen importlib._bootstrap_external>", line 724, in exec_module
  File "<frozen importlib._bootstrap_external>", line 860, in get_code
  File "<frozen importlib._bootstrap_external>", line 791, in source_to_code
  File "<frozen importlib._bootstrap>", line 219, in _call_with_frames_removed
  File "/opt/airflow/dags/process_weather_people_data_postgres/process_weather_people_data_postgres.py", line 19
    from utils
             ^
SyntaxError: invalid syntax
[2023-06-05T18:13:28.432+0000] {processor.py:768} WARNING - No viable dags retrieved from /opt/airflow/dags/process_weather_people_data_postgres/process_weather_people_data_postgres.py
[2023-06-05T18:13:28.495+0000] {processor.py:176} INFO - Processing /opt/airflow/dags/process_weather_people_data_postgres/process_weather_people_data_postgres.py took 0.078 seconds
[2023-06-05T18:13:35.482+0000] {processor.py:154} INFO - Started process (PID=6740) to work on /opt/airflow/dags/process_weather_people_data_postgres/process_weather_people_data_postgres.py
[2023-06-05T18:13:35.483+0000] {processor.py:756} INFO - Processing file /opt/airflow/dags/process_weather_people_data_postgres/process_weather_people_data_postgres.py for tasks to queue
[2023-06-05T18:13:35.485+0000] {logging_mixin.py:120} INFO - [2023-06-05T18:13:35.485+0000] {dagbag.py:537} INFO - Filling up the DagBag from /opt/airflow/dags/process_weather_people_data_postgres/process_weather_people_data_postgres.py
[2023-06-05T18:13:35.490+0000] {logging_mixin.py:120} INFO - [2023-06-05T18:13:35.488+0000] {dagbag.py:342} ERROR - Failed to import: /opt/airflow/dags/process_weather_people_data_postgres/process_weather_people_data_postgres.py
Traceback (most recent call last):
  File "/home/airflow/.local/lib/python3.7/site-packages/airflow/models/dagbag.py", line 338, in parse
    loader.exec_module(new_module)
  File "<frozen importlib._bootstrap_external>", line 724, in exec_module
  File "<frozen importlib._bootstrap_external>", line 860, in get_code
  File "<frozen importlib._bootstrap_external>", line 791, in source_to_code
  File "<frozen importlib._bootstrap>", line 219, in _call_with_frames_removed
  File "/opt/airflow/dags/process_weather_people_data_postgres/process_weather_people_data_postgres.py", line 19
    from plugins.utils.common
                            ^
SyntaxError: invalid syntax
[2023-06-05T18:13:35.491+0000] {processor.py:768} WARNING - No viable dags retrieved from /opt/airflow/dags/process_weather_people_data_postgres/process_weather_people_data_postgres.py
[2023-06-05T18:13:35.531+0000] {processor.py:176} INFO - Processing /opt/airflow/dags/process_weather_people_data_postgres/process_weather_people_data_postgres.py took 0.055 seconds
[2023-06-05T18:13:38.568+0000] {processor.py:154} INFO - Started process (PID=6741) to work on /opt/airflow/dags/process_weather_people_data_postgres/process_weather_people_data_postgres.py
[2023-06-05T18:13:38.569+0000] {processor.py:756} INFO - Processing file /opt/airflow/dags/process_weather_people_data_postgres/process_weather_people_data_postgres.py for tasks to queue
[2023-06-05T18:13:38.570+0000] {logging_mixin.py:120} INFO - [2023-06-05T18:13:38.569+0000] {dagbag.py:537} INFO - Filling up the DagBag from /opt/airflow/dags/process_weather_people_data_postgres/process_weather_people_data_postgres.py
[2023-06-05T18:13:38.577+0000] {logging_mixin.py:120} INFO - [2023-06-05T18:13:38.573+0000] {dagbag.py:342} ERROR - Failed to import: /opt/airflow/dags/process_weather_people_data_postgres/process_weather_people_data_postgres.py
Traceback (most recent call last):
  File "/home/airflow/.local/lib/python3.7/site-packages/airflow/models/dagbag.py", line 338, in parse
    loader.exec_module(new_module)
  File "<frozen importlib._bootstrap_external>", line 728, in exec_module
  File "<frozen importlib._bootstrap>", line 219, in _call_with_frames_removed
  File "/opt/airflow/dags/process_weather_people_data_postgres/process_weather_people_data_postgres.py", line 19, in <module>
    from plugins.utils.common import g
ModuleNotFoundError: No module named 'plugins'
[2023-06-05T18:13:38.578+0000] {processor.py:768} WARNING - No viable dags retrieved from /opt/airflow/dags/process_weather_people_data_postgres/process_weather_people_data_postgres.py
[2023-06-05T18:13:38.620+0000] {processor.py:176} INFO - Processing /opt/airflow/dags/process_weather_people_data_postgres/process_weather_people_data_postgres.py took 0.057 seconds
[2023-06-05T18:13:40.624+0000] {processor.py:154} INFO - Started process (PID=6751) to work on /opt/airflow/dags/process_weather_people_data_postgres/process_weather_people_data_postgres.py
[2023-06-05T18:13:40.631+0000] {processor.py:756} INFO - Processing file /opt/airflow/dags/process_weather_people_data_postgres/process_weather_people_data_postgres.py for tasks to queue
[2023-06-05T18:13:40.634+0000] {logging_mixin.py:120} INFO - [2023-06-05T18:13:40.633+0000] {dagbag.py:537} INFO - Filling up the DagBag from /opt/airflow/dags/process_weather_people_data_postgres/process_weather_people_data_postgres.py
[2023-06-05T18:13:40.660+0000] {logging_mixin.py:120} INFO - [2023-06-05T18:13:40.656+0000] {dagbag.py:342} ERROR - Failed to import: /opt/airflow/dags/process_weather_people_data_postgres/process_weather_people_data_postgres.py
Traceback (most recent call last):
  File "/home/airflow/.local/lib/python3.7/site-packages/airflow/models/dagbag.py", line 338, in parse
    loader.exec_module(new_module)
  File "<frozen importlib._bootstrap_external>", line 728, in exec_module
  File "<frozen importlib._bootstrap>", line 219, in _call_with_frames_removed
  File "/opt/airflow/dags/process_weather_people_data_postgres/process_weather_people_data_postgres.py", line 19, in <module>
    from plugins.utils.common import get_sql
ModuleNotFoundError: No module named 'plugins'
[2023-06-05T18:13:40.662+0000] {processor.py:768} WARNING - No viable dags retrieved from /opt/airflow/dags/process_weather_people_data_postgres/process_weather_people_data_postgres.py
[2023-06-05T18:13:40.734+0000] {processor.py:176} INFO - Processing /opt/airflow/dags/process_weather_people_data_postgres/process_weather_people_data_postgres.py took 0.136 seconds
[2023-06-05T18:14:10.829+0000] {processor.py:154} INFO - Started process (PID=6770) to work on /opt/airflow/dags/process_weather_people_data_postgres/process_weather_people_data_postgres.py
[2023-06-05T18:14:10.830+0000] {processor.py:756} INFO - Processing file /opt/airflow/dags/process_weather_people_data_postgres/process_weather_people_data_postgres.py for tasks to queue
[2023-06-05T18:14:10.831+0000] {logging_mixin.py:120} INFO - [2023-06-05T18:14:10.831+0000] {dagbag.py:537} INFO - Filling up the DagBag from /opt/airflow/dags/process_weather_people_data_postgres/process_weather_people_data_postgres.py
[2023-06-05T18:14:10.838+0000] {logging_mixin.py:120} INFO - [2023-06-05T18:14:10.837+0000] {dagbag.py:342} ERROR - Failed to import: /opt/airflow/dags/process_weather_people_data_postgres/process_weather_people_data_postgres.py
Traceback (most recent call last):
  File "/home/airflow/.local/lib/python3.7/site-packages/airflow/models/dagbag.py", line 338, in parse
    loader.exec_module(new_module)
  File "<frozen importlib._bootstrap_external>", line 728, in exec_module
  File "<frozen importlib._bootstrap>", line 219, in _call_with_frames_removed
  File "/opt/airflow/dags/process_weather_people_data_postgres/process_weather_people_data_postgres.py", line 19, in <module>
    from plugins.utils.common import get_sql
ModuleNotFoundError: No module named 'plugins'
[2023-06-05T18:14:10.839+0000] {processor.py:768} WARNING - No viable dags retrieved from /opt/airflow/dags/process_weather_people_data_postgres/process_weather_people_data_postgres.py
[2023-06-05T18:14:10.864+0000] {processor.py:176} INFO - Processing /opt/airflow/dags/process_weather_people_data_postgres/process_weather_people_data_postgres.py took 0.040 seconds
[2023-06-05T18:14:15.892+0000] {processor.py:154} INFO - Started process (PID=6780) to work on /opt/airflow/dags/process_weather_people_data_postgres/process_weather_people_data_postgres.py
[2023-06-05T18:14:15.894+0000] {processor.py:756} INFO - Processing file /opt/airflow/dags/process_weather_people_data_postgres/process_weather_people_data_postgres.py for tasks to queue
[2023-06-05T18:14:15.895+0000] {logging_mixin.py:120} INFO - [2023-06-05T18:14:15.895+0000] {dagbag.py:537} INFO - Filling up the DagBag from /opt/airflow/dags/process_weather_people_data_postgres/process_weather_people_data_postgres.py
[2023-06-05T18:14:15.899+0000] {logging_mixin.py:120} INFO - [2023-06-05T18:14:15.898+0000] {dagbag.py:342} ERROR - Failed to import: /opt/airflow/dags/process_weather_people_data_postgres/process_weather_people_data_postgres.py
Traceback (most recent call last):
  File "/home/airflow/.local/lib/python3.7/site-packages/airflow/models/dagbag.py", line 338, in parse
    loader.exec_module(new_module)
  File "<frozen importlib._bootstrap_external>", line 728, in exec_module
  File "<frozen importlib._bootstrap>", line 219, in _call_with_frames_removed
  File "/opt/airflow/dags/process_weather_people_data_postgres/process_weather_people_data_postgres.py", line 18, in <module>
    from plugins.utils.common import get_md
ModuleNotFoundError: No module named 'plugins'
[2023-06-05T18:14:15.899+0000] {processor.py:768} WARNING - No viable dags retrieved from /opt/airflow/dags/process_weather_people_data_postgres/process_weather_people_data_postgres.py
[2023-06-05T18:14:15.919+0000] {processor.py:176} INFO - Processing /opt/airflow/dags/process_weather_people_data_postgres/process_weather_people_data_postgres.py took 0.028 seconds
[2023-06-05T18:14:18.922+0000] {processor.py:154} INFO - Started process (PID=6781) to work on /opt/airflow/dags/process_weather_people_data_postgres/process_weather_people_data_postgres.py
[2023-06-05T18:14:18.923+0000] {processor.py:756} INFO - Processing file /opt/airflow/dags/process_weather_people_data_postgres/process_weather_people_data_postgres.py for tasks to queue
[2023-06-05T18:14:18.924+0000] {logging_mixin.py:120} INFO - [2023-06-05T18:14:18.924+0000] {dagbag.py:537} INFO - Filling up the DagBag from /opt/airflow/dags/process_weather_people_data_postgres/process_weather_people_data_postgres.py
[2023-06-05T18:14:18.928+0000] {logging_mixin.py:120} INFO - [2023-06-05T18:14:18.928+0000] {dagbag.py:342} ERROR - Failed to import: /opt/airflow/dags/process_weather_people_data_postgres/process_weather_people_data_postgres.py
Traceback (most recent call last):
  File "/home/airflow/.local/lib/python3.7/site-packages/airflow/models/dagbag.py", line 338, in parse
    loader.exec_module(new_module)
  File "<frozen importlib._bootstrap_external>", line 728, in exec_module
  File "<frozen importlib._bootstrap>", line 219, in _call_with_frames_removed
  File "/opt/airflow/dags/process_weather_people_data_postgres/process_weather_people_data_postgres.py", line 17, in <module>
    from plugins.utils.common import get_config
ModuleNotFoundError: No module named 'plugins'
[2023-06-05T18:14:18.929+0000] {processor.py:768} WARNING - No viable dags retrieved from /opt/airflow/dags/process_weather_people_data_postgres/process_weather_people_data_postgres.py
[2023-06-05T18:14:18.950+0000] {processor.py:176} INFO - Processing /opt/airflow/dags/process_weather_people_data_postgres/process_weather_people_data_postgres.py took 0.031 seconds
[2023-06-05T18:14:49.092+0000] {processor.py:154} INFO - Started process (PID=6809) to work on /opt/airflow/dags/process_weather_people_data_postgres/process_weather_people_data_postgres.py
[2023-06-05T18:14:49.094+0000] {processor.py:756} INFO - Processing file /opt/airflow/dags/process_weather_people_data_postgres/process_weather_people_data_postgres.py for tasks to queue
[2023-06-05T18:14:49.095+0000] {logging_mixin.py:120} INFO - [2023-06-05T18:14:49.094+0000] {dagbag.py:537} INFO - Filling up the DagBag from /opt/airflow/dags/process_weather_people_data_postgres/process_weather_people_data_postgres.py
[2023-06-05T18:14:49.099+0000] {logging_mixin.py:120} INFO - [2023-06-05T18:14:49.098+0000] {dagbag.py:342} ERROR - Failed to import: /opt/airflow/dags/process_weather_people_data_postgres/process_weather_people_data_postgres.py
Traceback (most recent call last):
  File "/home/airflow/.local/lib/python3.7/site-packages/airflow/models/dagbag.py", line 338, in parse
    loader.exec_module(new_module)
  File "<frozen importlib._bootstrap_external>", line 728, in exec_module
  File "<frozen importlib._bootstrap>", line 219, in _call_with_frames_removed
  File "/opt/airflow/dags/process_weather_people_data_postgres/process_weather_people_data_postgres.py", line 17, in <module>
    from plugins.utils.common import get_config
ModuleNotFoundError: No module named 'plugins'
[2023-06-05T18:14:49.100+0000] {processor.py:768} WARNING - No viable dags retrieved from /opt/airflow/dags/process_weather_people_data_postgres/process_weather_people_data_postgres.py
[2023-06-05T18:14:49.121+0000] {processor.py:176} INFO - Processing /opt/airflow/dags/process_weather_people_data_postgres/process_weather_people_data_postgres.py took 0.031 seconds
[2023-06-05T18:15:19.236+0000] {processor.py:154} INFO - Started process (PID=6828) to work on /opt/airflow/dags/process_weather_people_data_postgres/process_weather_people_data_postgres.py
[2023-06-05T18:15:19.237+0000] {processor.py:756} INFO - Processing file /opt/airflow/dags/process_weather_people_data_postgres/process_weather_people_data_postgres.py for tasks to queue
[2023-06-05T18:15:19.238+0000] {logging_mixin.py:120} INFO - [2023-06-05T18:15:19.238+0000] {dagbag.py:537} INFO - Filling up the DagBag from /opt/airflow/dags/process_weather_people_data_postgres/process_weather_people_data_postgres.py
[2023-06-05T18:15:19.241+0000] {logging_mixin.py:120} INFO - [2023-06-05T18:15:19.241+0000] {dagbag.py:342} ERROR - Failed to import: /opt/airflow/dags/process_weather_people_data_postgres/process_weather_people_data_postgres.py
Traceback (most recent call last):
  File "/home/airflow/.local/lib/python3.7/site-packages/airflow/models/dagbag.py", line 338, in parse
    loader.exec_module(new_module)
  File "<frozen importlib._bootstrap_external>", line 728, in exec_module
  File "<frozen importlib._bootstrap>", line 219, in _call_with_frames_removed
  File "/opt/airflow/dags/process_weather_people_data_postgres/process_weather_people_data_postgres.py", line 17, in <module>
    from plugins.utils.common import get_config
ModuleNotFoundError: No module named 'plugins'
[2023-06-05T18:15:19.242+0000] {processor.py:768} WARNING - No viable dags retrieved from /opt/airflow/dags/process_weather_people_data_postgres/process_weather_people_data_postgres.py
[2023-06-05T18:15:19.262+0000] {processor.py:176} INFO - Processing /opt/airflow/dags/process_weather_people_data_postgres/process_weather_people_data_postgres.py took 0.029 seconds
[2023-06-05T18:15:49.402+0000] {processor.py:154} INFO - Started process (PID=6856) to work on /opt/airflow/dags/process_weather_people_data_postgres/process_weather_people_data_postgres.py
[2023-06-05T18:15:49.403+0000] {processor.py:756} INFO - Processing file /opt/airflow/dags/process_weather_people_data_postgres/process_weather_people_data_postgres.py for tasks to queue
[2023-06-05T18:15:49.404+0000] {logging_mixin.py:120} INFO - [2023-06-05T18:15:49.404+0000] {dagbag.py:537} INFO - Filling up the DagBag from /opt/airflow/dags/process_weather_people_data_postgres/process_weather_people_data_postgres.py
[2023-06-05T18:15:49.408+0000] {logging_mixin.py:120} INFO - [2023-06-05T18:15:49.407+0000] {dagbag.py:342} ERROR - Failed to import: /opt/airflow/dags/process_weather_people_data_postgres/process_weather_people_data_postgres.py
Traceback (most recent call last):
  File "/home/airflow/.local/lib/python3.7/site-packages/airflow/models/dagbag.py", line 338, in parse
    loader.exec_module(new_module)
  File "<frozen importlib._bootstrap_external>", line 728, in exec_module
  File "<frozen importlib._bootstrap>", line 219, in _call_with_frames_removed
  File "/opt/airflow/dags/process_weather_people_data_postgres/process_weather_people_data_postgres.py", line 17, in <module>
    from plugins.utils.common import get_config
ModuleNotFoundError: No module named 'plugins'
[2023-06-05T18:15:49.409+0000] {processor.py:768} WARNING - No viable dags retrieved from /opt/airflow/dags/process_weather_people_data_postgres/process_weather_people_data_postgres.py
[2023-06-05T18:15:49.430+0000] {processor.py:176} INFO - Processing /opt/airflow/dags/process_weather_people_data_postgres/process_weather_people_data_postgres.py took 0.030 seconds
[2023-06-05T18:16:19.594+0000] {processor.py:154} INFO - Started process (PID=6884) to work on /opt/airflow/dags/process_weather_people_data_postgres/process_weather_people_data_postgres.py
[2023-06-05T18:16:19.596+0000] {processor.py:756} INFO - Processing file /opt/airflow/dags/process_weather_people_data_postgres/process_weather_people_data_postgres.py for tasks to queue
[2023-06-05T18:16:19.597+0000] {logging_mixin.py:120} INFO - [2023-06-05T18:16:19.597+0000] {dagbag.py:537} INFO - Filling up the DagBag from /opt/airflow/dags/process_weather_people_data_postgres/process_weather_people_data_postgres.py
[2023-06-05T18:16:19.602+0000] {logging_mixin.py:120} INFO - [2023-06-05T18:16:19.601+0000] {dagbag.py:342} ERROR - Failed to import: /opt/airflow/dags/process_weather_people_data_postgres/process_weather_people_data_postgres.py
Traceback (most recent call last):
  File "/home/airflow/.local/lib/python3.7/site-packages/airflow/models/dagbag.py", line 338, in parse
    loader.exec_module(new_module)
  File "<frozen importlib._bootstrap_external>", line 728, in exec_module
  File "<frozen importlib._bootstrap>", line 219, in _call_with_frames_removed
  File "/opt/airflow/dags/process_weather_people_data_postgres/process_weather_people_data_postgres.py", line 17, in <module>
    from plugins.utils.common import get_config
ModuleNotFoundError: No module named 'plugins'
[2023-06-05T18:16:19.602+0000] {processor.py:768} WARNING - No viable dags retrieved from /opt/airflow/dags/process_weather_people_data_postgres/process_weather_people_data_postgres.py
[2023-06-05T18:16:19.634+0000] {processor.py:176} INFO - Processing /opt/airflow/dags/process_weather_people_data_postgres/process_weather_people_data_postgres.py took 0.043 seconds
[2023-06-05T18:16:49.741+0000] {processor.py:154} INFO - Started process (PID=6904) to work on /opt/airflow/dags/process_weather_people_data_postgres/process_weather_people_data_postgres.py
[2023-06-05T18:16:49.742+0000] {processor.py:756} INFO - Processing file /opt/airflow/dags/process_weather_people_data_postgres/process_weather_people_data_postgres.py for tasks to queue
[2023-06-05T18:16:49.743+0000] {logging_mixin.py:120} INFO - [2023-06-05T18:16:49.743+0000] {dagbag.py:537} INFO - Filling up the DagBag from /opt/airflow/dags/process_weather_people_data_postgres/process_weather_people_data_postgres.py
[2023-06-05T18:16:49.747+0000] {logging_mixin.py:120} INFO - [2023-06-05T18:16:49.746+0000] {dagbag.py:342} ERROR - Failed to import: /opt/airflow/dags/process_weather_people_data_postgres/process_weather_people_data_postgres.py
Traceback (most recent call last):
  File "/home/airflow/.local/lib/python3.7/site-packages/airflow/models/dagbag.py", line 338, in parse
    loader.exec_module(new_module)
  File "<frozen importlib._bootstrap_external>", line 728, in exec_module
  File "<frozen importlib._bootstrap>", line 219, in _call_with_frames_removed
  File "/opt/airflow/dags/process_weather_people_data_postgres/process_weather_people_data_postgres.py", line 17, in <module>
    from plugins.utils.common import get_config
ModuleNotFoundError: No module named 'plugins'
[2023-06-05T18:16:49.747+0000] {processor.py:768} WARNING - No viable dags retrieved from /opt/airflow/dags/process_weather_people_data_postgres/process_weather_people_data_postgres.py
[2023-06-05T18:16:49.765+0000] {processor.py:176} INFO - Processing /opt/airflow/dags/process_weather_people_data_postgres/process_weather_people_data_postgres.py took 0.026 seconds
[2023-06-05T18:17:19.899+0000] {processor.py:154} INFO - Started process (PID=6932) to work on /opt/airflow/dags/process_weather_people_data_postgres/process_weather_people_data_postgres.py
[2023-06-05T18:17:19.901+0000] {processor.py:756} INFO - Processing file /opt/airflow/dags/process_weather_people_data_postgres/process_weather_people_data_postgres.py for tasks to queue
[2023-06-05T18:17:19.902+0000] {logging_mixin.py:120} INFO - [2023-06-05T18:17:19.901+0000] {dagbag.py:537} INFO - Filling up the DagBag from /opt/airflow/dags/process_weather_people_data_postgres/process_weather_people_data_postgres.py
[2023-06-05T18:17:19.905+0000] {logging_mixin.py:120} INFO - [2023-06-05T18:17:19.904+0000] {dagbag.py:342} ERROR - Failed to import: /opt/airflow/dags/process_weather_people_data_postgres/process_weather_people_data_postgres.py
Traceback (most recent call last):
  File "/home/airflow/.local/lib/python3.7/site-packages/airflow/models/dagbag.py", line 338, in parse
    loader.exec_module(new_module)
  File "<frozen importlib._bootstrap_external>", line 728, in exec_module
  File "<frozen importlib._bootstrap>", line 219, in _call_with_frames_removed
  File "/opt/airflow/dags/process_weather_people_data_postgres/process_weather_people_data_postgres.py", line 17, in <module>
    from plugins.utils.common import get_config
ModuleNotFoundError: No module named 'plugins'
[2023-06-05T18:17:19.905+0000] {processor.py:768} WARNING - No viable dags retrieved from /opt/airflow/dags/process_weather_people_data_postgres/process_weather_people_data_postgres.py
[2023-06-05T18:17:19.923+0000] {processor.py:176} INFO - Processing /opt/airflow/dags/process_weather_people_data_postgres/process_weather_people_data_postgres.py took 0.026 seconds
[2023-06-05T18:17:50.040+0000] {processor.py:154} INFO - Started process (PID=6960) to work on /opt/airflow/dags/process_weather_people_data_postgres/process_weather_people_data_postgres.py
[2023-06-05T18:17:50.041+0000] {processor.py:756} INFO - Processing file /opt/airflow/dags/process_weather_people_data_postgres/process_weather_people_data_postgres.py for tasks to queue
[2023-06-05T18:17:50.042+0000] {logging_mixin.py:120} INFO - [2023-06-05T18:17:50.042+0000] {dagbag.py:537} INFO - Filling up the DagBag from /opt/airflow/dags/process_weather_people_data_postgres/process_weather_people_data_postgres.py
[2023-06-05T18:17:50.045+0000] {logging_mixin.py:120} INFO - [2023-06-05T18:17:50.044+0000] {dagbag.py:342} ERROR - Failed to import: /opt/airflow/dags/process_weather_people_data_postgres/process_weather_people_data_postgres.py
Traceback (most recent call last):
  File "/home/airflow/.local/lib/python3.7/site-packages/airflow/models/dagbag.py", line 338, in parse
    loader.exec_module(new_module)
  File "<frozen importlib._bootstrap_external>", line 728, in exec_module
  File "<frozen importlib._bootstrap>", line 219, in _call_with_frames_removed
  File "/opt/airflow/dags/process_weather_people_data_postgres/process_weather_people_data_postgres.py", line 17, in <module>
    from plugins.utils.common import get_config
ModuleNotFoundError: No module named 'plugins'
[2023-06-05T18:17:50.046+0000] {processor.py:768} WARNING - No viable dags retrieved from /opt/airflow/dags/process_weather_people_data_postgres/process_weather_people_data_postgres.py
[2023-06-05T18:17:50.064+0000] {processor.py:176} INFO - Processing /opt/airflow/dags/process_weather_people_data_postgres/process_weather_people_data_postgres.py took 0.026 seconds
[2023-06-05T18:18:20.185+0000] {processor.py:154} INFO - Started process (PID=6979) to work on /opt/airflow/dags/process_weather_people_data_postgres/process_weather_people_data_postgres.py
[2023-06-05T18:18:20.186+0000] {processor.py:756} INFO - Processing file /opt/airflow/dags/process_weather_people_data_postgres/process_weather_people_data_postgres.py for tasks to queue
[2023-06-05T18:18:20.187+0000] {logging_mixin.py:120} INFO - [2023-06-05T18:18:20.187+0000] {dagbag.py:537} INFO - Filling up the DagBag from /opt/airflow/dags/process_weather_people_data_postgres/process_weather_people_data_postgres.py
[2023-06-05T18:18:20.190+0000] {logging_mixin.py:120} INFO - [2023-06-05T18:18:20.189+0000] {dagbag.py:342} ERROR - Failed to import: /opt/airflow/dags/process_weather_people_data_postgres/process_weather_people_data_postgres.py
Traceback (most recent call last):
  File "/home/airflow/.local/lib/python3.7/site-packages/airflow/models/dagbag.py", line 338, in parse
    loader.exec_module(new_module)
  File "<frozen importlib._bootstrap_external>", line 728, in exec_module
  File "<frozen importlib._bootstrap>", line 219, in _call_with_frames_removed
  File "/opt/airflow/dags/process_weather_people_data_postgres/process_weather_people_data_postgres.py", line 17, in <module>
    from plugins.utils.common import get_config
ModuleNotFoundError: No module named 'plugins'
[2023-06-05T18:18:20.190+0000] {processor.py:768} WARNING - No viable dags retrieved from /opt/airflow/dags/process_weather_people_data_postgres/process_weather_people_data_postgres.py
[2023-06-05T18:18:20.207+0000] {processor.py:176} INFO - Processing /opt/airflow/dags/process_weather_people_data_postgres/process_weather_people_data_postgres.py took 0.025 seconds
[2023-06-05T18:18:50.339+0000] {processor.py:154} INFO - Started process (PID=7007) to work on /opt/airflow/dags/process_weather_people_data_postgres/process_weather_people_data_postgres.py
[2023-06-05T18:18:50.339+0000] {processor.py:756} INFO - Processing file /opt/airflow/dags/process_weather_people_data_postgres/process_weather_people_data_postgres.py for tasks to queue
[2023-06-05T18:18:50.340+0000] {logging_mixin.py:120} INFO - [2023-06-05T18:18:50.340+0000] {dagbag.py:537} INFO - Filling up the DagBag from /opt/airflow/dags/process_weather_people_data_postgres/process_weather_people_data_postgres.py
[2023-06-05T18:18:50.344+0000] {logging_mixin.py:120} INFO - [2023-06-05T18:18:50.343+0000] {dagbag.py:342} ERROR - Failed to import: /opt/airflow/dags/process_weather_people_data_postgres/process_weather_people_data_postgres.py
Traceback (most recent call last):
  File "/home/airflow/.local/lib/python3.7/site-packages/airflow/models/dagbag.py", line 338, in parse
    loader.exec_module(new_module)
  File "<frozen importlib._bootstrap_external>", line 728, in exec_module
  File "<frozen importlib._bootstrap>", line 219, in _call_with_frames_removed
  File "/opt/airflow/dags/process_weather_people_data_postgres/process_weather_people_data_postgres.py", line 17, in <module>
    from plugins.utils.common import get_config
ModuleNotFoundError: No module named 'plugins'
[2023-06-05T18:18:50.344+0000] {processor.py:768} WARNING - No viable dags retrieved from /opt/airflow/dags/process_weather_people_data_postgres/process_weather_people_data_postgres.py
[2023-06-05T18:18:50.363+0000] {processor.py:176} INFO - Processing /opt/airflow/dags/process_weather_people_data_postgres/process_weather_people_data_postgres.py took 0.026 seconds
[2023-06-05T18:19:20.481+0000] {processor.py:154} INFO - Started process (PID=7035) to work on /opt/airflow/dags/process_weather_people_data_postgres/process_weather_people_data_postgres.py
[2023-06-05T18:19:20.483+0000] {processor.py:756} INFO - Processing file /opt/airflow/dags/process_weather_people_data_postgres/process_weather_people_data_postgres.py for tasks to queue
[2023-06-05T18:19:20.483+0000] {logging_mixin.py:120} INFO - [2023-06-05T18:19:20.483+0000] {dagbag.py:537} INFO - Filling up the DagBag from /opt/airflow/dags/process_weather_people_data_postgres/process_weather_people_data_postgres.py
[2023-06-05T18:19:20.487+0000] {logging_mixin.py:120} INFO - [2023-06-05T18:19:20.486+0000] {dagbag.py:342} ERROR - Failed to import: /opt/airflow/dags/process_weather_people_data_postgres/process_weather_people_data_postgres.py
Traceback (most recent call last):
  File "/home/airflow/.local/lib/python3.7/site-packages/airflow/models/dagbag.py", line 338, in parse
    loader.exec_module(new_module)
  File "<frozen importlib._bootstrap_external>", line 728, in exec_module
  File "<frozen importlib._bootstrap>", line 219, in _call_with_frames_removed
  File "/opt/airflow/dags/process_weather_people_data_postgres/process_weather_people_data_postgres.py", line 17, in <module>
    from plugins.utils.common import get_config
ModuleNotFoundError: No module named 'plugins'
[2023-06-05T18:19:20.488+0000] {processor.py:768} WARNING - No viable dags retrieved from /opt/airflow/dags/process_weather_people_data_postgres/process_weather_people_data_postgres.py
[2023-06-05T18:19:20.507+0000] {processor.py:176} INFO - Processing /opt/airflow/dags/process_weather_people_data_postgres/process_weather_people_data_postgres.py took 0.028 seconds
[2023-06-05T18:19:50.624+0000] {processor.py:154} INFO - Started process (PID=7054) to work on /opt/airflow/dags/process_weather_people_data_postgres/process_weather_people_data_postgres.py
[2023-06-05T18:19:50.625+0000] {processor.py:756} INFO - Processing file /opt/airflow/dags/process_weather_people_data_postgres/process_weather_people_data_postgres.py for tasks to queue
[2023-06-05T18:19:50.625+0000] {logging_mixin.py:120} INFO - [2023-06-05T18:19:50.625+0000] {dagbag.py:537} INFO - Filling up the DagBag from /opt/airflow/dags/process_weather_people_data_postgres/process_weather_people_data_postgres.py
[2023-06-05T18:19:50.630+0000] {logging_mixin.py:120} INFO - [2023-06-05T18:19:50.629+0000] {dagbag.py:342} ERROR - Failed to import: /opt/airflow/dags/process_weather_people_data_postgres/process_weather_people_data_postgres.py
Traceback (most recent call last):
  File "/home/airflow/.local/lib/python3.7/site-packages/airflow/models/dagbag.py", line 338, in parse
    loader.exec_module(new_module)
  File "<frozen importlib._bootstrap_external>", line 728, in exec_module
  File "<frozen importlib._bootstrap>", line 219, in _call_with_frames_removed
  File "/opt/airflow/dags/process_weather_people_data_postgres/process_weather_people_data_postgres.py", line 17, in <module>
    from plugins.utils.common import get_config
ModuleNotFoundError: No module named 'plugins'
[2023-06-05T18:19:50.630+0000] {processor.py:768} WARNING - No viable dags retrieved from /opt/airflow/dags/process_weather_people_data_postgres/process_weather_people_data_postgres.py
[2023-06-05T18:19:50.647+0000] {processor.py:176} INFO - Processing /opt/airflow/dags/process_weather_people_data_postgres/process_weather_people_data_postgres.py took 0.025 seconds
[2023-06-05T18:20:20.777+0000] {processor.py:154} INFO - Started process (PID=7082) to work on /opt/airflow/dags/process_weather_people_data_postgres/process_weather_people_data_postgres.py
[2023-06-05T18:20:20.778+0000] {processor.py:756} INFO - Processing file /opt/airflow/dags/process_weather_people_data_postgres/process_weather_people_data_postgres.py for tasks to queue
[2023-06-05T18:20:20.779+0000] {logging_mixin.py:120} INFO - [2023-06-05T18:20:20.779+0000] {dagbag.py:537} INFO - Filling up the DagBag from /opt/airflow/dags/process_weather_people_data_postgres/process_weather_people_data_postgres.py
[2023-06-05T18:20:20.782+0000] {logging_mixin.py:120} INFO - [2023-06-05T18:20:20.781+0000] {dagbag.py:342} ERROR - Failed to import: /opt/airflow/dags/process_weather_people_data_postgres/process_weather_people_data_postgres.py
Traceback (most recent call last):
  File "/home/airflow/.local/lib/python3.7/site-packages/airflow/models/dagbag.py", line 338, in parse
    loader.exec_module(new_module)
  File "<frozen importlib._bootstrap_external>", line 728, in exec_module
  File "<frozen importlib._bootstrap>", line 219, in _call_with_frames_removed
  File "/opt/airflow/dags/process_weather_people_data_postgres/process_weather_people_data_postgres.py", line 17, in <module>
    from plugins.utils.common import get_config
ModuleNotFoundError: No module named 'plugins'
[2023-06-05T18:20:20.783+0000] {processor.py:768} WARNING - No viable dags retrieved from /opt/airflow/dags/process_weather_people_data_postgres/process_weather_people_data_postgres.py
[2023-06-05T18:20:20.801+0000] {processor.py:176} INFO - Processing /opt/airflow/dags/process_weather_people_data_postgres/process_weather_people_data_postgres.py took 0.026 seconds
[2023-06-05T18:20:50.926+0000] {processor.py:154} INFO - Started process (PID=7110) to work on /opt/airflow/dags/process_weather_people_data_postgres/process_weather_people_data_postgres.py
[2023-06-05T18:20:50.928+0000] {processor.py:756} INFO - Processing file /opt/airflow/dags/process_weather_people_data_postgres/process_weather_people_data_postgres.py for tasks to queue
[2023-06-05T18:20:50.929+0000] {logging_mixin.py:120} INFO - [2023-06-05T18:20:50.929+0000] {dagbag.py:537} INFO - Filling up the DagBag from /opt/airflow/dags/process_weather_people_data_postgres/process_weather_people_data_postgres.py
[2023-06-05T18:20:50.933+0000] {logging_mixin.py:120} INFO - [2023-06-05T18:20:50.932+0000] {dagbag.py:342} ERROR - Failed to import: /opt/airflow/dags/process_weather_people_data_postgres/process_weather_people_data_postgres.py
Traceback (most recent call last):
  File "/home/airflow/.local/lib/python3.7/site-packages/airflow/models/dagbag.py", line 338, in parse
    loader.exec_module(new_module)
  File "<frozen importlib._bootstrap_external>", line 728, in exec_module
  File "<frozen importlib._bootstrap>", line 219, in _call_with_frames_removed
  File "/opt/airflow/dags/process_weather_people_data_postgres/process_weather_people_data_postgres.py", line 17, in <module>
    from plugins.utils.common import get_config
ModuleNotFoundError: No module named 'plugins'
[2023-06-05T18:20:50.933+0000] {processor.py:768} WARNING - No viable dags retrieved from /opt/airflow/dags/process_weather_people_data_postgres/process_weather_people_data_postgres.py
[2023-06-05T18:20:50.953+0000] {processor.py:176} INFO - Processing /opt/airflow/dags/process_weather_people_data_postgres/process_weather_people_data_postgres.py took 0.029 seconds
[2023-06-05T18:21:21.070+0000] {processor.py:154} INFO - Started process (PID=7129) to work on /opt/airflow/dags/process_weather_people_data_postgres/process_weather_people_data_postgres.py
[2023-06-05T18:21:21.071+0000] {processor.py:756} INFO - Processing file /opt/airflow/dags/process_weather_people_data_postgres/process_weather_people_data_postgres.py for tasks to queue
[2023-06-05T18:21:21.073+0000] {logging_mixin.py:120} INFO - [2023-06-05T18:21:21.073+0000] {dagbag.py:537} INFO - Filling up the DagBag from /opt/airflow/dags/process_weather_people_data_postgres/process_weather_people_data_postgres.py
[2023-06-05T18:21:21.076+0000] {logging_mixin.py:120} INFO - [2023-06-05T18:21:21.075+0000] {dagbag.py:342} ERROR - Failed to import: /opt/airflow/dags/process_weather_people_data_postgres/process_weather_people_data_postgres.py
Traceback (most recent call last):
  File "/home/airflow/.local/lib/python3.7/site-packages/airflow/models/dagbag.py", line 338, in parse
    loader.exec_module(new_module)
  File "<frozen importlib._bootstrap_external>", line 728, in exec_module
  File "<frozen importlib._bootstrap>", line 219, in _call_with_frames_removed
  File "/opt/airflow/dags/process_weather_people_data_postgres/process_weather_people_data_postgres.py", line 17, in <module>
    from plugins.utils.common import get_config
ModuleNotFoundError: No module named 'plugins'
[2023-06-05T18:21:21.076+0000] {processor.py:768} WARNING - No viable dags retrieved from /opt/airflow/dags/process_weather_people_data_postgres/process_weather_people_data_postgres.py
[2023-06-05T18:21:21.093+0000] {processor.py:176} INFO - Processing /opt/airflow/dags/process_weather_people_data_postgres/process_weather_people_data_postgres.py took 0.025 seconds
[2023-06-05T18:21:51.230+0000] {processor.py:154} INFO - Started process (PID=7157) to work on /opt/airflow/dags/process_weather_people_data_postgres/process_weather_people_data_postgres.py
[2023-06-05T18:21:51.232+0000] {processor.py:756} INFO - Processing file /opt/airflow/dags/process_weather_people_data_postgres/process_weather_people_data_postgres.py for tasks to queue
[2023-06-05T18:21:51.232+0000] {logging_mixin.py:120} INFO - [2023-06-05T18:21:51.232+0000] {dagbag.py:537} INFO - Filling up the DagBag from /opt/airflow/dags/process_weather_people_data_postgres/process_weather_people_data_postgres.py
[2023-06-05T18:21:51.236+0000] {logging_mixin.py:120} INFO - [2023-06-05T18:21:51.235+0000] {dagbag.py:342} ERROR - Failed to import: /opt/airflow/dags/process_weather_people_data_postgres/process_weather_people_data_postgres.py
Traceback (most recent call last):
  File "/home/airflow/.local/lib/python3.7/site-packages/airflow/models/dagbag.py", line 338, in parse
    loader.exec_module(new_module)
  File "<frozen importlib._bootstrap_external>", line 728, in exec_module
  File "<frozen importlib._bootstrap>", line 219, in _call_with_frames_removed
  File "/opt/airflow/dags/process_weather_people_data_postgres/process_weather_people_data_postgres.py", line 17, in <module>
    from plugins.utils.common import get_config
ModuleNotFoundError: No module named 'plugins'
[2023-06-05T18:21:51.236+0000] {processor.py:768} WARNING - No viable dags retrieved from /opt/airflow/dags/process_weather_people_data_postgres/process_weather_people_data_postgres.py
[2023-06-05T18:21:51.255+0000] {processor.py:176} INFO - Processing /opt/airflow/dags/process_weather_people_data_postgres/process_weather_people_data_postgres.py took 0.027 seconds
[2023-06-05T18:22:21.376+0000] {processor.py:154} INFO - Started process (PID=7185) to work on /opt/airflow/dags/process_weather_people_data_postgres/process_weather_people_data_postgres.py
[2023-06-05T18:22:21.377+0000] {processor.py:756} INFO - Processing file /opt/airflow/dags/process_weather_people_data_postgres/process_weather_people_data_postgres.py for tasks to queue
[2023-06-05T18:22:21.378+0000] {logging_mixin.py:120} INFO - [2023-06-05T18:22:21.378+0000] {dagbag.py:537} INFO - Filling up the DagBag from /opt/airflow/dags/process_weather_people_data_postgres/process_weather_people_data_postgres.py
[2023-06-05T18:22:21.381+0000] {logging_mixin.py:120} INFO - [2023-06-05T18:22:21.381+0000] {dagbag.py:342} ERROR - Failed to import: /opt/airflow/dags/process_weather_people_data_postgres/process_weather_people_data_postgres.py
Traceback (most recent call last):
  File "/home/airflow/.local/lib/python3.7/site-packages/airflow/models/dagbag.py", line 338, in parse
    loader.exec_module(new_module)
  File "<frozen importlib._bootstrap_external>", line 728, in exec_module
  File "<frozen importlib._bootstrap>", line 219, in _call_with_frames_removed
  File "/opt/airflow/dags/process_weather_people_data_postgres/process_weather_people_data_postgres.py", line 17, in <module>
    from plugins.utils.common import get_config
ModuleNotFoundError: No module named 'plugins'
[2023-06-05T18:22:21.382+0000] {processor.py:768} WARNING - No viable dags retrieved from /opt/airflow/dags/process_weather_people_data_postgres/process_weather_people_data_postgres.py
[2023-06-05T18:22:21.399+0000] {processor.py:176} INFO - Processing /opt/airflow/dags/process_weather_people_data_postgres/process_weather_people_data_postgres.py took 0.026 seconds
[2023-06-05T18:22:51.522+0000] {processor.py:154} INFO - Started process (PID=7204) to work on /opt/airflow/dags/process_weather_people_data_postgres/process_weather_people_data_postgres.py
[2023-06-05T18:22:51.523+0000] {processor.py:756} INFO - Processing file /opt/airflow/dags/process_weather_people_data_postgres/process_weather_people_data_postgres.py for tasks to queue
[2023-06-05T18:22:51.524+0000] {logging_mixin.py:120} INFO - [2023-06-05T18:22:51.524+0000] {dagbag.py:537} INFO - Filling up the DagBag from /opt/airflow/dags/process_weather_people_data_postgres/process_weather_people_data_postgres.py
[2023-06-05T18:22:51.528+0000] {logging_mixin.py:120} INFO - [2023-06-05T18:22:51.527+0000] {dagbag.py:342} ERROR - Failed to import: /opt/airflow/dags/process_weather_people_data_postgres/process_weather_people_data_postgres.py
Traceback (most recent call last):
  File "/home/airflow/.local/lib/python3.7/site-packages/airflow/models/dagbag.py", line 338, in parse
    loader.exec_module(new_module)
  File "<frozen importlib._bootstrap_external>", line 728, in exec_module
  File "<frozen importlib._bootstrap>", line 219, in _call_with_frames_removed
  File "/opt/airflow/dags/process_weather_people_data_postgres/process_weather_people_data_postgres.py", line 17, in <module>
    from plugins.utils.common import get_config
ModuleNotFoundError: No module named 'plugins'
[2023-06-05T18:22:51.528+0000] {processor.py:768} WARNING - No viable dags retrieved from /opt/airflow/dags/process_weather_people_data_postgres/process_weather_people_data_postgres.py
[2023-06-05T18:22:51.546+0000] {processor.py:176} INFO - Processing /opt/airflow/dags/process_weather_people_data_postgres/process_weather_people_data_postgres.py took 0.027 seconds
[2023-06-05T18:23:21.670+0000] {processor.py:154} INFO - Started process (PID=7232) to work on /opt/airflow/dags/process_weather_people_data_postgres/process_weather_people_data_postgres.py
[2023-06-05T18:23:21.671+0000] {processor.py:756} INFO - Processing file /opt/airflow/dags/process_weather_people_data_postgres/process_weather_people_data_postgres.py for tasks to queue
[2023-06-05T18:23:21.672+0000] {logging_mixin.py:120} INFO - [2023-06-05T18:23:21.672+0000] {dagbag.py:537} INFO - Filling up the DagBag from /opt/airflow/dags/process_weather_people_data_postgres/process_weather_people_data_postgres.py
[2023-06-05T18:23:21.675+0000] {logging_mixin.py:120} INFO - [2023-06-05T18:23:21.675+0000] {dagbag.py:342} ERROR - Failed to import: /opt/airflow/dags/process_weather_people_data_postgres/process_weather_people_data_postgres.py
Traceback (most recent call last):
  File "/home/airflow/.local/lib/python3.7/site-packages/airflow/models/dagbag.py", line 338, in parse
    loader.exec_module(new_module)
  File "<frozen importlib._bootstrap_external>", line 728, in exec_module
  File "<frozen importlib._bootstrap>", line 219, in _call_with_frames_removed
  File "/opt/airflow/dags/process_weather_people_data_postgres/process_weather_people_data_postgres.py", line 17, in <module>
    from plugins.utils.common import get_config
ModuleNotFoundError: No module named 'plugins'
[2023-06-05T18:23:21.676+0000] {processor.py:768} WARNING - No viable dags retrieved from /opt/airflow/dags/process_weather_people_data_postgres/process_weather_people_data_postgres.py
[2023-06-05T18:23:21.694+0000] {processor.py:176} INFO - Processing /opt/airflow/dags/process_weather_people_data_postgres/process_weather_people_data_postgres.py took 0.025 seconds
[2023-06-05T18:23:51.812+0000] {processor.py:154} INFO - Started process (PID=7261) to work on /opt/airflow/dags/process_weather_people_data_postgres/process_weather_people_data_postgres.py
[2023-06-05T18:23:51.813+0000] {processor.py:756} INFO - Processing file /opt/airflow/dags/process_weather_people_data_postgres/process_weather_people_data_postgres.py for tasks to queue
[2023-06-05T18:23:51.814+0000] {logging_mixin.py:120} INFO - [2023-06-05T18:23:51.814+0000] {dagbag.py:537} INFO - Filling up the DagBag from /opt/airflow/dags/process_weather_people_data_postgres/process_weather_people_data_postgres.py
[2023-06-05T18:23:51.817+0000] {logging_mixin.py:120} INFO - [2023-06-05T18:23:51.817+0000] {dagbag.py:342} ERROR - Failed to import: /opt/airflow/dags/process_weather_people_data_postgres/process_weather_people_data_postgres.py
Traceback (most recent call last):
  File "/home/airflow/.local/lib/python3.7/site-packages/airflow/models/dagbag.py", line 338, in parse
    loader.exec_module(new_module)
  File "<frozen importlib._bootstrap_external>", line 728, in exec_module
  File "<frozen importlib._bootstrap>", line 219, in _call_with_frames_removed
  File "/opt/airflow/dags/process_weather_people_data_postgres/process_weather_people_data_postgres.py", line 17, in <module>
    from plugins.utils.common import get_config
ModuleNotFoundError: No module named 'plugins'
[2023-06-05T18:23:51.818+0000] {processor.py:768} WARNING - No viable dags retrieved from /opt/airflow/dags/process_weather_people_data_postgres/process_weather_people_data_postgres.py
[2023-06-05T18:23:51.835+0000] {processor.py:176} INFO - Processing /opt/airflow/dags/process_weather_people_data_postgres/process_weather_people_data_postgres.py took 0.025 seconds
[2023-06-05T18:24:21.958+0000] {processor.py:154} INFO - Started process (PID=7280) to work on /opt/airflow/dags/process_weather_people_data_postgres/process_weather_people_data_postgres.py
[2023-06-05T18:24:21.960+0000] {processor.py:756} INFO - Processing file /opt/airflow/dags/process_weather_people_data_postgres/process_weather_people_data_postgres.py for tasks to queue
[2023-06-05T18:24:21.961+0000] {logging_mixin.py:120} INFO - [2023-06-05T18:24:21.961+0000] {dagbag.py:537} INFO - Filling up the DagBag from /opt/airflow/dags/process_weather_people_data_postgres/process_weather_people_data_postgres.py
[2023-06-05T18:24:21.964+0000] {logging_mixin.py:120} INFO - [2023-06-05T18:24:21.963+0000] {dagbag.py:342} ERROR - Failed to import: /opt/airflow/dags/process_weather_people_data_postgres/process_weather_people_data_postgres.py
Traceback (most recent call last):
  File "/home/airflow/.local/lib/python3.7/site-packages/airflow/models/dagbag.py", line 338, in parse
    loader.exec_module(new_module)
  File "<frozen importlib._bootstrap_external>", line 728, in exec_module
  File "<frozen importlib._bootstrap>", line 219, in _call_with_frames_removed
  File "/opt/airflow/dags/process_weather_people_data_postgres/process_weather_people_data_postgres.py", line 17, in <module>
    from plugins.utils.common import get_config
ModuleNotFoundError: No module named 'plugins'
[2023-06-05T18:24:21.964+0000] {processor.py:768} WARNING - No viable dags retrieved from /opt/airflow/dags/process_weather_people_data_postgres/process_weather_people_data_postgres.py
[2023-06-05T18:24:21.981+0000] {processor.py:176} INFO - Processing /opt/airflow/dags/process_weather_people_data_postgres/process_weather_people_data_postgres.py took 0.025 seconds
[2023-06-05T18:24:52.119+0000] {processor.py:154} INFO - Started process (PID=7308) to work on /opt/airflow/dags/process_weather_people_data_postgres/process_weather_people_data_postgres.py
[2023-06-05T18:24:52.119+0000] {processor.py:756} INFO - Processing file /opt/airflow/dags/process_weather_people_data_postgres/process_weather_people_data_postgres.py for tasks to queue
[2023-06-05T18:24:52.120+0000] {logging_mixin.py:120} INFO - [2023-06-05T18:24:52.120+0000] {dagbag.py:537} INFO - Filling up the DagBag from /opt/airflow/dags/process_weather_people_data_postgres/process_weather_people_data_postgres.py
[2023-06-05T18:24:52.124+0000] {logging_mixin.py:120} INFO - [2023-06-05T18:24:52.123+0000] {dagbag.py:342} ERROR - Failed to import: /opt/airflow/dags/process_weather_people_data_postgres/process_weather_people_data_postgres.py
Traceback (most recent call last):
  File "/home/airflow/.local/lib/python3.7/site-packages/airflow/models/dagbag.py", line 338, in parse
    loader.exec_module(new_module)
  File "<frozen importlib._bootstrap_external>", line 728, in exec_module
  File "<frozen importlib._bootstrap>", line 219, in _call_with_frames_removed
  File "/opt/airflow/dags/process_weather_people_data_postgres/process_weather_people_data_postgres.py", line 17, in <module>
    from plugins.utils.common import get_config
ModuleNotFoundError: No module named 'plugins'
[2023-06-05T18:24:52.124+0000] {processor.py:768} WARNING - No viable dags retrieved from /opt/airflow/dags/process_weather_people_data_postgres/process_weather_people_data_postgres.py
[2023-06-05T18:24:52.144+0000] {processor.py:176} INFO - Processing /opt/airflow/dags/process_weather_people_data_postgres/process_weather_people_data_postgres.py took 0.028 seconds
[2023-06-05T18:25:22.256+0000] {processor.py:154} INFO - Started process (PID=7336) to work on /opt/airflow/dags/process_weather_people_data_postgres/process_weather_people_data_postgres.py
[2023-06-05T18:25:22.257+0000] {processor.py:756} INFO - Processing file /opt/airflow/dags/process_weather_people_data_postgres/process_weather_people_data_postgres.py for tasks to queue
[2023-06-05T18:25:22.258+0000] {logging_mixin.py:120} INFO - [2023-06-05T18:25:22.258+0000] {dagbag.py:537} INFO - Filling up the DagBag from /opt/airflow/dags/process_weather_people_data_postgres/process_weather_people_data_postgres.py
[2023-06-05T18:25:22.261+0000] {logging_mixin.py:120} INFO - [2023-06-05T18:25:22.260+0000] {dagbag.py:342} ERROR - Failed to import: /opt/airflow/dags/process_weather_people_data_postgres/process_weather_people_data_postgres.py
Traceback (most recent call last):
  File "/home/airflow/.local/lib/python3.7/site-packages/airflow/models/dagbag.py", line 338, in parse
    loader.exec_module(new_module)
  File "<frozen importlib._bootstrap_external>", line 728, in exec_module
  File "<frozen importlib._bootstrap>", line 219, in _call_with_frames_removed
  File "/opt/airflow/dags/process_weather_people_data_postgres/process_weather_people_data_postgres.py", line 17, in <module>
    from plugins.utils.common import get_config
ModuleNotFoundError: No module named 'plugins'
[2023-06-05T18:25:22.262+0000] {processor.py:768} WARNING - No viable dags retrieved from /opt/airflow/dags/process_weather_people_data_postgres/process_weather_people_data_postgres.py
[2023-06-05T18:25:22.279+0000] {processor.py:176} INFO - Processing /opt/airflow/dags/process_weather_people_data_postgres/process_weather_people_data_postgres.py took 0.025 seconds
[2023-06-05T18:25:52.621+0000] {processor.py:154} INFO - Started process (PID=7355) to work on /opt/airflow/dags/process_weather_people_data_postgres/process_weather_people_data_postgres.py
[2023-06-05T18:25:52.624+0000] {processor.py:756} INFO - Processing file /opt/airflow/dags/process_weather_people_data_postgres/process_weather_people_data_postgres.py for tasks to queue
[2023-06-05T18:25:52.626+0000] {logging_mixin.py:120} INFO - [2023-06-05T18:25:52.625+0000] {dagbag.py:537} INFO - Filling up the DagBag from /opt/airflow/dags/process_weather_people_data_postgres/process_weather_people_data_postgres.py
[2023-06-05T18:25:52.701+0000] {logging_mixin.py:120} INFO - [2023-06-05T18:25:52.691+0000] {dagbag.py:342} ERROR - Failed to import: /opt/airflow/dags/process_weather_people_data_postgres/process_weather_people_data_postgres.py
Traceback (most recent call last):
  File "/home/airflow/.local/lib/python3.7/site-packages/airflow/models/dagbag.py", line 338, in parse
    loader.exec_module(new_module)
  File "<frozen importlib._bootstrap_external>", line 728, in exec_module
  File "<frozen importlib._bootstrap>", line 219, in _call_with_frames_removed
  File "/opt/airflow/dags/process_weather_people_data_postgres/process_weather_people_data_postgres.py", line 17, in <module>
    from plugins.utils.common import get_config
ModuleNotFoundError: No module named 'plugins'
[2023-06-05T18:25:52.703+0000] {processor.py:768} WARNING - No viable dags retrieved from /opt/airflow/dags/process_weather_people_data_postgres/process_weather_people_data_postgres.py
[2023-06-05T18:25:52.844+0000] {processor.py:176} INFO - Processing /opt/airflow/dags/process_weather_people_data_postgres/process_weather_people_data_postgres.py took 0.301 seconds
[2023-06-05T19:19:48.310+0000] {processor.py:154} INFO - Started process (PID=7374) to work on /opt/airflow/dags/process_weather_people_data_postgres/process_weather_people_data_postgres.py
[2023-06-05T19:19:48.311+0000] {processor.py:756} INFO - Processing file /opt/airflow/dags/process_weather_people_data_postgres/process_weather_people_data_postgres.py for tasks to queue
[2023-06-05T19:19:48.312+0000] {logging_mixin.py:120} INFO - [2023-06-05T19:19:48.312+0000] {dagbag.py:537} INFO - Filling up the DagBag from /opt/airflow/dags/process_weather_people_data_postgres/process_weather_people_data_postgres.py
[2023-06-05T19:19:48.315+0000] {logging_mixin.py:120} INFO - [2023-06-05T19:19:48.314+0000] {dagbag.py:342} ERROR - Failed to import: /opt/airflow/dags/process_weather_people_data_postgres/process_weather_people_data_postgres.py
Traceback (most recent call last):
  File "/home/airflow/.local/lib/python3.7/site-packages/airflow/models/dagbag.py", line 338, in parse
    loader.exec_module(new_module)
  File "<frozen importlib._bootstrap_external>", line 728, in exec_module
  File "<frozen importlib._bootstrap>", line 219, in _call_with_frames_removed
  File "/opt/airflow/dags/process_weather_people_data_postgres/process_weather_people_data_postgres.py", line 17, in <module>
    from plugins.utils.common import get_config
ModuleNotFoundError: No module named 'plugins'
[2023-06-05T19:19:48.316+0000] {processor.py:768} WARNING - No viable dags retrieved from /opt/airflow/dags/process_weather_people_data_postgres/process_weather_people_data_postgres.py
[2023-06-05T19:19:48.335+0000] {processor.py:176} INFO - Processing /opt/airflow/dags/process_weather_people_data_postgres/process_weather_people_data_postgres.py took 0.028 seconds
[2023-06-05T19:20:02.395+0000] {processor.py:154} INFO - Started process (PID=7393) to work on /opt/airflow/dags/process_weather_people_data_postgres/process_weather_people_data_postgres.py
[2023-06-05T19:20:02.396+0000] {processor.py:756} INFO - Processing file /opt/airflow/dags/process_weather_people_data_postgres/process_weather_people_data_postgres.py for tasks to queue
[2023-06-05T19:20:02.397+0000] {logging_mixin.py:120} INFO - [2023-06-05T19:20:02.397+0000] {dagbag.py:537} INFO - Filling up the DagBag from /opt/airflow/dags/process_weather_people_data_postgres/process_weather_people_data_postgres.py
[2023-06-05T19:20:02.406+0000] {logging_mixin.py:120} INFO - [2023-06-05T19:20:02.403+0000] {dagbag.py:342} ERROR - Failed to import: /opt/airflow/dags/process_weather_people_data_postgres/process_weather_people_data_postgres.py
Traceback (most recent call last):
  File "/home/airflow/.local/lib/python3.7/site-packages/airflow/models/dagbag.py", line 338, in parse
    loader.exec_module(new_module)
  File "<frozen importlib._bootstrap_external>", line 728, in exec_module
  File "<frozen importlib._bootstrap>", line 219, in _call_with_frames_removed
  File "/opt/airflow/dags/process_weather_people_data_postgres/process_weather_people_data_postgres.py", line 17, in <module>
    from ut import get_config
ModuleNotFoundError: No module named 'ut'
[2023-06-05T19:20:02.407+0000] {processor.py:768} WARNING - No viable dags retrieved from /opt/airflow/dags/process_weather_people_data_postgres/process_weather_people_data_postgres.py
[2023-06-05T19:20:02.440+0000] {processor.py:176} INFO - Processing /opt/airflow/dags/process_weather_people_data_postgres/process_weather_people_data_postgres.py took 0.053 seconds
[2023-06-05T19:20:04.419+0000] {processor.py:154} INFO - Started process (PID=7394) to work on /opt/airflow/dags/process_weather_people_data_postgres/process_weather_people_data_postgres.py
[2023-06-05T19:20:04.419+0000] {processor.py:756} INFO - Processing file /opt/airflow/dags/process_weather_people_data_postgres/process_weather_people_data_postgres.py for tasks to queue
[2023-06-05T19:20:04.420+0000] {logging_mixin.py:120} INFO - [2023-06-05T19:20:04.420+0000] {dagbag.py:537} INFO - Filling up the DagBag from /opt/airflow/dags/process_weather_people_data_postgres/process_weather_people_data_postgres.py
[2023-06-05T19:20:04.422+0000] {logging_mixin.py:120} INFO - [2023-06-05T19:20:04.421+0000] {dagbag.py:342} ERROR - Failed to import: /opt/airflow/dags/process_weather_people_data_postgres/process_weather_people_data_postgres.py
Traceback (most recent call last):
  File "/home/airflow/.local/lib/python3.7/site-packages/airflow/models/dagbag.py", line 338, in parse
    loader.exec_module(new_module)
  File "<frozen importlib._bootstrap_external>", line 724, in exec_module
  File "<frozen importlib._bootstrap_external>", line 860, in get_code
  File "<frozen importlib._bootstrap_external>", line 791, in source_to_code
  File "<frozen importlib._bootstrap>", line 219, in _call_with_frames_removed
  File "/opt/airflow/dags/process_weather_people_data_postgres/process_weather_people_data_postgres.py", line 17
    from utils. import get_config
                     ^
SyntaxError: invalid syntax
[2023-06-05T19:20:04.423+0000] {processor.py:768} WARNING - No viable dags retrieved from /opt/airflow/dags/process_weather_people_data_postgres/process_weather_people_data_postgres.py
[2023-06-05T19:20:04.441+0000] {processor.py:176} INFO - Processing /opt/airflow/dags/process_weather_people_data_postgres/process_weather_people_data_postgres.py took 0.025 seconds
[2023-06-05T19:20:07.438+0000] {processor.py:154} INFO - Started process (PID=7395) to work on /opt/airflow/dags/process_weather_people_data_postgres/process_weather_people_data_postgres.py
[2023-06-05T19:20:07.439+0000] {processor.py:756} INFO - Processing file /opt/airflow/dags/process_weather_people_data_postgres/process_weather_people_data_postgres.py for tasks to queue
[2023-06-05T19:20:07.439+0000] {logging_mixin.py:120} INFO - [2023-06-05T19:20:07.439+0000] {dagbag.py:537} INFO - Filling up the DagBag from /opt/airflow/dags/process_weather_people_data_postgres/process_weather_people_data_postgres.py
[2023-06-05T19:20:07.444+0000] {logging_mixin.py:120} INFO - [2023-06-05T19:20:07.443+0000] {dagbag.py:342} ERROR - Failed to import: /opt/airflow/dags/process_weather_people_data_postgres/process_weather_people_data_postgres.py
Traceback (most recent call last):
  File "/home/airflow/.local/lib/python3.7/site-packages/airflow/models/dagbag.py", line 338, in parse
    loader.exec_module(new_module)
  File "<frozen importlib._bootstrap_external>", line 728, in exec_module
  File "<frozen importlib._bootstrap>", line 219, in _call_with_frames_removed
  File "/opt/airflow/dags/process_weather_people_data_postgres/process_weather_people_data_postgres.py", line 18, in <module>
    from plugins.utils.common import get_md
ModuleNotFoundError: No module named 'plugins'
[2023-06-05T19:20:07.445+0000] {processor.py:768} WARNING - No viable dags retrieved from /opt/airflow/dags/process_weather_people_data_postgres/process_weather_people_data_postgres.py
[2023-06-05T19:20:07.465+0000] {processor.py:176} INFO - Processing /opt/airflow/dags/process_weather_people_data_postgres/process_weather_people_data_postgres.py took 0.029 seconds
[2023-06-05T19:20:37.607+0000] {processor.py:154} INFO - Started process (PID=7423) to work on /opt/airflow/dags/process_weather_people_data_postgres/process_weather_people_data_postgres.py
[2023-06-05T19:20:37.608+0000] {processor.py:756} INFO - Processing file /opt/airflow/dags/process_weather_people_data_postgres/process_weather_people_data_postgres.py for tasks to queue
[2023-06-05T19:20:37.609+0000] {logging_mixin.py:120} INFO - [2023-06-05T19:20:37.609+0000] {dagbag.py:537} INFO - Filling up the DagBag from /opt/airflow/dags/process_weather_people_data_postgres/process_weather_people_data_postgres.py
[2023-06-05T19:20:37.613+0000] {logging_mixin.py:120} INFO - [2023-06-05T19:20:37.612+0000] {dagbag.py:342} ERROR - Failed to import: /opt/airflow/dags/process_weather_people_data_postgres/process_weather_people_data_postgres.py
Traceback (most recent call last):
  File "/home/airflow/.local/lib/python3.7/site-packages/airflow/models/dagbag.py", line 338, in parse
    loader.exec_module(new_module)
  File "<frozen importlib._bootstrap_external>", line 728, in exec_module
  File "<frozen importlib._bootstrap>", line 219, in _call_with_frames_removed
  File "/opt/airflow/dags/process_weather_people_data_postgres/process_weather_people_data_postgres.py", line 18, in <module>
    from plugins.utils.common import get_md
ModuleNotFoundError: No module named 'plugins'
[2023-06-05T19:20:37.613+0000] {processor.py:768} WARNING - No viable dags retrieved from /opt/airflow/dags/process_weather_people_data_postgres/process_weather_people_data_postgres.py
[2023-06-05T19:20:37.631+0000] {processor.py:176} INFO - Processing /opt/airflow/dags/process_weather_people_data_postgres/process_weather_people_data_postgres.py took 0.026 seconds
[2023-06-05T19:21:07.757+0000] {processor.py:154} INFO - Started process (PID=7442) to work on /opt/airflow/dags/process_weather_people_data_postgres/process_weather_people_data_postgres.py
[2023-06-05T19:21:07.758+0000] {processor.py:756} INFO - Processing file /opt/airflow/dags/process_weather_people_data_postgres/process_weather_people_data_postgres.py for tasks to queue
[2023-06-05T19:21:07.758+0000] {logging_mixin.py:120} INFO - [2023-06-05T19:21:07.758+0000] {dagbag.py:537} INFO - Filling up the DagBag from /opt/airflow/dags/process_weather_people_data_postgres/process_weather_people_data_postgres.py
[2023-06-05T19:21:07.763+0000] {logging_mixin.py:120} INFO - [2023-06-05T19:21:07.762+0000] {dagbag.py:342} ERROR - Failed to import: /opt/airflow/dags/process_weather_people_data_postgres/process_weather_people_data_postgres.py
Traceback (most recent call last):
  File "/home/airflow/.local/lib/python3.7/site-packages/airflow/models/dagbag.py", line 338, in parse
    loader.exec_module(new_module)
  File "<frozen importlib._bootstrap_external>", line 728, in exec_module
  File "<frozen importlib._bootstrap>", line 219, in _call_with_frames_removed
  File "/opt/airflow/dags/process_weather_people_data_postgres/process_weather_people_data_postgres.py", line 18, in <module>
    from plugins.utils.common import get_md
ModuleNotFoundError: No module named 'plugins'
[2023-06-05T19:21:07.764+0000] {processor.py:768} WARNING - No viable dags retrieved from /opt/airflow/dags/process_weather_people_data_postgres/process_weather_people_data_postgres.py
[2023-06-05T19:21:07.783+0000] {processor.py:176} INFO - Processing /opt/airflow/dags/process_weather_people_data_postgres/process_weather_people_data_postgres.py took 0.028 seconds
[2023-06-05T19:23:27.187+0000] {processor.py:154} INFO - Started process (PID=64) to work on /opt/airflow/dags/process_weather_people_data_postgres/process_weather_people_data_postgres.py
[2023-06-05T19:23:27.189+0000] {processor.py:756} INFO - Processing file /opt/airflow/dags/process_weather_people_data_postgres/process_weather_people_data_postgres.py for tasks to queue
[2023-06-05T19:23:27.191+0000] {logging_mixin.py:120} INFO - [2023-06-05T19:23:27.190+0000] {dagbag.py:537} INFO - Filling up the DagBag from /opt/airflow/dags/process_weather_people_data_postgres/process_weather_people_data_postgres.py
[2023-06-05T19:23:27.218+0000] {logging_mixin.py:120} INFO - [2023-06-05T19:23:27.215+0000] {dagbag.py:342} ERROR - Failed to import: /opt/airflow/dags/process_weather_people_data_postgres/process_weather_people_data_postgres.py
Traceback (most recent call last):
  File "/home/airflow/.local/lib/python3.7/site-packages/airflow/models/dagbag.py", line 338, in parse
    loader.exec_module(new_module)
  File "<frozen importlib._bootstrap_external>", line 728, in exec_module
  File "<frozen importlib._bootstrap>", line 219, in _call_with_frames_removed
  File "/opt/airflow/dags/process_weather_people_data_postgres/process_weather_people_data_postgres.py", line 18, in <module>
    from plugins.utils.common import get_md
ModuleNotFoundError: No module named 'plugins'
[2023-06-05T19:23:27.220+0000] {processor.py:768} WARNING - No viable dags retrieved from /opt/airflow/dags/process_weather_people_data_postgres/process_weather_people_data_postgres.py
[2023-06-05T19:23:27.275+0000] {processor.py:176} INFO - Processing /opt/airflow/dags/process_weather_people_data_postgres/process_weather_people_data_postgres.py took 0.092 seconds
[2023-06-05T19:23:57.387+0000] {processor.py:154} INFO - Started process (PID=83) to work on /opt/airflow/dags/process_weather_people_data_postgres/process_weather_people_data_postgres.py
[2023-06-05T19:23:57.389+0000] {processor.py:756} INFO - Processing file /opt/airflow/dags/process_weather_people_data_postgres/process_weather_people_data_postgres.py for tasks to queue
[2023-06-05T19:23:57.391+0000] {logging_mixin.py:120} INFO - [2023-06-05T19:23:57.391+0000] {dagbag.py:537} INFO - Filling up the DagBag from /opt/airflow/dags/process_weather_people_data_postgres/process_weather_people_data_postgres.py
[2023-06-05T19:23:57.398+0000] {logging_mixin.py:120} INFO - [2023-06-05T19:23:57.396+0000] {dagbag.py:342} ERROR - Failed to import: /opt/airflow/dags/process_weather_people_data_postgres/process_weather_people_data_postgres.py
Traceback (most recent call last):
  File "/home/airflow/.local/lib/python3.7/site-packages/airflow/models/dagbag.py", line 338, in parse
    loader.exec_module(new_module)
  File "<frozen importlib._bootstrap_external>", line 728, in exec_module
  File "<frozen importlib._bootstrap>", line 219, in _call_with_frames_removed
  File "/opt/airflow/dags/process_weather_people_data_postgres/process_weather_people_data_postgres.py", line 18, in <module>
    from plugins.utils.common import get_md
ModuleNotFoundError: No module named 'plugins'
[2023-06-05T19:23:57.399+0000] {processor.py:768} WARNING - No viable dags retrieved from /opt/airflow/dags/process_weather_people_data_postgres/process_weather_people_data_postgres.py
[2023-06-05T19:23:57.434+0000] {processor.py:176} INFO - Processing /opt/airflow/dags/process_weather_people_data_postgres/process_weather_people_data_postgres.py took 0.052 seconds
[2023-06-05T19:24:27.612+0000] {processor.py:154} INFO - Started process (PID=111) to work on /opt/airflow/dags/process_weather_people_data_postgres/process_weather_people_data_postgres.py
[2023-06-05T19:24:27.614+0000] {processor.py:756} INFO - Processing file /opt/airflow/dags/process_weather_people_data_postgres/process_weather_people_data_postgres.py for tasks to queue
[2023-06-05T19:24:27.615+0000] {logging_mixin.py:120} INFO - [2023-06-05T19:24:27.615+0000] {dagbag.py:537} INFO - Filling up the DagBag from /opt/airflow/dags/process_weather_people_data_postgres/process_weather_people_data_postgres.py
[2023-06-05T19:24:27.623+0000] {logging_mixin.py:120} INFO - [2023-06-05T19:24:27.620+0000] {dagbag.py:342} ERROR - Failed to import: /opt/airflow/dags/process_weather_people_data_postgres/process_weather_people_data_postgres.py
Traceback (most recent call last):
  File "/home/airflow/.local/lib/python3.7/site-packages/airflow/models/dagbag.py", line 338, in parse
    loader.exec_module(new_module)
  File "<frozen importlib._bootstrap_external>", line 728, in exec_module
  File "<frozen importlib._bootstrap>", line 219, in _call_with_frames_removed
  File "/opt/airflow/dags/process_weather_people_data_postgres/process_weather_people_data_postgres.py", line 18, in <module>
    from plugins.utils.common import get_md
ModuleNotFoundError: No module named 'plugins'
[2023-06-05T19:24:27.623+0000] {processor.py:768} WARNING - No viable dags retrieved from /opt/airflow/dags/process_weather_people_data_postgres/process_weather_people_data_postgres.py
[2023-06-05T19:24:27.653+0000] {processor.py:176} INFO - Processing /opt/airflow/dags/process_weather_people_data_postgres/process_weather_people_data_postgres.py took 0.046 seconds
[2023-06-05T19:24:57.830+0000] {processor.py:154} INFO - Started process (PID=130) to work on /opt/airflow/dags/process_weather_people_data_postgres/process_weather_people_data_postgres.py
[2023-06-05T19:24:57.831+0000] {processor.py:756} INFO - Processing file /opt/airflow/dags/process_weather_people_data_postgres/process_weather_people_data_postgres.py for tasks to queue
[2023-06-05T19:24:57.832+0000] {logging_mixin.py:120} INFO - [2023-06-05T19:24:57.832+0000] {dagbag.py:537} INFO - Filling up the DagBag from /opt/airflow/dags/process_weather_people_data_postgres/process_weather_people_data_postgres.py
[2023-06-05T19:24:57.838+0000] {logging_mixin.py:120} INFO - [2023-06-05T19:24:57.837+0000] {dagbag.py:342} ERROR - Failed to import: /opt/airflow/dags/process_weather_people_data_postgres/process_weather_people_data_postgres.py
Traceback (most recent call last):
  File "/home/airflow/.local/lib/python3.7/site-packages/airflow/models/dagbag.py", line 338, in parse
    loader.exec_module(new_module)
  File "<frozen importlib._bootstrap_external>", line 728, in exec_module
  File "<frozen importlib._bootstrap>", line 219, in _call_with_frames_removed
  File "/opt/airflow/dags/process_weather_people_data_postgres/process_weather_people_data_postgres.py", line 18, in <module>
    from plugins.utils.common import get_md
ModuleNotFoundError: No module named 'plugins'
[2023-06-05T19:24:57.838+0000] {processor.py:768} WARNING - No viable dags retrieved from /opt/airflow/dags/process_weather_people_data_postgres/process_weather_people_data_postgres.py
[2023-06-05T19:24:57.868+0000] {processor.py:176} INFO - Processing /opt/airflow/dags/process_weather_people_data_postgres/process_weather_people_data_postgres.py took 0.042 seconds
[2023-06-05T19:25:27.983+0000] {processor.py:154} INFO - Started process (PID=159) to work on /opt/airflow/dags/process_weather_people_data_postgres/process_weather_people_data_postgres.py
[2023-06-05T19:25:27.983+0000] {processor.py:756} INFO - Processing file /opt/airflow/dags/process_weather_people_data_postgres/process_weather_people_data_postgres.py for tasks to queue
[2023-06-05T19:25:27.984+0000] {logging_mixin.py:120} INFO - [2023-06-05T19:25:27.984+0000] {dagbag.py:537} INFO - Filling up the DagBag from /opt/airflow/dags/process_weather_people_data_postgres/process_weather_people_data_postgres.py
[2023-06-05T19:25:27.988+0000] {logging_mixin.py:120} INFO - [2023-06-05T19:25:27.986+0000] {dagbag.py:342} ERROR - Failed to import: /opt/airflow/dags/process_weather_people_data_postgres/process_weather_people_data_postgres.py
Traceback (most recent call last):
  File "/home/airflow/.local/lib/python3.7/site-packages/airflow/models/dagbag.py", line 338, in parse
    loader.exec_module(new_module)
  File "<frozen importlib._bootstrap_external>", line 728, in exec_module
  File "<frozen importlib._bootstrap>", line 219, in _call_with_frames_removed
  File "/opt/airflow/dags/process_weather_people_data_postgres/process_weather_people_data_postgres.py", line 18, in <module>
    from plugins.utils.common import get_md
ModuleNotFoundError: No module named 'plugins'
[2023-06-05T19:25:27.988+0000] {processor.py:768} WARNING - No viable dags retrieved from /opt/airflow/dags/process_weather_people_data_postgres/process_weather_people_data_postgres.py
[2023-06-05T19:25:28.008+0000] {processor.py:176} INFO - Processing /opt/airflow/dags/process_weather_people_data_postgres/process_weather_people_data_postgres.py took 0.029 seconds
[2023-06-05T19:25:58.142+0000] {processor.py:154} INFO - Started process (PID=178) to work on /opt/airflow/dags/process_weather_people_data_postgres/process_weather_people_data_postgres.py
[2023-06-05T19:25:58.144+0000] {processor.py:756} INFO - Processing file /opt/airflow/dags/process_weather_people_data_postgres/process_weather_people_data_postgres.py for tasks to queue
[2023-06-05T19:25:58.145+0000] {logging_mixin.py:120} INFO - [2023-06-05T19:25:58.145+0000] {dagbag.py:537} INFO - Filling up the DagBag from /opt/airflow/dags/process_weather_people_data_postgres/process_weather_people_data_postgres.py
[2023-06-05T19:25:58.148+0000] {logging_mixin.py:120} INFO - [2023-06-05T19:25:58.147+0000] {dagbag.py:342} ERROR - Failed to import: /opt/airflow/dags/process_weather_people_data_postgres/process_weather_people_data_postgres.py
Traceback (most recent call last):
  File "/home/airflow/.local/lib/python3.7/site-packages/airflow/models/dagbag.py", line 338, in parse
    loader.exec_module(new_module)
  File "<frozen importlib._bootstrap_external>", line 728, in exec_module
  File "<frozen importlib._bootstrap>", line 219, in _call_with_frames_removed
  File "/opt/airflow/dags/process_weather_people_data_postgres/process_weather_people_data_postgres.py", line 18, in <module>
    from plugins.utils.common import get_md
ModuleNotFoundError: No module named 'plugins'
[2023-06-05T19:25:58.149+0000] {processor.py:768} WARNING - No viable dags retrieved from /opt/airflow/dags/process_weather_people_data_postgres/process_weather_people_data_postgres.py
[2023-06-05T19:25:58.168+0000] {processor.py:176} INFO - Processing /opt/airflow/dags/process_weather_people_data_postgres/process_weather_people_data_postgres.py took 0.028 seconds
[2023-06-05T19:26:28.308+0000] {processor.py:154} INFO - Started process (PID=206) to work on /opt/airflow/dags/process_weather_people_data_postgres/process_weather_people_data_postgres.py
[2023-06-05T19:26:28.309+0000] {processor.py:756} INFO - Processing file /opt/airflow/dags/process_weather_people_data_postgres/process_weather_people_data_postgres.py for tasks to queue
[2023-06-05T19:26:28.309+0000] {logging_mixin.py:120} INFO - [2023-06-05T19:26:28.309+0000] {dagbag.py:537} INFO - Filling up the DagBag from /opt/airflow/dags/process_weather_people_data_postgres/process_weather_people_data_postgres.py
[2023-06-05T19:26:28.313+0000] {logging_mixin.py:120} INFO - [2023-06-05T19:26:28.312+0000] {dagbag.py:342} ERROR - Failed to import: /opt/airflow/dags/process_weather_people_data_postgres/process_weather_people_data_postgres.py
Traceback (most recent call last):
  File "/home/airflow/.local/lib/python3.7/site-packages/airflow/models/dagbag.py", line 338, in parse
    loader.exec_module(new_module)
  File "<frozen importlib._bootstrap_external>", line 728, in exec_module
  File "<frozen importlib._bootstrap>", line 219, in _call_with_frames_removed
  File "/opt/airflow/dags/process_weather_people_data_postgres/process_weather_people_data_postgres.py", line 18, in <module>
    from plugins.utils.common import get_md
ModuleNotFoundError: No module named 'plugins'
[2023-06-05T19:26:28.313+0000] {processor.py:768} WARNING - No viable dags retrieved from /opt/airflow/dags/process_weather_people_data_postgres/process_weather_people_data_postgres.py
[2023-06-05T19:26:28.332+0000] {processor.py:176} INFO - Processing /opt/airflow/dags/process_weather_people_data_postgres/process_weather_people_data_postgres.py took 0.027 seconds
[2023-06-05T19:26:58.465+0000] {processor.py:154} INFO - Started process (PID=234) to work on /opt/airflow/dags/process_weather_people_data_postgres/process_weather_people_data_postgres.py
[2023-06-05T19:26:58.466+0000] {processor.py:756} INFO - Processing file /opt/airflow/dags/process_weather_people_data_postgres/process_weather_people_data_postgres.py for tasks to queue
[2023-06-05T19:26:58.467+0000] {logging_mixin.py:120} INFO - [2023-06-05T19:26:58.467+0000] {dagbag.py:537} INFO - Filling up the DagBag from /opt/airflow/dags/process_weather_people_data_postgres/process_weather_people_data_postgres.py
[2023-06-05T19:26:58.471+0000] {logging_mixin.py:120} INFO - [2023-06-05T19:26:58.470+0000] {dagbag.py:342} ERROR - Failed to import: /opt/airflow/dags/process_weather_people_data_postgres/process_weather_people_data_postgres.py
Traceback (most recent call last):
  File "/home/airflow/.local/lib/python3.7/site-packages/airflow/models/dagbag.py", line 338, in parse
    loader.exec_module(new_module)
  File "<frozen importlib._bootstrap_external>", line 728, in exec_module
  File "<frozen importlib._bootstrap>", line 219, in _call_with_frames_removed
  File "/opt/airflow/dags/process_weather_people_data_postgres/process_weather_people_data_postgres.py", line 18, in <module>
    from plugins.utils.common import get_md
ModuleNotFoundError: No module named 'plugins'
[2023-06-05T19:26:58.472+0000] {processor.py:768} WARNING - No viable dags retrieved from /opt/airflow/dags/process_weather_people_data_postgres/process_weather_people_data_postgres.py
[2023-06-05T19:26:58.493+0000] {processor.py:176} INFO - Processing /opt/airflow/dags/process_weather_people_data_postgres/process_weather_people_data_postgres.py took 0.032 seconds
[2023-06-05T19:27:28.633+0000] {processor.py:154} INFO - Started process (PID=253) to work on /opt/airflow/dags/process_weather_people_data_postgres/process_weather_people_data_postgres.py
[2023-06-05T19:27:28.634+0000] {processor.py:756} INFO - Processing file /opt/airflow/dags/process_weather_people_data_postgres/process_weather_people_data_postgres.py for tasks to queue
[2023-06-05T19:27:28.635+0000] {logging_mixin.py:120} INFO - [2023-06-05T19:27:28.635+0000] {dagbag.py:537} INFO - Filling up the DagBag from /opt/airflow/dags/process_weather_people_data_postgres/process_weather_people_data_postgres.py
[2023-06-05T19:27:28.641+0000] {logging_mixin.py:120} INFO - [2023-06-05T19:27:28.639+0000] {dagbag.py:342} ERROR - Failed to import: /opt/airflow/dags/process_weather_people_data_postgres/process_weather_people_data_postgres.py
Traceback (most recent call last):
  File "/home/airflow/.local/lib/python3.7/site-packages/airflow/models/dagbag.py", line 338, in parse
    loader.exec_module(new_module)
  File "<frozen importlib._bootstrap_external>", line 728, in exec_module
  File "<frozen importlib._bootstrap>", line 219, in _call_with_frames_removed
  File "/opt/airflow/dags/process_weather_people_data_postgres/process_weather_people_data_postgres.py", line 18, in <module>
    from plugins.utils.common import get_md
ModuleNotFoundError: No module named 'plugins'
[2023-06-05T19:27:28.642+0000] {processor.py:768} WARNING - No viable dags retrieved from /opt/airflow/dags/process_weather_people_data_postgres/process_weather_people_data_postgres.py
[2023-06-05T19:27:28.680+0000] {processor.py:176} INFO - Processing /opt/airflow/dags/process_weather_people_data_postgres/process_weather_people_data_postgres.py took 0.051 seconds
