[2023-06-06T00:00:16.056+0000] {processor.py:154} INFO - Started process (PID=14348) to work on /opt/airflow/dags/process_weather_people_postgres/process_weather_people_postgres.py
[2023-06-06T00:00:16.057+0000] {processor.py:756} INFO - Processing file /opt/airflow/dags/process_weather_people_postgres/process_weather_people_postgres.py for tasks to queue
[2023-06-06T00:00:16.058+0000] {logging_mixin.py:120} INFO - [2023-06-06T00:00:16.058+0000] {dagbag.py:537} INFO - Filling up the DagBag from /opt/airflow/dags/process_weather_people_postgres/process_weather_people_postgres.py
[2023-06-06T00:00:16.637+0000] {logging_mixin.py:120} INFO - [2023-06-06T00:00:16.636+0000] {taskmixin.py:205} WARNING - Dependency <Task(PostgresOperator): create_users_table>, group_users.is_1_api_available already registered for DAG: process_weather_people_postgres
[2023-06-06T00:00:16.637+0000] {logging_mixin.py:120} INFO - [2023-06-06T00:00:16.637+0000] {taskmixin.py:205} WARNING - Dependency <Task(HttpSensor): group_users.is_1_api_available>, create_users_table already registered for DAG: process_weather_people_postgres
[2023-06-06T00:00:16.641+0000] {logging_mixin.py:120} INFO - [2023-06-06T00:00:16.639+0000] {dagbag.py:449} ERROR - Failed to bag_dag: /opt/airflow/dags/process_weather_people_postgres/process_weather_people_postgres.py
Traceback (most recent call last):
  File "/home/airflow/.local/lib/python3.7/site-packages/airflow/models/dagbag.py", line 437, in _process_modules
    self.bag_dag(dag=dag, root_dag=dag)
  File "/home/airflow/.local/lib/python3.7/site-packages/airflow/models/dagbag.py", line 464, in bag_dag
    self._bag_dag(dag=dag, root_dag=root_dag, recursive=True)
  File "/home/airflow/.local/lib/python3.7/site-packages/airflow/models/dagbag.py", line 472, in _bag_dag
    check_cycle(dag)  # throws if a task cycle is found
  File "/home/airflow/.local/lib/python3.7/site-packages/airflow/utils/dag_cycle_tester.py", line 78, in check_cycle
    child_to_check = _check_adjacent_tasks(current_task_id, task)
  File "/home/airflow/.local/lib/python3.7/site-packages/airflow/utils/dag_cycle_tester.py", line 64, in _check_adjacent_tasks
    raise AirflowDagCycleException(msg)
airflow.exceptions.AirflowDagCycleException: Cycle detected in DAG: process_weather_people_postgres. Faulty task: group_users.slack_notification_1
[2023-06-06T00:00:16.641+0000] {processor.py:768} WARNING - No viable dags retrieved from /opt/airflow/dags/process_weather_people_postgres/process_weather_people_postgres.py
[2023-06-06T00:00:16.665+0000] {processor.py:176} INFO - Processing /opt/airflow/dags/process_weather_people_postgres/process_weather_people_postgres.py took 0.614 seconds
[2023-06-06T00:00:46.845+0000] {processor.py:154} INFO - Started process (PID=14377) to work on /opt/airflow/dags/process_weather_people_postgres/process_weather_people_postgres.py
[2023-06-06T00:00:46.846+0000] {processor.py:756} INFO - Processing file /opt/airflow/dags/process_weather_people_postgres/process_weather_people_postgres.py for tasks to queue
[2023-06-06T00:00:46.847+0000] {logging_mixin.py:120} INFO - [2023-06-06T00:00:46.847+0000] {dagbag.py:537} INFO - Filling up the DagBag from /opt/airflow/dags/process_weather_people_postgres/process_weather_people_postgres.py
[2023-06-06T00:00:47.274+0000] {logging_mixin.py:120} INFO - [2023-06-06T00:00:47.273+0000] {dagbag.py:342} ERROR - Failed to import: /opt/airflow/dags/process_weather_people_postgres/process_weather_people_postgres.py
Traceback (most recent call last):
  File "/home/airflow/.local/lib/python3.7/site-packages/airflow/models/dagbag.py", line 338, in parse
    loader.exec_module(new_module)
  File "<frozen importlib._bootstrap_external>", line 728, in exec_module
  File "<frozen importlib._bootstrap>", line 219, in _call_with_frames_removed
  File "/opt/airflow/dags/process_weather_people_postgres/process_weather_people_postgres.py", line 39, in <module>
    from others.operators.climate_temperature_slack import ClimateNotificationSlackOperator
  File "/opt/airflow/plugins/others/operators/climate_temperature_slack.py", line 65
    endpoint_with_params =
                          ^
SyntaxError: invalid syntax
[2023-06-06T00:00:47.275+0000] {processor.py:768} WARNING - No viable dags retrieved from /opt/airflow/dags/process_weather_people_postgres/process_weather_people_postgres.py
[2023-06-06T00:00:47.295+0000] {processor.py:176} INFO - Processing /opt/airflow/dags/process_weather_people_postgres/process_weather_people_postgres.py took 0.453 seconds
[2023-06-06T00:01:17.356+0000] {processor.py:154} INFO - Started process (PID=14407) to work on /opt/airflow/dags/process_weather_people_postgres/process_weather_people_postgres.py
[2023-06-06T00:01:17.358+0000] {processor.py:756} INFO - Processing file /opt/airflow/dags/process_weather_people_postgres/process_weather_people_postgres.py for tasks to queue
[2023-06-06T00:01:17.359+0000] {logging_mixin.py:120} INFO - [2023-06-06T00:01:17.359+0000] {dagbag.py:537} INFO - Filling up the DagBag from /opt/airflow/dags/process_weather_people_postgres/process_weather_people_postgres.py
[2023-06-06T00:01:17.946+0000] {logging_mixin.py:120} INFO - [2023-06-06T00:01:17.945+0000] {dagbag.py:342} ERROR - Failed to import: /opt/airflow/dags/process_weather_people_postgres/process_weather_people_postgres.py
Traceback (most recent call last):
  File "/home/airflow/.local/lib/python3.7/site-packages/airflow/models/dagbag.py", line 338, in parse
    loader.exec_module(new_module)
  File "<frozen importlib._bootstrap_external>", line 728, in exec_module
  File "<frozen importlib._bootstrap>", line 219, in _call_with_frames_removed
  File "/opt/airflow/dags/process_weather_people_postgres/process_weather_people_postgres.py", line 39, in <module>
    from others.operators.climate_temperature_slack import ClimateNotificationSlackOperator
  File "/opt/airflow/plugins/others/operators/climate_temperature_slack.py", line 66
    endpoint_with_params =
                          ^
SyntaxError: invalid syntax
[2023-06-06T00:01:17.947+0000] {processor.py:768} WARNING - No viable dags retrieved from /opt/airflow/dags/process_weather_people_postgres/process_weather_people_postgres.py
[2023-06-06T00:01:17.966+0000] {processor.py:176} INFO - Processing /opt/airflow/dags/process_weather_people_postgres/process_weather_people_postgres.py took 0.613 seconds
[2023-06-06T00:01:48.131+0000] {processor.py:154} INFO - Started process (PID=14427) to work on /opt/airflow/dags/process_weather_people_postgres/process_weather_people_postgres.py
[2023-06-06T00:01:48.133+0000] {processor.py:756} INFO - Processing file /opt/airflow/dags/process_weather_people_postgres/process_weather_people_postgres.py for tasks to queue
[2023-06-06T00:01:48.134+0000] {logging_mixin.py:120} INFO - [2023-06-06T00:01:48.133+0000] {dagbag.py:537} INFO - Filling up the DagBag from /opt/airflow/dags/process_weather_people_postgres/process_weather_people_postgres.py
[2023-06-06T00:01:48.569+0000] {logging_mixin.py:120} INFO - [2023-06-06T00:01:48.568+0000] {dagbag.py:342} ERROR - Failed to import: /opt/airflow/dags/process_weather_people_postgres/process_weather_people_postgres.py
Traceback (most recent call last):
  File "/home/airflow/.local/lib/python3.7/site-packages/airflow/models/dagbag.py", line 338, in parse
    loader.exec_module(new_module)
  File "<frozen importlib._bootstrap_external>", line 728, in exec_module
  File "<frozen importlib._bootstrap>", line 219, in _call_with_frames_removed
  File "/opt/airflow/dags/process_weather_people_postgres/process_weather_people_postgres.py", line 39, in <module>
    from others.operators.climate_temperature_slack import ClimateNotificationSlackOperator
  File "/opt/airflow/plugins/others/operators/climate_temperature_slack.py", line 66
    endpoint_with_params =
                          ^
SyntaxError: invalid syntax
[2023-06-06T00:01:48.570+0000] {processor.py:768} WARNING - No viable dags retrieved from /opt/airflow/dags/process_weather_people_postgres/process_weather_people_postgres.py
[2023-06-06T00:01:48.586+0000] {processor.py:176} INFO - Processing /opt/airflow/dags/process_weather_people_postgres/process_weather_people_postgres.py took 0.457 seconds
[2023-06-06T00:02:18.802+0000] {processor.py:154} INFO - Started process (PID=14457) to work on /opt/airflow/dags/process_weather_people_postgres/process_weather_people_postgres.py
[2023-06-06T00:02:18.804+0000] {processor.py:756} INFO - Processing file /opt/airflow/dags/process_weather_people_postgres/process_weather_people_postgres.py for tasks to queue
[2023-06-06T00:02:18.805+0000] {logging_mixin.py:120} INFO - [2023-06-06T00:02:18.805+0000] {dagbag.py:537} INFO - Filling up the DagBag from /opt/airflow/dags/process_weather_people_postgres/process_weather_people_postgres.py
[2023-06-06T00:02:19.291+0000] {logging_mixin.py:120} INFO - [2023-06-06T00:02:19.289+0000] {dagbag.py:342} ERROR - Failed to import: /opt/airflow/dags/process_weather_people_postgres/process_weather_people_postgres.py
Traceback (most recent call last):
  File "/home/airflow/.local/lib/python3.7/site-packages/airflow/models/dagbag.py", line 338, in parse
    loader.exec_module(new_module)
  File "<frozen importlib._bootstrap_external>", line 728, in exec_module
  File "<frozen importlib._bootstrap>", line 219, in _call_with_frames_removed
  File "/opt/airflow/dags/process_weather_people_postgres/process_weather_people_postgres.py", line 39, in <module>
    from others.operators.climate_temperature_slack import ClimateNotificationSlackOperator
  File "/opt/airflow/plugins/others/operators/climate_temperature_slack.py", line 66
    endpoint_with_params =
                          ^
SyntaxError: invalid syntax
[2023-06-06T00:02:19.291+0000] {processor.py:768} WARNING - No viable dags retrieved from /opt/airflow/dags/process_weather_people_postgres/process_weather_people_postgres.py
[2023-06-06T00:02:19.306+0000] {processor.py:176} INFO - Processing /opt/airflow/dags/process_weather_people_postgres/process_weather_people_postgres.py took 0.508 seconds
[2023-06-06T00:02:49.466+0000] {processor.py:154} INFO - Started process (PID=14486) to work on /opt/airflow/dags/process_weather_people_postgres/process_weather_people_postgres.py
[2023-06-06T00:02:49.468+0000] {processor.py:756} INFO - Processing file /opt/airflow/dags/process_weather_people_postgres/process_weather_people_postgres.py for tasks to queue
[2023-06-06T00:02:49.469+0000] {logging_mixin.py:120} INFO - [2023-06-06T00:02:49.468+0000] {dagbag.py:537} INFO - Filling up the DagBag from /opt/airflow/dags/process_weather_people_postgres/process_weather_people_postgres.py
[2023-06-06T00:02:49.912+0000] {logging_mixin.py:120} INFO - [2023-06-06T00:02:49.912+0000] {taskmixin.py:205} WARNING - Dependency <Task(PostgresOperator): create_users_table>, group_users.is_1_api_available already registered for DAG: process_weather_people_postgres
[2023-06-06T00:02:49.912+0000] {logging_mixin.py:120} INFO - [2023-06-06T00:02:49.912+0000] {taskmixin.py:205} WARNING - Dependency <Task(HttpSensor): group_users.is_1_api_available>, create_users_table already registered for DAG: process_weather_people_postgres
[2023-06-06T00:02:49.915+0000] {logging_mixin.py:120} INFO - [2023-06-06T00:02:49.914+0000] {dagbag.py:449} ERROR - Failed to bag_dag: /opt/airflow/dags/process_weather_people_postgres/process_weather_people_postgres.py
Traceback (most recent call last):
  File "/home/airflow/.local/lib/python3.7/site-packages/airflow/models/dagbag.py", line 437, in _process_modules
    self.bag_dag(dag=dag, root_dag=dag)
  File "/home/airflow/.local/lib/python3.7/site-packages/airflow/models/dagbag.py", line 464, in bag_dag
    self._bag_dag(dag=dag, root_dag=root_dag, recursive=True)
  File "/home/airflow/.local/lib/python3.7/site-packages/airflow/models/dagbag.py", line 472, in _bag_dag
    check_cycle(dag)  # throws if a task cycle is found
  File "/home/airflow/.local/lib/python3.7/site-packages/airflow/utils/dag_cycle_tester.py", line 78, in check_cycle
    child_to_check = _check_adjacent_tasks(current_task_id, task)
  File "/home/airflow/.local/lib/python3.7/site-packages/airflow/utils/dag_cycle_tester.py", line 64, in _check_adjacent_tasks
    raise AirflowDagCycleException(msg)
airflow.exceptions.AirflowDagCycleException: Cycle detected in DAG: process_weather_people_postgres. Faulty task: group_users.slack_notification_1
[2023-06-06T00:02:49.915+0000] {processor.py:768} WARNING - No viable dags retrieved from /opt/airflow/dags/process_weather_people_postgres/process_weather_people_postgres.py
[2023-06-06T00:02:49.932+0000] {processor.py:176} INFO - Processing /opt/airflow/dags/process_weather_people_postgres/process_weather_people_postgres.py took 0.468 seconds
[2023-06-06T00:03:20.105+0000] {processor.py:154} INFO - Started process (PID=14506) to work on /opt/airflow/dags/process_weather_people_postgres/process_weather_people_postgres.py
[2023-06-06T00:03:20.106+0000] {processor.py:756} INFO - Processing file /opt/airflow/dags/process_weather_people_postgres/process_weather_people_postgres.py for tasks to queue
[2023-06-06T00:03:20.107+0000] {logging_mixin.py:120} INFO - [2023-06-06T00:03:20.107+0000] {dagbag.py:537} INFO - Filling up the DagBag from /opt/airflow/dags/process_weather_people_postgres/process_weather_people_postgres.py
[2023-06-06T00:03:21.098+0000] {logging_mixin.py:120} INFO - [2023-06-06T00:03:21.098+0000] {taskmixin.py:205} WARNING - Dependency <Task(PostgresOperator): create_users_table>, group_users.is_1_api_available already registered for DAG: process_weather_people_postgres
[2023-06-06T00:03:21.099+0000] {logging_mixin.py:120} INFO - [2023-06-06T00:03:21.099+0000] {taskmixin.py:205} WARNING - Dependency <Task(HttpSensor): group_users.is_1_api_available>, create_users_table already registered for DAG: process_weather_people_postgres
[2023-06-06T00:03:21.104+0000] {logging_mixin.py:120} INFO - [2023-06-06T00:03:21.102+0000] {dagbag.py:449} ERROR - Failed to bag_dag: /opt/airflow/dags/process_weather_people_postgres/process_weather_people_postgres.py
Traceback (most recent call last):
  File "/home/airflow/.local/lib/python3.7/site-packages/airflow/models/dagbag.py", line 437, in _process_modules
    self.bag_dag(dag=dag, root_dag=dag)
  File "/home/airflow/.local/lib/python3.7/site-packages/airflow/models/dagbag.py", line 464, in bag_dag
    self._bag_dag(dag=dag, root_dag=root_dag, recursive=True)
  File "/home/airflow/.local/lib/python3.7/site-packages/airflow/models/dagbag.py", line 472, in _bag_dag
    check_cycle(dag)  # throws if a task cycle is found
  File "/home/airflow/.local/lib/python3.7/site-packages/airflow/utils/dag_cycle_tester.py", line 78, in check_cycle
    child_to_check = _check_adjacent_tasks(current_task_id, task)
  File "/home/airflow/.local/lib/python3.7/site-packages/airflow/utils/dag_cycle_tester.py", line 64, in _check_adjacent_tasks
    raise AirflowDagCycleException(msg)
airflow.exceptions.AirflowDagCycleException: Cycle detected in DAG: process_weather_people_postgres. Faulty task: group_users.slack_notification_1
[2023-06-06T00:03:21.104+0000] {processor.py:768} WARNING - No viable dags retrieved from /opt/airflow/dags/process_weather_people_postgres/process_weather_people_postgres.py
[2023-06-06T00:03:21.135+0000] {processor.py:176} INFO - Processing /opt/airflow/dags/process_weather_people_postgres/process_weather_people_postgres.py took 1.035 seconds
[2023-06-06T00:03:51.289+0000] {processor.py:154} INFO - Started process (PID=14537) to work on /opt/airflow/dags/process_weather_people_postgres/process_weather_people_postgres.py
[2023-06-06T00:03:51.290+0000] {processor.py:756} INFO - Processing file /opt/airflow/dags/process_weather_people_postgres/process_weather_people_postgres.py for tasks to queue
[2023-06-06T00:03:51.290+0000] {logging_mixin.py:120} INFO - [2023-06-06T00:03:51.290+0000] {dagbag.py:537} INFO - Filling up the DagBag from /opt/airflow/dags/process_weather_people_postgres/process_weather_people_postgres.py
[2023-06-06T00:03:51.754+0000] {logging_mixin.py:120} INFO - [2023-06-06T00:03:51.753+0000] {dagbag.py:342} ERROR - Failed to import: /opt/airflow/dags/process_weather_people_postgres/process_weather_people_postgres.py
Traceback (most recent call last):
  File "/home/airflow/.local/lib/python3.7/site-packages/airflow/models/dagbag.py", line 338, in parse
    loader.exec_module(new_module)
  File "<frozen importlib._bootstrap_external>", line 728, in exec_module
  File "<frozen importlib._bootstrap>", line 219, in _call_with_frames_removed
  File "/opt/airflow/dags/process_weather_people_postgres/process_weather_people_postgres.py", line 39, in <module>
    from others.operators.climate_temperature_slack import ClimateNotificationSlackOperator
  File "/opt/airflow/plugins/others/operators/climate_temperature_slack.py", line 67
    endpoint_with_params = self.endpoint_fixed + f'&lat={}&lon=-63.2743'
                                                ^
SyntaxError: f-string: empty expression not allowed
[2023-06-06T00:03:51.755+0000] {processor.py:768} WARNING - No viable dags retrieved from /opt/airflow/dags/process_weather_people_postgres/process_weather_people_postgres.py
[2023-06-06T00:03:51.779+0000] {processor.py:176} INFO - Processing /opt/airflow/dags/process_weather_people_postgres/process_weather_people_postgres.py took 0.493 seconds
[2023-06-06T00:04:21.955+0000] {processor.py:154} INFO - Started process (PID=14568) to work on /opt/airflow/dags/process_weather_people_postgres/process_weather_people_postgres.py
[2023-06-06T00:04:21.956+0000] {processor.py:756} INFO - Processing file /opt/airflow/dags/process_weather_people_postgres/process_weather_people_postgres.py for tasks to queue
[2023-06-06T00:04:21.957+0000] {logging_mixin.py:120} INFO - [2023-06-06T00:04:21.957+0000] {dagbag.py:537} INFO - Filling up the DagBag from /opt/airflow/dags/process_weather_people_postgres/process_weather_people_postgres.py
[2023-06-06T00:04:22.650+0000] {logging_mixin.py:120} INFO - [2023-06-06T00:04:22.650+0000] {taskmixin.py:205} WARNING - Dependency <Task(PostgresOperator): create_users_table>, group_users.is_1_api_available already registered for DAG: process_weather_people_postgres
[2023-06-06T00:04:22.651+0000] {logging_mixin.py:120} INFO - [2023-06-06T00:04:22.650+0000] {taskmixin.py:205} WARNING - Dependency <Task(HttpSensor): group_users.is_1_api_available>, create_users_table already registered for DAG: process_weather_people_postgres
[2023-06-06T00:04:22.655+0000] {logging_mixin.py:120} INFO - [2023-06-06T00:04:22.653+0000] {dagbag.py:449} ERROR - Failed to bag_dag: /opt/airflow/dags/process_weather_people_postgres/process_weather_people_postgres.py
Traceback (most recent call last):
  File "/home/airflow/.local/lib/python3.7/site-packages/airflow/models/dagbag.py", line 437, in _process_modules
    self.bag_dag(dag=dag, root_dag=dag)
  File "/home/airflow/.local/lib/python3.7/site-packages/airflow/models/dagbag.py", line 464, in bag_dag
    self._bag_dag(dag=dag, root_dag=root_dag, recursive=True)
  File "/home/airflow/.local/lib/python3.7/site-packages/airflow/models/dagbag.py", line 472, in _bag_dag
    check_cycle(dag)  # throws if a task cycle is found
  File "/home/airflow/.local/lib/python3.7/site-packages/airflow/utils/dag_cycle_tester.py", line 78, in check_cycle
    child_to_check = _check_adjacent_tasks(current_task_id, task)
  File "/home/airflow/.local/lib/python3.7/site-packages/airflow/utils/dag_cycle_tester.py", line 64, in _check_adjacent_tasks
    raise AirflowDagCycleException(msg)
airflow.exceptions.AirflowDagCycleException: Cycle detected in DAG: process_weather_people_postgres. Faulty task: group_users.slack_notification_1
[2023-06-06T00:04:22.656+0000] {processor.py:768} WARNING - No viable dags retrieved from /opt/airflow/dags/process_weather_people_postgres/process_weather_people_postgres.py
[2023-06-06T00:04:22.686+0000] {processor.py:176} INFO - Processing /opt/airflow/dags/process_weather_people_postgres/process_weather_people_postgres.py took 0.734 seconds
[2023-06-06T00:04:52.864+0000] {processor.py:154} INFO - Started process (PID=14588) to work on /opt/airflow/dags/process_weather_people_postgres/process_weather_people_postgres.py
[2023-06-06T00:04:52.866+0000] {processor.py:756} INFO - Processing file /opt/airflow/dags/process_weather_people_postgres/process_weather_people_postgres.py for tasks to queue
[2023-06-06T00:04:52.868+0000] {logging_mixin.py:120} INFO - [2023-06-06T00:04:52.867+0000] {dagbag.py:537} INFO - Filling up the DagBag from /opt/airflow/dags/process_weather_people_postgres/process_weather_people_postgres.py
[2023-06-06T00:04:53.460+0000] {logging_mixin.py:120} INFO - [2023-06-06T00:04:53.460+0000] {taskmixin.py:205} WARNING - Dependency <Task(PostgresOperator): create_users_table>, group_users.is_1_api_available already registered for DAG: process_weather_people_postgres
[2023-06-06T00:04:53.460+0000] {logging_mixin.py:120} INFO - [2023-06-06T00:04:53.460+0000] {taskmixin.py:205} WARNING - Dependency <Task(HttpSensor): group_users.is_1_api_available>, create_users_table already registered for DAG: process_weather_people_postgres
[2023-06-06T00:04:53.463+0000] {logging_mixin.py:120} INFO - [2023-06-06T00:04:53.462+0000] {dagbag.py:449} ERROR - Failed to bag_dag: /opt/airflow/dags/process_weather_people_postgres/process_weather_people_postgres.py
Traceback (most recent call last):
  File "/home/airflow/.local/lib/python3.7/site-packages/airflow/models/dagbag.py", line 437, in _process_modules
    self.bag_dag(dag=dag, root_dag=dag)
  File "/home/airflow/.local/lib/python3.7/site-packages/airflow/models/dagbag.py", line 464, in bag_dag
    self._bag_dag(dag=dag, root_dag=root_dag, recursive=True)
  File "/home/airflow/.local/lib/python3.7/site-packages/airflow/models/dagbag.py", line 472, in _bag_dag
    check_cycle(dag)  # throws if a task cycle is found
  File "/home/airflow/.local/lib/python3.7/site-packages/airflow/utils/dag_cycle_tester.py", line 78, in check_cycle
    child_to_check = _check_adjacent_tasks(current_task_id, task)
  File "/home/airflow/.local/lib/python3.7/site-packages/airflow/utils/dag_cycle_tester.py", line 64, in _check_adjacent_tasks
    raise AirflowDagCycleException(msg)
airflow.exceptions.AirflowDagCycleException: Cycle detected in DAG: process_weather_people_postgres. Faulty task: group_users.slack_notification_1
[2023-06-06T00:04:53.464+0000] {processor.py:768} WARNING - No viable dags retrieved from /opt/airflow/dags/process_weather_people_postgres/process_weather_people_postgres.py
[2023-06-06T00:04:53.489+0000] {processor.py:176} INFO - Processing /opt/airflow/dags/process_weather_people_postgres/process_weather_people_postgres.py took 0.636 seconds
[2023-06-06T00:05:23.728+0000] {processor.py:154} INFO - Started process (PID=14617) to work on /opt/airflow/dags/process_weather_people_postgres/process_weather_people_postgres.py
[2023-06-06T00:05:23.729+0000] {processor.py:756} INFO - Processing file /opt/airflow/dags/process_weather_people_postgres/process_weather_people_postgres.py for tasks to queue
[2023-06-06T00:05:23.730+0000] {logging_mixin.py:120} INFO - [2023-06-06T00:05:23.730+0000] {dagbag.py:537} INFO - Filling up the DagBag from /opt/airflow/dags/process_weather_people_postgres/process_weather_people_postgres.py
[2023-06-06T00:05:24.176+0000] {logging_mixin.py:120} INFO - [2023-06-06T00:05:24.176+0000] {taskmixin.py:205} WARNING - Dependency <Task(PostgresOperator): create_users_table>, group_users.is_1_api_available already registered for DAG: process_weather_people_postgres
[2023-06-06T00:05:24.176+0000] {logging_mixin.py:120} INFO - [2023-06-06T00:05:24.176+0000] {taskmixin.py:205} WARNING - Dependency <Task(HttpSensor): group_users.is_1_api_available>, create_users_table already registered for DAG: process_weather_people_postgres
[2023-06-06T00:05:24.179+0000] {logging_mixin.py:120} INFO - [2023-06-06T00:05:24.178+0000] {dagbag.py:449} ERROR - Failed to bag_dag: /opt/airflow/dags/process_weather_people_postgres/process_weather_people_postgres.py
Traceback (most recent call last):
  File "/home/airflow/.local/lib/python3.7/site-packages/airflow/models/dagbag.py", line 437, in _process_modules
    self.bag_dag(dag=dag, root_dag=dag)
  File "/home/airflow/.local/lib/python3.7/site-packages/airflow/models/dagbag.py", line 464, in bag_dag
    self._bag_dag(dag=dag, root_dag=root_dag, recursive=True)
  File "/home/airflow/.local/lib/python3.7/site-packages/airflow/models/dagbag.py", line 472, in _bag_dag
    check_cycle(dag)  # throws if a task cycle is found
  File "/home/airflow/.local/lib/python3.7/site-packages/airflow/utils/dag_cycle_tester.py", line 78, in check_cycle
    child_to_check = _check_adjacent_tasks(current_task_id, task)
  File "/home/airflow/.local/lib/python3.7/site-packages/airflow/utils/dag_cycle_tester.py", line 64, in _check_adjacent_tasks
    raise AirflowDagCycleException(msg)
airflow.exceptions.AirflowDagCycleException: Cycle detected in DAG: process_weather_people_postgres. Faulty task: group_users.slack_notification_1
[2023-06-06T00:05:24.179+0000] {processor.py:768} WARNING - No viable dags retrieved from /opt/airflow/dags/process_weather_people_postgres/process_weather_people_postgres.py
[2023-06-06T00:05:24.198+0000] {processor.py:176} INFO - Processing /opt/airflow/dags/process_weather_people_postgres/process_weather_people_postgres.py took 0.473 seconds
[2023-06-06T00:05:54.370+0000] {processor.py:154} INFO - Started process (PID=14646) to work on /opt/airflow/dags/process_weather_people_postgres/process_weather_people_postgres.py
[2023-06-06T00:05:54.371+0000] {processor.py:756} INFO - Processing file /opt/airflow/dags/process_weather_people_postgres/process_weather_people_postgres.py for tasks to queue
[2023-06-06T00:05:54.373+0000] {logging_mixin.py:120} INFO - [2023-06-06T00:05:54.373+0000] {dagbag.py:537} INFO - Filling up the DagBag from /opt/airflow/dags/process_weather_people_postgres/process_weather_people_postgres.py
[2023-06-06T00:05:55.454+0000] {logging_mixin.py:120} INFO - [2023-06-06T00:05:55.454+0000] {taskmixin.py:205} WARNING - Dependency <Task(PostgresOperator): create_users_table>, group_users.is_1_api_available already registered for DAG: process_weather_people_postgres
[2023-06-06T00:05:55.455+0000] {logging_mixin.py:120} INFO - [2023-06-06T00:05:55.455+0000] {taskmixin.py:205} WARNING - Dependency <Task(HttpSensor): group_users.is_1_api_available>, create_users_table already registered for DAG: process_weather_people_postgres
[2023-06-06T00:05:55.457+0000] {logging_mixin.py:120} INFO - [2023-06-06T00:05:55.456+0000] {dagbag.py:449} ERROR - Failed to bag_dag: /opt/airflow/dags/process_weather_people_postgres/process_weather_people_postgres.py
Traceback (most recent call last):
  File "/home/airflow/.local/lib/python3.7/site-packages/airflow/models/dagbag.py", line 437, in _process_modules
    self.bag_dag(dag=dag, root_dag=dag)
  File "/home/airflow/.local/lib/python3.7/site-packages/airflow/models/dagbag.py", line 464, in bag_dag
    self._bag_dag(dag=dag, root_dag=root_dag, recursive=True)
  File "/home/airflow/.local/lib/python3.7/site-packages/airflow/models/dagbag.py", line 472, in _bag_dag
    check_cycle(dag)  # throws if a task cycle is found
  File "/home/airflow/.local/lib/python3.7/site-packages/airflow/utils/dag_cycle_tester.py", line 78, in check_cycle
    child_to_check = _check_adjacent_tasks(current_task_id, task)
  File "/home/airflow/.local/lib/python3.7/site-packages/airflow/utils/dag_cycle_tester.py", line 64, in _check_adjacent_tasks
    raise AirflowDagCycleException(msg)
airflow.exceptions.AirflowDagCycleException: Cycle detected in DAG: process_weather_people_postgres. Faulty task: group_users.slack_notification_1
[2023-06-06T00:05:55.457+0000] {processor.py:768} WARNING - No viable dags retrieved from /opt/airflow/dags/process_weather_people_postgres/process_weather_people_postgres.py
[2023-06-06T00:05:55.476+0000] {processor.py:176} INFO - Processing /opt/airflow/dags/process_weather_people_postgres/process_weather_people_postgres.py took 1.109 seconds
[2023-06-06T00:06:25.519+0000] {processor.py:154} INFO - Started process (PID=14666) to work on /opt/airflow/dags/process_weather_people_postgres/process_weather_people_postgres.py
[2023-06-06T00:06:25.520+0000] {processor.py:756} INFO - Processing file /opt/airflow/dags/process_weather_people_postgres/process_weather_people_postgres.py for tasks to queue
[2023-06-06T00:06:25.521+0000] {logging_mixin.py:120} INFO - [2023-06-06T00:06:25.521+0000] {dagbag.py:537} INFO - Filling up the DagBag from /opt/airflow/dags/process_weather_people_postgres/process_weather_people_postgres.py
[2023-06-06T00:06:25.950+0000] {logging_mixin.py:120} INFO - [2023-06-06T00:06:25.950+0000] {taskmixin.py:205} WARNING - Dependency <Task(PostgresOperator): create_users_table>, group_users.is_1_api_available already registered for DAG: process_weather_people_postgres
[2023-06-06T00:06:25.951+0000] {logging_mixin.py:120} INFO - [2023-06-06T00:06:25.951+0000] {taskmixin.py:205} WARNING - Dependency <Task(HttpSensor): group_users.is_1_api_available>, create_users_table already registered for DAG: process_weather_people_postgres
[2023-06-06T00:06:25.952+0000] {logging_mixin.py:120} INFO - [2023-06-06T00:06:25.952+0000] {dagbag.py:449} ERROR - Failed to bag_dag: /opt/airflow/dags/process_weather_people_postgres/process_weather_people_postgres.py
Traceback (most recent call last):
  File "/home/airflow/.local/lib/python3.7/site-packages/airflow/models/dagbag.py", line 437, in _process_modules
    self.bag_dag(dag=dag, root_dag=dag)
  File "/home/airflow/.local/lib/python3.7/site-packages/airflow/models/dagbag.py", line 464, in bag_dag
    self._bag_dag(dag=dag, root_dag=root_dag, recursive=True)
  File "/home/airflow/.local/lib/python3.7/site-packages/airflow/models/dagbag.py", line 472, in _bag_dag
    check_cycle(dag)  # throws if a task cycle is found
  File "/home/airflow/.local/lib/python3.7/site-packages/airflow/utils/dag_cycle_tester.py", line 78, in check_cycle
    child_to_check = _check_adjacent_tasks(current_task_id, task)
  File "/home/airflow/.local/lib/python3.7/site-packages/airflow/utils/dag_cycle_tester.py", line 64, in _check_adjacent_tasks
    raise AirflowDagCycleException(msg)
airflow.exceptions.AirflowDagCycleException: Cycle detected in DAG: process_weather_people_postgres. Faulty task: group_users.slack_notification_1
[2023-06-06T00:06:25.953+0000] {processor.py:768} WARNING - No viable dags retrieved from /opt/airflow/dags/process_weather_people_postgres/process_weather_people_postgres.py
[2023-06-06T00:06:25.970+0000] {processor.py:176} INFO - Processing /opt/airflow/dags/process_weather_people_postgres/process_weather_people_postgres.py took 0.454 seconds
[2023-06-06T00:06:56.110+0000] {processor.py:154} INFO - Started process (PID=14695) to work on /opt/airflow/dags/process_weather_people_postgres/process_weather_people_postgres.py
[2023-06-06T00:06:56.112+0000] {processor.py:756} INFO - Processing file /opt/airflow/dags/process_weather_people_postgres/process_weather_people_postgres.py for tasks to queue
[2023-06-06T00:06:56.113+0000] {logging_mixin.py:120} INFO - [2023-06-06T00:06:56.112+0000] {dagbag.py:537} INFO - Filling up the DagBag from /opt/airflow/dags/process_weather_people_postgres/process_weather_people_postgres.py
[2023-06-06T00:06:56.518+0000] {logging_mixin.py:120} INFO - [2023-06-06T00:06:56.518+0000] {taskmixin.py:205} WARNING - Dependency <Task(PostgresOperator): create_users_table>, group_users.is_1_api_available already registered for DAG: process_weather_people_postgres
[2023-06-06T00:06:56.519+0000] {logging_mixin.py:120} INFO - [2023-06-06T00:06:56.518+0000] {taskmixin.py:205} WARNING - Dependency <Task(HttpSensor): group_users.is_1_api_available>, create_users_table already registered for DAG: process_weather_people_postgres
[2023-06-06T00:06:56.521+0000] {logging_mixin.py:120} INFO - [2023-06-06T00:06:56.519+0000] {dagbag.py:449} ERROR - Failed to bag_dag: /opt/airflow/dags/process_weather_people_postgres/process_weather_people_postgres.py
Traceback (most recent call last):
  File "/home/airflow/.local/lib/python3.7/site-packages/airflow/models/dagbag.py", line 437, in _process_modules
    self.bag_dag(dag=dag, root_dag=dag)
  File "/home/airflow/.local/lib/python3.7/site-packages/airflow/models/dagbag.py", line 464, in bag_dag
    self._bag_dag(dag=dag, root_dag=root_dag, recursive=True)
  File "/home/airflow/.local/lib/python3.7/site-packages/airflow/models/dagbag.py", line 472, in _bag_dag
    check_cycle(dag)  # throws if a task cycle is found
  File "/home/airflow/.local/lib/python3.7/site-packages/airflow/utils/dag_cycle_tester.py", line 78, in check_cycle
    child_to_check = _check_adjacent_tasks(current_task_id, task)
  File "/home/airflow/.local/lib/python3.7/site-packages/airflow/utils/dag_cycle_tester.py", line 64, in _check_adjacent_tasks
    raise AirflowDagCycleException(msg)
airflow.exceptions.AirflowDagCycleException: Cycle detected in DAG: process_weather_people_postgres. Faulty task: group_users.slack_notification_1
[2023-06-06T00:06:56.521+0000] {processor.py:768} WARNING - No viable dags retrieved from /opt/airflow/dags/process_weather_people_postgres/process_weather_people_postgres.py
[2023-06-06T00:06:56.539+0000] {processor.py:176} INFO - Processing /opt/airflow/dags/process_weather_people_postgres/process_weather_people_postgres.py took 0.432 seconds
[2023-06-06T00:07:26.684+0000] {processor.py:154} INFO - Started process (PID=14725) to work on /opt/airflow/dags/process_weather_people_postgres/process_weather_people_postgres.py
[2023-06-06T00:07:26.685+0000] {processor.py:756} INFO - Processing file /opt/airflow/dags/process_weather_people_postgres/process_weather_people_postgres.py for tasks to queue
[2023-06-06T00:07:26.686+0000] {logging_mixin.py:120} INFO - [2023-06-06T00:07:26.686+0000] {dagbag.py:537} INFO - Filling up the DagBag from /opt/airflow/dags/process_weather_people_postgres/process_weather_people_postgres.py
[2023-06-06T00:07:27.112+0000] {logging_mixin.py:120} INFO - [2023-06-06T00:07:27.112+0000] {taskmixin.py:205} WARNING - Dependency <Task(PostgresOperator): create_users_table>, group_users.is_1_api_available already registered for DAG: process_weather_people_postgres
[2023-06-06T00:07:27.113+0000] {logging_mixin.py:120} INFO - [2023-06-06T00:07:27.113+0000] {taskmixin.py:205} WARNING - Dependency <Task(HttpSensor): group_users.is_1_api_available>, create_users_table already registered for DAG: process_weather_people_postgres
[2023-06-06T00:07:27.115+0000] {logging_mixin.py:120} INFO - [2023-06-06T00:07:27.114+0000] {dagbag.py:449} ERROR - Failed to bag_dag: /opt/airflow/dags/process_weather_people_postgres/process_weather_people_postgres.py
Traceback (most recent call last):
  File "/home/airflow/.local/lib/python3.7/site-packages/airflow/models/dagbag.py", line 437, in _process_modules
    self.bag_dag(dag=dag, root_dag=dag)
  File "/home/airflow/.local/lib/python3.7/site-packages/airflow/models/dagbag.py", line 464, in bag_dag
    self._bag_dag(dag=dag, root_dag=root_dag, recursive=True)
  File "/home/airflow/.local/lib/python3.7/site-packages/airflow/models/dagbag.py", line 472, in _bag_dag
    check_cycle(dag)  # throws if a task cycle is found
  File "/home/airflow/.local/lib/python3.7/site-packages/airflow/utils/dag_cycle_tester.py", line 78, in check_cycle
    child_to_check = _check_adjacent_tasks(current_task_id, task)
  File "/home/airflow/.local/lib/python3.7/site-packages/airflow/utils/dag_cycle_tester.py", line 64, in _check_adjacent_tasks
    raise AirflowDagCycleException(msg)
airflow.exceptions.AirflowDagCycleException: Cycle detected in DAG: process_weather_people_postgres. Faulty task: group_users.slack_notification_1
[2023-06-06T00:07:27.115+0000] {processor.py:768} WARNING - No viable dags retrieved from /opt/airflow/dags/process_weather_people_postgres/process_weather_people_postgres.py
[2023-06-06T00:07:27.134+0000] {processor.py:176} INFO - Processing /opt/airflow/dags/process_weather_people_postgres/process_weather_people_postgres.py took 0.453 seconds
[2023-06-06T00:07:57.288+0000] {processor.py:154} INFO - Started process (PID=14745) to work on /opt/airflow/dags/process_weather_people_postgres/process_weather_people_postgres.py
[2023-06-06T00:07:57.289+0000] {processor.py:756} INFO - Processing file /opt/airflow/dags/process_weather_people_postgres/process_weather_people_postgres.py for tasks to queue
[2023-06-06T00:07:57.290+0000] {logging_mixin.py:120} INFO - [2023-06-06T00:07:57.290+0000] {dagbag.py:537} INFO - Filling up the DagBag from /opt/airflow/dags/process_weather_people_postgres/process_weather_people_postgres.py
[2023-06-06T00:07:57.714+0000] {logging_mixin.py:120} INFO - [2023-06-06T00:07:57.714+0000] {taskmixin.py:205} WARNING - Dependency <Task(PostgresOperator): create_users_table>, group_users.is_1_api_available already registered for DAG: process_weather_people_postgres
[2023-06-06T00:07:57.715+0000] {logging_mixin.py:120} INFO - [2023-06-06T00:07:57.715+0000] {taskmixin.py:205} WARNING - Dependency <Task(HttpSensor): group_users.is_1_api_available>, create_users_table already registered for DAG: process_weather_people_postgres
[2023-06-06T00:07:57.717+0000] {logging_mixin.py:120} INFO - [2023-06-06T00:07:57.716+0000] {dagbag.py:449} ERROR - Failed to bag_dag: /opt/airflow/dags/process_weather_people_postgres/process_weather_people_postgres.py
Traceback (most recent call last):
  File "/home/airflow/.local/lib/python3.7/site-packages/airflow/models/dagbag.py", line 437, in _process_modules
    self.bag_dag(dag=dag, root_dag=dag)
  File "/home/airflow/.local/lib/python3.7/site-packages/airflow/models/dagbag.py", line 464, in bag_dag
    self._bag_dag(dag=dag, root_dag=root_dag, recursive=True)
  File "/home/airflow/.local/lib/python3.7/site-packages/airflow/models/dagbag.py", line 472, in _bag_dag
    check_cycle(dag)  # throws if a task cycle is found
  File "/home/airflow/.local/lib/python3.7/site-packages/airflow/utils/dag_cycle_tester.py", line 78, in check_cycle
    child_to_check = _check_adjacent_tasks(current_task_id, task)
  File "/home/airflow/.local/lib/python3.7/site-packages/airflow/utils/dag_cycle_tester.py", line 64, in _check_adjacent_tasks
    raise AirflowDagCycleException(msg)
airflow.exceptions.AirflowDagCycleException: Cycle detected in DAG: process_weather_people_postgres. Faulty task: group_users.slack_notification_1
[2023-06-06T00:07:57.717+0000] {processor.py:768} WARNING - No viable dags retrieved from /opt/airflow/dags/process_weather_people_postgres/process_weather_people_postgres.py
[2023-06-06T00:07:57.735+0000] {processor.py:176} INFO - Processing /opt/airflow/dags/process_weather_people_postgres/process_weather_people_postgres.py took 0.449 seconds
[2023-06-06T00:07:59.780+0000] {processor.py:154} INFO - Started process (PID=14756) to work on /opt/airflow/dags/process_weather_people_postgres/process_weather_people_postgres.py
[2023-06-06T00:07:59.782+0000] {processor.py:756} INFO - Processing file /opt/airflow/dags/process_weather_people_postgres/process_weather_people_postgres.py for tasks to queue
[2023-06-06T00:07:59.783+0000] {logging_mixin.py:120} INFO - [2023-06-06T00:07:59.782+0000] {dagbag.py:537} INFO - Filling up the DagBag from /opt/airflow/dags/process_weather_people_postgres/process_weather_people_postgres.py
[2023-06-06T00:08:00.291+0000] {logging_mixin.py:120} INFO - [2023-06-06T00:08:00.290+0000] {taskmixin.py:205} WARNING - Dependency <Task(PostgresOperator): create_users_table>, group_users.is_1_api_available already registered for DAG: process_weather_people_postgres
[2023-06-06T00:08:00.291+0000] {logging_mixin.py:120} INFO - [2023-06-06T00:08:00.291+0000] {taskmixin.py:205} WARNING - Dependency <Task(HttpSensor): group_users.is_1_api_available>, create_users_table already registered for DAG: process_weather_people_postgres
[2023-06-06T00:08:00.294+0000] {logging_mixin.py:120} INFO - [2023-06-06T00:08:00.292+0000] {dagbag.py:449} ERROR - Failed to bag_dag: /opt/airflow/dags/process_weather_people_postgres/process_weather_people_postgres.py
Traceback (most recent call last):
  File "/home/airflow/.local/lib/python3.7/site-packages/airflow/models/dagbag.py", line 437, in _process_modules
    self.bag_dag(dag=dag, root_dag=dag)
  File "/home/airflow/.local/lib/python3.7/site-packages/airflow/models/dagbag.py", line 464, in bag_dag
    self._bag_dag(dag=dag, root_dag=root_dag, recursive=True)
  File "/home/airflow/.local/lib/python3.7/site-packages/airflow/models/dagbag.py", line 472, in _bag_dag
    check_cycle(dag)  # throws if a task cycle is found
  File "/home/airflow/.local/lib/python3.7/site-packages/airflow/utils/dag_cycle_tester.py", line 78, in check_cycle
    child_to_check = _check_adjacent_tasks(current_task_id, task)
  File "/home/airflow/.local/lib/python3.7/site-packages/airflow/utils/dag_cycle_tester.py", line 64, in _check_adjacent_tasks
    raise AirflowDagCycleException(msg)
airflow.exceptions.AirflowDagCycleException: Cycle detected in DAG: process_weather_people_postgres. Faulty task: group_users.slack_notification_1
[2023-06-06T00:08:00.294+0000] {processor.py:768} WARNING - No viable dags retrieved from /opt/airflow/dags/process_weather_people_postgres/process_weather_people_postgres.py
[2023-06-06T00:08:00.356+0000] {processor.py:176} INFO - Processing /opt/airflow/dags/process_weather_people_postgres/process_weather_people_postgres.py took 0.579 seconds
[2023-06-06T00:08:30.463+0000] {processor.py:154} INFO - Started process (PID=14776) to work on /opt/airflow/dags/process_weather_people_postgres/process_weather_people_postgres.py
[2023-06-06T00:08:30.464+0000] {processor.py:756} INFO - Processing file /opt/airflow/dags/process_weather_people_postgres/process_weather_people_postgres.py for tasks to queue
[2023-06-06T00:08:30.466+0000] {logging_mixin.py:120} INFO - [2023-06-06T00:08:30.466+0000] {dagbag.py:537} INFO - Filling up the DagBag from /opt/airflow/dags/process_weather_people_postgres/process_weather_people_postgres.py
[2023-06-06T00:08:30.912+0000] {logging_mixin.py:120} INFO - [2023-06-06T00:08:30.912+0000] {taskmixin.py:205} WARNING - Dependency <Task(PostgresOperator): create_users_table>, group_users.is_1_api_available already registered for DAG: process_weather_people_postgres
[2023-06-06T00:08:30.912+0000] {logging_mixin.py:120} INFO - [2023-06-06T00:08:30.912+0000] {taskmixin.py:205} WARNING - Dependency <Task(HttpSensor): group_users.is_1_api_available>, create_users_table already registered for DAG: process_weather_people_postgres
[2023-06-06T00:08:30.915+0000] {logging_mixin.py:120} INFO - [2023-06-06T00:08:30.914+0000] {dagbag.py:449} ERROR - Failed to bag_dag: /opt/airflow/dags/process_weather_people_postgres/process_weather_people_postgres.py
Traceback (most recent call last):
  File "/home/airflow/.local/lib/python3.7/site-packages/airflow/models/dagbag.py", line 437, in _process_modules
    self.bag_dag(dag=dag, root_dag=dag)
  File "/home/airflow/.local/lib/python3.7/site-packages/airflow/models/dagbag.py", line 464, in bag_dag
    self._bag_dag(dag=dag, root_dag=root_dag, recursive=True)
  File "/home/airflow/.local/lib/python3.7/site-packages/airflow/models/dagbag.py", line 472, in _bag_dag
    check_cycle(dag)  # throws if a task cycle is found
  File "/home/airflow/.local/lib/python3.7/site-packages/airflow/utils/dag_cycle_tester.py", line 78, in check_cycle
    child_to_check = _check_adjacent_tasks(current_task_id, task)
  File "/home/airflow/.local/lib/python3.7/site-packages/airflow/utils/dag_cycle_tester.py", line 64, in _check_adjacent_tasks
    raise AirflowDagCycleException(msg)
airflow.exceptions.AirflowDagCycleException: Cycle detected in DAG: process_weather_people_postgres. Faulty task: group_users.slack_notification_1
[2023-06-06T00:08:30.916+0000] {processor.py:768} WARNING - No viable dags retrieved from /opt/airflow/dags/process_weather_people_postgres/process_weather_people_postgres.py
[2023-06-06T00:08:30.936+0000] {processor.py:176} INFO - Processing /opt/airflow/dags/process_weather_people_postgres/process_weather_people_postgres.py took 0.475 seconds
[2023-06-06T00:09:01.152+0000] {processor.py:154} INFO - Started process (PID=14805) to work on /opt/airflow/dags/process_weather_people_postgres/process_weather_people_postgres.py
[2023-06-06T00:09:01.153+0000] {processor.py:756} INFO - Processing file /opt/airflow/dags/process_weather_people_postgres/process_weather_people_postgres.py for tasks to queue
[2023-06-06T00:09:01.154+0000] {logging_mixin.py:120} INFO - [2023-06-06T00:09:01.154+0000] {dagbag.py:537} INFO - Filling up the DagBag from /opt/airflow/dags/process_weather_people_postgres/process_weather_people_postgres.py
[2023-06-06T00:09:01.639+0000] {logging_mixin.py:120} INFO - [2023-06-06T00:09:01.639+0000] {taskmixin.py:205} WARNING - Dependency <Task(PostgresOperator): create_users_table>, group_users.is_1_api_available already registered for DAG: process_weather_people_postgres
[2023-06-06T00:09:01.640+0000] {logging_mixin.py:120} INFO - [2023-06-06T00:09:01.640+0000] {taskmixin.py:205} WARNING - Dependency <Task(HttpSensor): group_users.is_1_api_available>, create_users_table already registered for DAG: process_weather_people_postgres
[2023-06-06T00:09:01.643+0000] {logging_mixin.py:120} INFO - [2023-06-06T00:09:01.641+0000] {dagbag.py:449} ERROR - Failed to bag_dag: /opt/airflow/dags/process_weather_people_postgres/process_weather_people_postgres.py
Traceback (most recent call last):
  File "/home/airflow/.local/lib/python3.7/site-packages/airflow/models/dagbag.py", line 437, in _process_modules
    self.bag_dag(dag=dag, root_dag=dag)
  File "/home/airflow/.local/lib/python3.7/site-packages/airflow/models/dagbag.py", line 464, in bag_dag
    self._bag_dag(dag=dag, root_dag=root_dag, recursive=True)
  File "/home/airflow/.local/lib/python3.7/site-packages/airflow/models/dagbag.py", line 472, in _bag_dag
    check_cycle(dag)  # throws if a task cycle is found
  File "/home/airflow/.local/lib/python3.7/site-packages/airflow/utils/dag_cycle_tester.py", line 78, in check_cycle
    child_to_check = _check_adjacent_tasks(current_task_id, task)
  File "/home/airflow/.local/lib/python3.7/site-packages/airflow/utils/dag_cycle_tester.py", line 64, in _check_adjacent_tasks
    raise AirflowDagCycleException(msg)
airflow.exceptions.AirflowDagCycleException: Cycle detected in DAG: process_weather_people_postgres. Faulty task: group_users.slack_notification_1
[2023-06-06T00:09:01.643+0000] {processor.py:768} WARNING - No viable dags retrieved from /opt/airflow/dags/process_weather_people_postgres/process_weather_people_postgres.py
[2023-06-06T00:09:01.740+0000] {processor.py:176} INFO - Processing /opt/airflow/dags/process_weather_people_postgres/process_weather_people_postgres.py took 0.591 seconds
[2023-06-06T00:09:31.878+0000] {processor.py:154} INFO - Started process (PID=14834) to work on /opt/airflow/dags/process_weather_people_postgres/process_weather_people_postgres.py
[2023-06-06T00:09:31.880+0000] {processor.py:756} INFO - Processing file /opt/airflow/dags/process_weather_people_postgres/process_weather_people_postgres.py for tasks to queue
[2023-06-06T00:09:31.881+0000] {logging_mixin.py:120} INFO - [2023-06-06T00:09:31.880+0000] {dagbag.py:537} INFO - Filling up the DagBag from /opt/airflow/dags/process_weather_people_postgres/process_weather_people_postgres.py
[2023-06-06T00:09:32.325+0000] {logging_mixin.py:120} INFO - [2023-06-06T00:09:32.325+0000] {taskmixin.py:205} WARNING - Dependency <Task(PostgresOperator): create_users_table>, group_users.is_1_api_available already registered for DAG: process_weather_people_postgres
[2023-06-06T00:09:32.326+0000] {logging_mixin.py:120} INFO - [2023-06-06T00:09:32.325+0000] {taskmixin.py:205} WARNING - Dependency <Task(HttpSensor): group_users.is_1_api_available>, create_users_table already registered for DAG: process_weather_people_postgres
[2023-06-06T00:09:32.327+0000] {logging_mixin.py:120} INFO - [2023-06-06T00:09:32.327+0000] {dagbag.py:449} ERROR - Failed to bag_dag: /opt/airflow/dags/process_weather_people_postgres/process_weather_people_postgres.py
Traceback (most recent call last):
  File "/home/airflow/.local/lib/python3.7/site-packages/airflow/models/dagbag.py", line 437, in _process_modules
    self.bag_dag(dag=dag, root_dag=dag)
  File "/home/airflow/.local/lib/python3.7/site-packages/airflow/models/dagbag.py", line 464, in bag_dag
    self._bag_dag(dag=dag, root_dag=root_dag, recursive=True)
  File "/home/airflow/.local/lib/python3.7/site-packages/airflow/models/dagbag.py", line 472, in _bag_dag
    check_cycle(dag)  # throws if a task cycle is found
  File "/home/airflow/.local/lib/python3.7/site-packages/airflow/utils/dag_cycle_tester.py", line 78, in check_cycle
    child_to_check = _check_adjacent_tasks(current_task_id, task)
  File "/home/airflow/.local/lib/python3.7/site-packages/airflow/utils/dag_cycle_tester.py", line 64, in _check_adjacent_tasks
    raise AirflowDagCycleException(msg)
airflow.exceptions.AirflowDagCycleException: Cycle detected in DAG: process_weather_people_postgres. Faulty task: group_users.slack_notification_1
[2023-06-06T00:09:32.328+0000] {processor.py:768} WARNING - No viable dags retrieved from /opt/airflow/dags/process_weather_people_postgres/process_weather_people_postgres.py
[2023-06-06T00:09:32.346+0000] {processor.py:176} INFO - Processing /opt/airflow/dags/process_weather_people_postgres/process_weather_people_postgres.py took 0.470 seconds
[2023-06-06T00:10:02.514+0000] {processor.py:154} INFO - Started process (PID=14854) to work on /opt/airflow/dags/process_weather_people_postgres/process_weather_people_postgres.py
[2023-06-06T00:10:02.515+0000] {processor.py:756} INFO - Processing file /opt/airflow/dags/process_weather_people_postgres/process_weather_people_postgres.py for tasks to queue
[2023-06-06T00:10:02.516+0000] {logging_mixin.py:120} INFO - [2023-06-06T00:10:02.516+0000] {dagbag.py:537} INFO - Filling up the DagBag from /opt/airflow/dags/process_weather_people_postgres/process_weather_people_postgres.py
[2023-06-06T00:10:02.910+0000] {logging_mixin.py:120} INFO - [2023-06-06T00:10:02.910+0000] {taskmixin.py:205} WARNING - Dependency <Task(PostgresOperator): create_users_table>, group_users.is_1_api_available already registered for DAG: process_weather_people_postgres
[2023-06-06T00:10:02.911+0000] {logging_mixin.py:120} INFO - [2023-06-06T00:10:02.911+0000] {taskmixin.py:205} WARNING - Dependency <Task(HttpSensor): group_users.is_1_api_available>, create_users_table already registered for DAG: process_weather_people_postgres
[2023-06-06T00:10:02.913+0000] {logging_mixin.py:120} INFO - [2023-06-06T00:10:02.912+0000] {dagbag.py:449} ERROR - Failed to bag_dag: /opt/airflow/dags/process_weather_people_postgres/process_weather_people_postgres.py
Traceback (most recent call last):
  File "/home/airflow/.local/lib/python3.7/site-packages/airflow/models/dagbag.py", line 437, in _process_modules
    self.bag_dag(dag=dag, root_dag=dag)
  File "/home/airflow/.local/lib/python3.7/site-packages/airflow/models/dagbag.py", line 464, in bag_dag
    self._bag_dag(dag=dag, root_dag=root_dag, recursive=True)
  File "/home/airflow/.local/lib/python3.7/site-packages/airflow/models/dagbag.py", line 472, in _bag_dag
    check_cycle(dag)  # throws if a task cycle is found
  File "/home/airflow/.local/lib/python3.7/site-packages/airflow/utils/dag_cycle_tester.py", line 78, in check_cycle
    child_to_check = _check_adjacent_tasks(current_task_id, task)
  File "/home/airflow/.local/lib/python3.7/site-packages/airflow/utils/dag_cycle_tester.py", line 64, in _check_adjacent_tasks
    raise AirflowDagCycleException(msg)
airflow.exceptions.AirflowDagCycleException: Cycle detected in DAG: process_weather_people_postgres. Faulty task: group_users.slack_notification_1
[2023-06-06T00:10:02.913+0000] {processor.py:768} WARNING - No viable dags retrieved from /opt/airflow/dags/process_weather_people_postgres/process_weather_people_postgres.py
[2023-06-06T00:10:02.933+0000] {processor.py:176} INFO - Processing /opt/airflow/dags/process_weather_people_postgres/process_weather_people_postgres.py took 0.422 seconds
[2023-06-06T00:10:33.078+0000] {processor.py:154} INFO - Started process (PID=14883) to work on /opt/airflow/dags/process_weather_people_postgres/process_weather_people_postgres.py
[2023-06-06T00:10:33.079+0000] {processor.py:756} INFO - Processing file /opt/airflow/dags/process_weather_people_postgres/process_weather_people_postgres.py for tasks to queue
[2023-06-06T00:10:33.080+0000] {logging_mixin.py:120} INFO - [2023-06-06T00:10:33.080+0000] {dagbag.py:537} INFO - Filling up the DagBag from /opt/airflow/dags/process_weather_people_postgres/process_weather_people_postgres.py
[2023-06-06T00:10:33.608+0000] {logging_mixin.py:120} INFO - [2023-06-06T00:10:33.608+0000] {taskmixin.py:205} WARNING - Dependency <Task(PostgresOperator): create_users_table>, group_users.is_1_api_available already registered for DAG: process_weather_people_postgres
[2023-06-06T00:10:33.608+0000] {logging_mixin.py:120} INFO - [2023-06-06T00:10:33.608+0000] {taskmixin.py:205} WARNING - Dependency <Task(HttpSensor): group_users.is_1_api_available>, create_users_table already registered for DAG: process_weather_people_postgres
[2023-06-06T00:10:33.611+0000] {logging_mixin.py:120} INFO - [2023-06-06T00:10:33.609+0000] {dagbag.py:449} ERROR - Failed to bag_dag: /opt/airflow/dags/process_weather_people_postgres/process_weather_people_postgres.py
Traceback (most recent call last):
  File "/home/airflow/.local/lib/python3.7/site-packages/airflow/models/dagbag.py", line 437, in _process_modules
    self.bag_dag(dag=dag, root_dag=dag)
  File "/home/airflow/.local/lib/python3.7/site-packages/airflow/models/dagbag.py", line 464, in bag_dag
    self._bag_dag(dag=dag, root_dag=root_dag, recursive=True)
  File "/home/airflow/.local/lib/python3.7/site-packages/airflow/models/dagbag.py", line 472, in _bag_dag
    check_cycle(dag)  # throws if a task cycle is found
  File "/home/airflow/.local/lib/python3.7/site-packages/airflow/utils/dag_cycle_tester.py", line 78, in check_cycle
    child_to_check = _check_adjacent_tasks(current_task_id, task)
  File "/home/airflow/.local/lib/python3.7/site-packages/airflow/utils/dag_cycle_tester.py", line 64, in _check_adjacent_tasks
    raise AirflowDagCycleException(msg)
airflow.exceptions.AirflowDagCycleException: Cycle detected in DAG: process_weather_people_postgres. Faulty task: group_users.slack_notification_1
[2023-06-06T00:10:33.611+0000] {processor.py:768} WARNING - No viable dags retrieved from /opt/airflow/dags/process_weather_people_postgres/process_weather_people_postgres.py
[2023-06-06T00:10:33.630+0000] {processor.py:176} INFO - Processing /opt/airflow/dags/process_weather_people_postgres/process_weather_people_postgres.py took 0.555 seconds
[2023-06-06T00:11:03.824+0000] {processor.py:154} INFO - Started process (PID=14912) to work on /opt/airflow/dags/process_weather_people_postgres/process_weather_people_postgres.py
[2023-06-06T00:11:03.828+0000] {processor.py:756} INFO - Processing file /opt/airflow/dags/process_weather_people_postgres/process_weather_people_postgres.py for tasks to queue
[2023-06-06T00:11:03.830+0000] {logging_mixin.py:120} INFO - [2023-06-06T00:11:03.830+0000] {dagbag.py:537} INFO - Filling up the DagBag from /opt/airflow/dags/process_weather_people_postgres/process_weather_people_postgres.py
[2023-06-06T00:11:04.482+0000] {logging_mixin.py:120} INFO - [2023-06-06T00:11:04.482+0000] {taskmixin.py:205} WARNING - Dependency <Task(PostgresOperator): create_users_table>, group_users.is_1_api_available already registered for DAG: process_weather_people_postgres
[2023-06-06T00:11:04.482+0000] {logging_mixin.py:120} INFO - [2023-06-06T00:11:04.482+0000] {taskmixin.py:205} WARNING - Dependency <Task(HttpSensor): group_users.is_1_api_available>, create_users_table already registered for DAG: process_weather_people_postgres
[2023-06-06T00:11:04.484+0000] {logging_mixin.py:120} INFO - [2023-06-06T00:11:04.483+0000] {dagbag.py:449} ERROR - Failed to bag_dag: /opt/airflow/dags/process_weather_people_postgres/process_weather_people_postgres.py
Traceback (most recent call last):
  File "/home/airflow/.local/lib/python3.7/site-packages/airflow/models/dagbag.py", line 437, in _process_modules
    self.bag_dag(dag=dag, root_dag=dag)
  File "/home/airflow/.local/lib/python3.7/site-packages/airflow/models/dagbag.py", line 464, in bag_dag
    self._bag_dag(dag=dag, root_dag=root_dag, recursive=True)
  File "/home/airflow/.local/lib/python3.7/site-packages/airflow/models/dagbag.py", line 472, in _bag_dag
    check_cycle(dag)  # throws if a task cycle is found
  File "/home/airflow/.local/lib/python3.7/site-packages/airflow/utils/dag_cycle_tester.py", line 78, in check_cycle
    child_to_check = _check_adjacent_tasks(current_task_id, task)
  File "/home/airflow/.local/lib/python3.7/site-packages/airflow/utils/dag_cycle_tester.py", line 64, in _check_adjacent_tasks
    raise AirflowDagCycleException(msg)
airflow.exceptions.AirflowDagCycleException: Cycle detected in DAG: process_weather_people_postgres. Faulty task: group_users.slack_notification_1
[2023-06-06T00:11:04.485+0000] {processor.py:768} WARNING - No viable dags retrieved from /opt/airflow/dags/process_weather_people_postgres/process_weather_people_postgres.py
[2023-06-06T00:11:04.514+0000] {processor.py:176} INFO - Processing /opt/airflow/dags/process_weather_people_postgres/process_weather_people_postgres.py took 0.704 seconds
[2023-06-06T00:11:34.689+0000] {processor.py:154} INFO - Started process (PID=14932) to work on /opt/airflow/dags/process_weather_people_postgres/process_weather_people_postgres.py
[2023-06-06T00:11:34.690+0000] {processor.py:756} INFO - Processing file /opt/airflow/dags/process_weather_people_postgres/process_weather_people_postgres.py for tasks to queue
[2023-06-06T00:11:34.691+0000] {logging_mixin.py:120} INFO - [2023-06-06T00:11:34.690+0000] {dagbag.py:537} INFO - Filling up the DagBag from /opt/airflow/dags/process_weather_people_postgres/process_weather_people_postgres.py
[2023-06-06T00:11:35.112+0000] {logging_mixin.py:120} INFO - [2023-06-06T00:11:35.111+0000] {taskmixin.py:205} WARNING - Dependency <Task(PostgresOperator): create_users_table>, group_users.is_1_api_available already registered for DAG: process_weather_people_postgres
[2023-06-06T00:11:35.112+0000] {logging_mixin.py:120} INFO - [2023-06-06T00:11:35.112+0000] {taskmixin.py:205} WARNING - Dependency <Task(HttpSensor): group_users.is_1_api_available>, create_users_table already registered for DAG: process_weather_people_postgres
[2023-06-06T00:11:35.114+0000] {logging_mixin.py:120} INFO - [2023-06-06T00:11:35.113+0000] {dagbag.py:449} ERROR - Failed to bag_dag: /opt/airflow/dags/process_weather_people_postgres/process_weather_people_postgres.py
Traceback (most recent call last):
  File "/home/airflow/.local/lib/python3.7/site-packages/airflow/models/dagbag.py", line 437, in _process_modules
    self.bag_dag(dag=dag, root_dag=dag)
  File "/home/airflow/.local/lib/python3.7/site-packages/airflow/models/dagbag.py", line 464, in bag_dag
    self._bag_dag(dag=dag, root_dag=root_dag, recursive=True)
  File "/home/airflow/.local/lib/python3.7/site-packages/airflow/models/dagbag.py", line 472, in _bag_dag
    check_cycle(dag)  # throws if a task cycle is found
  File "/home/airflow/.local/lib/python3.7/site-packages/airflow/utils/dag_cycle_tester.py", line 78, in check_cycle
    child_to_check = _check_adjacent_tasks(current_task_id, task)
  File "/home/airflow/.local/lib/python3.7/site-packages/airflow/utils/dag_cycle_tester.py", line 64, in _check_adjacent_tasks
    raise AirflowDagCycleException(msg)
airflow.exceptions.AirflowDagCycleException: Cycle detected in DAG: process_weather_people_postgres. Faulty task: group_users.slack_notification_1
[2023-06-06T00:11:35.114+0000] {processor.py:768} WARNING - No viable dags retrieved from /opt/airflow/dags/process_weather_people_postgres/process_weather_people_postgres.py
[2023-06-06T00:11:35.130+0000] {processor.py:176} INFO - Processing /opt/airflow/dags/process_weather_people_postgres/process_weather_people_postgres.py took 0.444 seconds
[2023-06-06T00:12:05.294+0000] {processor.py:154} INFO - Started process (PID=14961) to work on /opt/airflow/dags/process_weather_people_postgres/process_weather_people_postgres.py
[2023-06-06T00:12:05.314+0000] {processor.py:756} INFO - Processing file /opt/airflow/dags/process_weather_people_postgres/process_weather_people_postgres.py for tasks to queue
[2023-06-06T00:12:05.317+0000] {logging_mixin.py:120} INFO - [2023-06-06T00:12:05.316+0000] {dagbag.py:537} INFO - Filling up the DagBag from /opt/airflow/dags/process_weather_people_postgres/process_weather_people_postgres.py
[2023-06-06T00:12:05.844+0000] {logging_mixin.py:120} INFO - [2023-06-06T00:12:05.843+0000] {taskmixin.py:205} WARNING - Dependency <Task(PostgresOperator): create_users_table>, group_users.is_1_api_available already registered for DAG: process_weather_people_postgres
[2023-06-06T00:12:05.844+0000] {logging_mixin.py:120} INFO - [2023-06-06T00:12:05.844+0000] {taskmixin.py:205} WARNING - Dependency <Task(HttpSensor): group_users.is_1_api_available>, create_users_table already registered for DAG: process_weather_people_postgres
[2023-06-06T00:12:05.846+0000] {logging_mixin.py:120} INFO - [2023-06-06T00:12:05.845+0000] {dagbag.py:449} ERROR - Failed to bag_dag: /opt/airflow/dags/process_weather_people_postgres/process_weather_people_postgres.py
Traceback (most recent call last):
  File "/home/airflow/.local/lib/python3.7/site-packages/airflow/models/dagbag.py", line 437, in _process_modules
    self.bag_dag(dag=dag, root_dag=dag)
  File "/home/airflow/.local/lib/python3.7/site-packages/airflow/models/dagbag.py", line 464, in bag_dag
    self._bag_dag(dag=dag, root_dag=root_dag, recursive=True)
  File "/home/airflow/.local/lib/python3.7/site-packages/airflow/models/dagbag.py", line 472, in _bag_dag
    check_cycle(dag)  # throws if a task cycle is found
  File "/home/airflow/.local/lib/python3.7/site-packages/airflow/utils/dag_cycle_tester.py", line 78, in check_cycle
    child_to_check = _check_adjacent_tasks(current_task_id, task)
  File "/home/airflow/.local/lib/python3.7/site-packages/airflow/utils/dag_cycle_tester.py", line 64, in _check_adjacent_tasks
    raise AirflowDagCycleException(msg)
airflow.exceptions.AirflowDagCycleException: Cycle detected in DAG: process_weather_people_postgres. Faulty task: group_users.slack_notification_1
[2023-06-06T00:12:05.847+0000] {processor.py:768} WARNING - No viable dags retrieved from /opt/airflow/dags/process_weather_people_postgres/process_weather_people_postgres.py
[2023-06-06T00:12:05.862+0000] {processor.py:176} INFO - Processing /opt/airflow/dags/process_weather_people_postgres/process_weather_people_postgres.py took 0.582 seconds
[2023-06-06T00:12:36.010+0000] {processor.py:154} INFO - Started process (PID=14990) to work on /opt/airflow/dags/process_weather_people_postgres/process_weather_people_postgres.py
[2023-06-06T00:12:36.011+0000] {processor.py:756} INFO - Processing file /opt/airflow/dags/process_weather_people_postgres/process_weather_people_postgres.py for tasks to queue
[2023-06-06T00:12:36.012+0000] {logging_mixin.py:120} INFO - [2023-06-06T00:12:36.012+0000] {dagbag.py:537} INFO - Filling up the DagBag from /opt/airflow/dags/process_weather_people_postgres/process_weather_people_postgres.py
[2023-06-06T00:12:36.460+0000] {logging_mixin.py:120} INFO - [2023-06-06T00:12:36.460+0000] {taskmixin.py:205} WARNING - Dependency <Task(PostgresOperator): create_users_table>, group_users.is_1_api_available already registered for DAG: process_weather_people_postgres
[2023-06-06T00:12:36.460+0000] {logging_mixin.py:120} INFO - [2023-06-06T00:12:36.460+0000] {taskmixin.py:205} WARNING - Dependency <Task(HttpSensor): group_users.is_1_api_available>, create_users_table already registered for DAG: process_weather_people_postgres
[2023-06-06T00:12:36.462+0000] {logging_mixin.py:120} INFO - [2023-06-06T00:12:36.461+0000] {dagbag.py:449} ERROR - Failed to bag_dag: /opt/airflow/dags/process_weather_people_postgres/process_weather_people_postgres.py
Traceback (most recent call last):
  File "/home/airflow/.local/lib/python3.7/site-packages/airflow/models/dagbag.py", line 437, in _process_modules
    self.bag_dag(dag=dag, root_dag=dag)
  File "/home/airflow/.local/lib/python3.7/site-packages/airflow/models/dagbag.py", line 464, in bag_dag
    self._bag_dag(dag=dag, root_dag=root_dag, recursive=True)
  File "/home/airflow/.local/lib/python3.7/site-packages/airflow/models/dagbag.py", line 472, in _bag_dag
    check_cycle(dag)  # throws if a task cycle is found
  File "/home/airflow/.local/lib/python3.7/site-packages/airflow/utils/dag_cycle_tester.py", line 78, in check_cycle
    child_to_check = _check_adjacent_tasks(current_task_id, task)
  File "/home/airflow/.local/lib/python3.7/site-packages/airflow/utils/dag_cycle_tester.py", line 64, in _check_adjacent_tasks
    raise AirflowDagCycleException(msg)
airflow.exceptions.AirflowDagCycleException: Cycle detected in DAG: process_weather_people_postgres. Faulty task: group_users.slack_notification_1
[2023-06-06T00:12:36.462+0000] {processor.py:768} WARNING - No viable dags retrieved from /opt/airflow/dags/process_weather_people_postgres/process_weather_people_postgres.py
[2023-06-06T00:12:36.480+0000] {processor.py:176} INFO - Processing /opt/airflow/dags/process_weather_people_postgres/process_weather_people_postgres.py took 0.472 seconds
[2023-06-06T00:13:06.559+0000] {processor.py:154} INFO - Started process (PID=15019) to work on /opt/airflow/dags/process_weather_people_postgres/process_weather_people_postgres.py
[2023-06-06T00:13:06.560+0000] {processor.py:756} INFO - Processing file /opt/airflow/dags/process_weather_people_postgres/process_weather_people_postgres.py for tasks to queue
[2023-06-06T00:13:06.561+0000] {logging_mixin.py:120} INFO - [2023-06-06T00:13:06.561+0000] {dagbag.py:537} INFO - Filling up the DagBag from /opt/airflow/dags/process_weather_people_postgres/process_weather_people_postgres.py
[2023-06-06T00:13:07.165+0000] {logging_mixin.py:120} INFO - [2023-06-06T00:13:07.165+0000] {taskmixin.py:205} WARNING - Dependency <Task(PostgresOperator): create_users_table>, group_users.is_1_api_available already registered for DAG: process_weather_people_postgres
[2023-06-06T00:13:07.165+0000] {logging_mixin.py:120} INFO - [2023-06-06T00:13:07.165+0000] {taskmixin.py:205} WARNING - Dependency <Task(HttpSensor): group_users.is_1_api_available>, create_users_table already registered for DAG: process_weather_people_postgres
[2023-06-06T00:13:07.168+0000] {logging_mixin.py:120} INFO - [2023-06-06T00:13:07.167+0000] {dagbag.py:449} ERROR - Failed to bag_dag: /opt/airflow/dags/process_weather_people_postgres/process_weather_people_postgres.py
Traceback (most recent call last):
  File "/home/airflow/.local/lib/python3.7/site-packages/airflow/models/dagbag.py", line 437, in _process_modules
    self.bag_dag(dag=dag, root_dag=dag)
  File "/home/airflow/.local/lib/python3.7/site-packages/airflow/models/dagbag.py", line 464, in bag_dag
    self._bag_dag(dag=dag, root_dag=root_dag, recursive=True)
  File "/home/airflow/.local/lib/python3.7/site-packages/airflow/models/dagbag.py", line 472, in _bag_dag
    check_cycle(dag)  # throws if a task cycle is found
  File "/home/airflow/.local/lib/python3.7/site-packages/airflow/utils/dag_cycle_tester.py", line 78, in check_cycle
    child_to_check = _check_adjacent_tasks(current_task_id, task)
  File "/home/airflow/.local/lib/python3.7/site-packages/airflow/utils/dag_cycle_tester.py", line 64, in _check_adjacent_tasks
    raise AirflowDagCycleException(msg)
airflow.exceptions.AirflowDagCycleException: Cycle detected in DAG: process_weather_people_postgres. Faulty task: group_users.slack_notification_1
[2023-06-06T00:13:07.168+0000] {processor.py:768} WARNING - No viable dags retrieved from /opt/airflow/dags/process_weather_people_postgres/process_weather_people_postgres.py
[2023-06-06T00:13:07.198+0000] {processor.py:176} INFO - Processing /opt/airflow/dags/process_weather_people_postgres/process_weather_people_postgres.py took 0.642 seconds
[2023-06-06T00:13:37.348+0000] {processor.py:154} INFO - Started process (PID=15039) to work on /opt/airflow/dags/process_weather_people_postgres/process_weather_people_postgres.py
[2023-06-06T00:13:37.349+0000] {processor.py:756} INFO - Processing file /opt/airflow/dags/process_weather_people_postgres/process_weather_people_postgres.py for tasks to queue
[2023-06-06T00:13:37.350+0000] {logging_mixin.py:120} INFO - [2023-06-06T00:13:37.350+0000] {dagbag.py:537} INFO - Filling up the DagBag from /opt/airflow/dags/process_weather_people_postgres/process_weather_people_postgres.py
[2023-06-06T00:13:37.801+0000] {logging_mixin.py:120} INFO - [2023-06-06T00:13:37.801+0000] {taskmixin.py:205} WARNING - Dependency <Task(PostgresOperator): create_users_table>, group_users.is_1_api_available already registered for DAG: process_weather_people_postgres
[2023-06-06T00:13:37.802+0000] {logging_mixin.py:120} INFO - [2023-06-06T00:13:37.802+0000] {taskmixin.py:205} WARNING - Dependency <Task(HttpSensor): group_users.is_1_api_available>, create_users_table already registered for DAG: process_weather_people_postgres
[2023-06-06T00:13:37.804+0000] {logging_mixin.py:120} INFO - [2023-06-06T00:13:37.803+0000] {dagbag.py:449} ERROR - Failed to bag_dag: /opt/airflow/dags/process_weather_people_postgres/process_weather_people_postgres.py
Traceback (most recent call last):
  File "/home/airflow/.local/lib/python3.7/site-packages/airflow/models/dagbag.py", line 437, in _process_modules
    self.bag_dag(dag=dag, root_dag=dag)
  File "/home/airflow/.local/lib/python3.7/site-packages/airflow/models/dagbag.py", line 464, in bag_dag
    self._bag_dag(dag=dag, root_dag=root_dag, recursive=True)
  File "/home/airflow/.local/lib/python3.7/site-packages/airflow/models/dagbag.py", line 472, in _bag_dag
    check_cycle(dag)  # throws if a task cycle is found
  File "/home/airflow/.local/lib/python3.7/site-packages/airflow/utils/dag_cycle_tester.py", line 78, in check_cycle
    child_to_check = _check_adjacent_tasks(current_task_id, task)
  File "/home/airflow/.local/lib/python3.7/site-packages/airflow/utils/dag_cycle_tester.py", line 64, in _check_adjacent_tasks
    raise AirflowDagCycleException(msg)
airflow.exceptions.AirflowDagCycleException: Cycle detected in DAG: process_weather_people_postgres. Faulty task: group_users.slack_notification_1
[2023-06-06T00:13:37.804+0000] {processor.py:768} WARNING - No viable dags retrieved from /opt/airflow/dags/process_weather_people_postgres/process_weather_people_postgres.py
[2023-06-06T00:13:37.827+0000] {processor.py:176} INFO - Processing /opt/airflow/dags/process_weather_people_postgres/process_weather_people_postgres.py took 0.482 seconds
